Workbook

Sheet 01_PRESUPUESTO_CRONOGRAMA_BASE
A1: Item | B1: Código WBS | C1: Descripción de la Partida Presupuestal | D1: Unidad | E1: Metrado Meta | F1: P.U. Directo (S/) | G1: Parcial Directo (S/) | H1: Fecha Inicio | I1: Fecha Fin | J1: Duración (Días) | K1: Día Inicio Obra | L1: Día Fin Obra | M1: Tasa PV Diario (S/Día)
A2: 01.01 | B2: WBS-100 | C2: Obras Preliminares y Trabajos Provisionales | D2: GLB | E2: 1 | F2: 8296.4 | G2: =ROUND(E2*F2, 2) | H2: 2026-08-01 | I2: 2026-08-14 | J2: =(L2-K2)+1 | K2: 1 | L2: 14 | M2: =ROUND(G2/J2, 2)
A3: 01.02.01 | B3: WBS-100 | C3: Trazo, Nivelación y Replanteo de Zanjas | D3: M | E3: 2400 | F3: 3.35 | G3: =ROUND(E3*F3, 2) | H3: 2026-08-01 | I3: 2026-08-14 | J3: =(L3-K3)+1 | K3: 1 | L3: 14 | M3: =ROUND(G3/J3, 2)
A4: 01.02.02 | B4: WBS-200 | C4: Excavación de Zanja H=1.50m - 2.20m a Máquina (Terreno Normal) | D4: M3 | E4: 3840 | F4: 11.66 | G4: =ROUND(E4*F4, 2) | H4: 2026-08-10 | I4: 2026-08-25 | J4: =(L4-K4)+1 | K4: 10 | L4: 25 | M4: =ROUND(G4/J4, 2)
A5: 01.02.03 | B5: WBS-200 | C5: Preparación y Colocación de Cama de Arena e=0.10m | D5: M | E5: 2400 | F5: 11.12 | G5: =ROUND(E5*F5, 2) | H5: 2026-08-12 | I5: 2026-08-28 | J5: =(L5-K5)+1 | K5: 12 | L5: 28 | M5: =ROUND(G5/J5, 2)
A6: 01.02.04 | B6: WBS-200 | C6: Suministro e Instalación de Tubería PVC UF DN 200mm Serie S-20 para Alcantarillado | D6: M | E6: 1400 | F6: 55.51 | G6: =ROUND(E6*F6, 2) | H6: 2026-08-15 | I6: 2026-08-31 | J6: =(L6-K6)+1 | K6: 15 | L6: 31 | M6: =ROUND(G6/J6, 2)
A7: 01.02.05 | B7: WBS-200 | C7: Relleno Compactado de Zanja en Capas de 0.20m con Maquinaria/Plancha | D7: M3 | E7: 3300 | F7: 28.54 | G7: =ROUND(E7*F7, 2) | H7: 2026-08-18 | I7: 2026-09-05 | J7: =(L7-K7)+1 | K7: 18 | L7: 36 | M7: =ROUND(G7/J7, 2)
A8: 01.02.06 | B8: WBS-200 | C8: Construcción de Buzones Prefabricados de Concreto h=1.50m - 2.50m (Inc. Marco y Tapa) | D8: UND | E8: 32 | F8: 2500.73 | G8: =ROUND(E8*F8, 2) | H8: 2026-08-22 | I8: 2026-09-10 | J8: =(L8-K8)+1 | K8: 22 | L8: 41 | M8: =ROUND(G8/J8, 2)
A9: 01.02.07 | B9: WBS-200 | C9: Conexiones Domiciliarias de Alcantarillado (Caja de Registro + Acometida) | D9: UND | E9: 120 | F9: 405.54 | G9: =ROUND(E9*F9, 2) | H9: 2026-08-28 | I9: 2026-09-12 | J9: =(L9-K9)+1 | K9: 28 | L9: 43 | M9: =ROUND(G9/J9, 2)
A10: 01.03.01 | B10: WBS-300 | C10: Suministro e Instalación de Tubería PVC C-10 DN 110mm para Agua Potable | D10: M | E10: 1000 | F10: 38.76 | G10: =ROUND(E10*F10, 2) | H10: 2026-08-22 | I10: 2026-09-12 | J10: =(L10-K10)+1 | K10: 22 | L10: 43 | M10: =ROUND(G10/J10, 2)
A11: 01.03.02 | B11: WBS-300 | C11: Conexiones Domiciliarias de Agua Potable (Caja de Agua + Abrazadera + Acometida) | D11: UND | E11: 120 | F11: 156.71 | G11: =ROUND(E11*F11, 2) | H11: 2026-09-01 | I11: 2026-09-20 | J11: =(L11-K11)+1 | K11: 32 | L11: 51 | M11: =ROUND(G11/J11, 2)
A12: 01.04.01 | B12: WBS-400 | C12: Pruebas Hidráulicas de Redes de Agua y Alcantarillado + Desinfección | D12: GLB | E12: 1 | F12: 9348.06 | G12: =ROUND(E12*F12, 2) | H12: 2026-09-17 | I12: 2026-09-29 | J12: =(L12-K12)+1 | K12: 48 | L12: 60 | M12: =ROUND(G12/J12, 2)
C13: COSTO DIRECTO TOTAL (S/) | G13: =SUM(G2:G12)
C14: GASTOS GENERALES (10.00%) | G14: =ROUND(G13*0.1, 2)
C15: UTILIDAD (8.00%) | G15: =ROUND(G13*0.08, 2)
C16: SUB TOTAL / VALOR VENTA (SIN IGV) | G16: =SUM(G13:G15)
C17: IMPUESTO GENERAL A LAS VENTAS (IGV 18%) | G17: =ROUND(G16*0.18, 2)
C18: PRECIO TOTAL COMERCIAL DE OBRA (CON IGV) | G18: =G16+G17

Sheet 02_CRONOGRAMA_PV_DIARIO
A1: N° Día Obra | B1: Fecha Obra | C1: Código WBS | D1: Nombre Frente WBS | E1: PV Diario Programado (S/) | F1: PV Acumulado WBS (S/)
A2: 1 | B2: 2026-08-01 | C2: WBS-100 | D2: Obras Preliminares, Trazo y Movilización | E2: =IF(AND(A2>='01_PRESUPUESTO_CRONOGRAMA_BASE'!K2, A2<='01_PRESUPUESTO_CRONOGRAMA_BASE'!L2), '01_PRESUPUESTO_CRONOGRAMA_BASE'!M2, 0) + IF(AND(A2>='01_PRESUPUESTO_CRONOGRAMA_BASE'!K3, A2<='01_PRESUPUESTO_CRONOGRAMA_BASE'!L3), '01_PRESUPUESTO_CRONOGRAMA_BASE'!M3, 0) | F2: =SUMIFS(E$2:E2, C$2:C2, C2)
A3: 1 | B3: 2026-08-01 | C3: WBS-200 | D3: Red de Alcantarillado, Zanjas y Buzones | E3: =IF(AND(A3>='01_PRESUPUESTO_CRONOGRAMA_BASE'!K4, A3<='01_PRESUPUESTO_CRONOGRAMA_BASE'!L4), '01_PRESUPUESTO_CRONOGRAMA_BASE'!M4, 0) + IF(AND(A3>='01_PRESUPUESTO_CRONOGRAMA_BASE'!K5, A3<='01_PRESUPUESTO_CRONOGRAMA_BASE'!L5), '01_PRESUPUESTO_CRONOGRAMA_BASE'!M5, 0) + IF(AND(A3>='01_PRESUPUESTO_CRONOGRAMA_BASE'!K6, A3<='01_PRESUPUESTO_CRONOGRAMA_BASE'!L6), '01_PRESUPUESTO_CRONOGRAMA_BASE'!M6, 0) + IF(AND(A3>='01_PRESUPUESTO_CRONOGRAMA_BASE'!K7, A3<='01_PRESUPUESTO_CRONOGRAMA_BASE'!L7), '01_PRESUPUESTO_CRONOGRAMA_BASE'!M7, 0) + IF(AND(A3>='01_PRESUPUESTO_CRONOGRAMA_BASE'!K8, A3<='01_PRESUPUESTO_CRONOGRAMA_BASE'!L8), '01_PRESUPUESTO_CRONOGRAMA_BASE'!M8, 0) + IF(AND(A3>='01_PRESUPUESTO_CRONOGRAMA_BASE'!K9, A3<='01_PRESUPUESTO_CRONOGRAMA_BASE'!L9), '01_PRESUPUESTO_CRONOGRAMA_BASE'!M9, 0) | F3: =SUMIFS(E$2:E3, C$2:C3, C3)
A4: 1 | B4: 2026-08-01 | C4: WBS-300 | D4: Red de Agua Potable y Conexiones Domiciliarias | E4: =IF(AND(A4>='01_PRESUPUESTO_CRONOGRAMA_BASE'!K10, A4<='01_PRESUPUESTO_CRONOGRAMA_BASE'!L10), '01_PRESUPUESTO_CRONOGRAMA_BASE'!M10, 0) + IF(AND(A4>='01_PRESUPUESTO_CRONOGRAMA_BASE'!K11, A4<='01_PRESUPUESTO_CRONOGRAMA_BASE'!L11), '01_PRESUPUESTO_CRONOGRAMA_BASE'!M11, 0) | F4: =SUMIFS(E$2:E4, C$2:C4, C4)
A5: 1 | B5: 2026-08-01 | C5: WBS-400 | D5: Pruebas Hidráulicas, Desinfección y Entrega | E5: =IF(AND(A5>='01_PRESUPUESTO_CRONOGRAMA_BASE'!K12, A5<='01_PRESUPUESTO_CRONOGRAMA_BASE'!L12), '01_PRESUPUESTO_CRONOGRAMA_BASE'!M12, 0) | F5: =SUMIFS(E$2:E5, C$2:C5, C5)
A6: 2 | B6: 2026-08-02 | C6: WBS-100 | D6: Obras Preliminares, Trazo y Movilización | E6: =IF(AND(A6>='01_PRESUPUESTO_CRONOGRAMA_BASE'!K2, A6<='01_PRESUPUESTO_CRONOGRAMA_BASE'!L2), '01_PRESUPUESTO_CRONOGRAMA_BASE'!M2, 0) + IF(AND(A6>='01_PRESUPUESTO_CRONOGRAMA_BASE'!K3, A6<='01_PRESUPUESTO_CRONOGRAMA_BASE'!L3), '01_PRESUPUESTO_CRONOGRAMA_BASE'!M3, 0) | F6: =SUMIFS(E$2:E6, C$2:C6, C6)
A7: 2 | B7: 2026-08-02 | C7: WBS-200 | D7: Red de Alcantarillado, Zanjas y Buzones | E7: =IF(AND(A7>='01_PRESUPUESTO_CRONOGRAMA_BASE'!K4, A7<='01_PRESUPUESTO_CRONOGRAMA_BASE'!L4), '01_PRESUPUESTO_CRONOGRAMA_BASE'!M4, 0) + IF(AND(A7>='01_PRESUPUESTO_CRONOGRAMA_BASE'!K5, A7<='01_PRESUPUESTO_CRONOGRAMA_BASE'!L5), '01_PRESUPUESTO_CRONOGRAMA_BASE'!M5, 0) + IF(AND(A7>='01_PRESUPUESTO_CRONOGRAMA_BASE'!K6, A7<='01_PRESUPUESTO_CRONOGRAMA_BASE'!L6), '01_PRESUPUESTO_CRONOGRAMA_BASE'!M6, 0) + IF(AND(A7>='01_PRESUPUESTO_CRONOGRAMA_BASE'!K7, A7<='01_PRESUPUESTO_CRONOGRAMA_BASE'!L7), '01_PRESUPUESTO_CRONOGRAMA_BASE'!M7, 0) + IF(AND(A7>='01_PRESUPUESTO_CRONOGRAMA_BASE'!K8, A7<='01_PRESUPUESTO_CRONOGRAMA_BASE'!L8), '01_PRESUPUESTO_CRONOGRAMA_BASE'!M8, 0) + IF(AND(A7>='01_PRESUPUESTO_CRONOGRAMA_BASE'!K9, A7<='01_PRESUPUESTO_CRONOGRAMA_BASE'!L9), '01_PRESUPUESTO_CRONOGRAMA_BASE'!M9, 0) | F7: =SUMIFS(E$2:E7, C$2:C7, C7)
A8: 2 | B8: 2026-08-02 | C8: WBS-300 | D8: Red de Agua Potable y Conexiones Domiciliarias | E8: =IF(AND(A8>='01_PRESUPUESTO_CRONOGRAMA_BASE'!K10, A8<='01_PRESUPUESTO_CRONOGRAMA_BASE'!L10), '01_PRESUPUESTO_CRONOGRAMA_BASE'!M10, 0) + IF(AND(A8>='01_PRESUPUESTO_CRONOGRAMA_BASE'!K11, A8<='01_PRESUPUESTO_CRONOGRAMA_BASE'!L11), '01_PRESUPUESTO_CRONOGRAMA_BASE'!M11, 0) | F8: =SUMIFS(E$2:E8, C$2:C8, C8)
A9: 2 | B9: 2026-08-02 | C9: WBS-400 | D9: Pruebas Hidráulicas, Desinfección y Entrega | E9: =IF(AND(A9>='01_PRESUPUESTO_CRONOGRAMA_BASE'!K12, A9<='01_PRESUPUESTO_CRONOGRAMA_BASE'!L12), '01_PRESUPUESTO_CRONOGRAMA_BASE'!M12, 0) | F9: =SUMIFS(E$2:E9, C$2:C9, C9)
A10: 3 | B10: 2026-08-03 | C10: WBS-100 | D10: Obras Preliminares, Trazo y Movilización | E10: =IF(AND(A10>='01_PRESUPUESTO_CRONOGRAMA_BASE'!K2, A10<='01_PRESUPUESTO_CRONOGRAMA_BASE'!L2), '01_PRESUPUESTO_CRONOGRAMA_BASE'!M2, 0) + IF(AND(A10>='01_PRESUPUESTO_CRONOGRAMA_BASE'!K3, A10<='01_PRESUPUESTO_CRONOGRAMA_BASE'!L3), '01_PRESUPUESTO_CRONOGRAMA_BASE'!M3, 0) | F10: =SUMIFS(E$2:E10, C$2:C10, C10)
A11: 3 | B11: 2026-08-03 | C11: WBS-200 | D11: Red de Alcantarillado, Zanjas y Buzones | E11: =IF(AND(A11>='01_PRESUPUESTO_CRONOGRAMA_BASE'!K4, A11<='01_PRESUPUESTO_CRONOGRAMA_BASE'!L4), '01_PRESUPUESTO_CRONOGRAMA_BASE'!M4, 0) + IF(AND(A11>='01_PRESUPUESTO_CRONOGRAMA_BASE'!K5, A11<='01_PRESUPUESTO_CRONOGRAMA_BASE'!L5), '01_PRESUPUESTO_CRONOGRAMA_BASE'!M5, 0) + IF(AND(A11>='01_PRESUPUESTO_CRONOGRAMA_BASE'!K6, A11<='01_PRESUPUESTO_CRONOGRAMA_BASE'!L6), '01_PRESUPUESTO_CRONOGRAMA_BASE'!M6, 0) + IF(AND(A11>='01_PRESUPUESTO_CRONOGRAMA_BASE'!K7, A11<='01_PRESUPUESTO_CRONOGRAMA_BASE'!L7), '01_PRESUPUESTO_CRONOGRAMA_BASE'!M7, 0) + IF(AND(A11>='01_PRESUPUESTO_CRONOGRAMA_BASE'!K8, A11<='01_PRESUPUESTO_CRONOGRAMA_BASE'!L8), '01_PRESUPUESTO_CRONOGRAMA_BASE'!M8, 0) + IF(AND(A11>='01_PRESUPUESTO_CRONOGRAMA_BASE'!K9, A11<='01_PRESUPUESTO_CRONOGRAMA_BASE'!L9), '01_PRESUPUESTO_CRONOGRAMA_BASE'!M9, 0) | F11: =SUMIFS(E$2:E11, C$2:C11, C11)
A12: 3 | B12: 2026-08-03 | C12: WBS-300 | D12: Red de Agua Potable y Conexiones Domiciliarias | E12: =IF(AND(A12>='01_PRESUPUESTO_CRONOGRAMA_BASE'!K10, A12<='01_PRESUPUESTO_CRONOGRAMA_BASE'!L10), '01_PRESUPUESTO_CRONOGRAMA_BASE'!M10, 0) + IF(AND(A12>='01_PRESUPUESTO_CRONOGRAMA_BASE'!K11, A12<='01_PRESUPUESTO_CRONOGRAMA_BASE'!L11), '01_PRESUPUESTO_CRONOGRAMA_BASE'!M11, 0) | F12: =SUMIFS(E$2:E12, C$2:C12, C12)
A13: 3 | B13: 2026-08-03 | C13: WBS-400 | D13: Pruebas Hidráulicas, Desinfección y Entrega | E13: =IF(AND(A13>='01_PRESUPUESTO_CRONOGRAMA_BASE'!K12, A13<='01_PRESUPUESTO_CRONOGRAMA_BASE'!L12), '01_PRESUPUESTO_CRONOGRAMA_BASE'!M12, 0) | F13: =SUMIFS(E$2:E13, C$2:C13, C13)
A14: 4 | B14: 2026-08-04 | C14: WBS-100 | D14: Obras Preliminares, Trazo y Movilización | E14: =IF(AND(A14>='01_PRESUPUESTO_CRONOGRAMA_BASE'!K2, A14<='01_PRESUPUESTO_CRONOGRAMA_BASE'!L2), '01_PRESUPUESTO_CRONOGRAMA_BASE'!M2, 0) + IF(AND(A14>='01_PRESUPUESTO_CRONOGRAMA_BASE'!K3, A14<='01_PRESUPUESTO_CRONOGRAMA_BASE'!L3), '01_PRESUPUESTO_CRONOGRAMA_BASE'!M3, 0) | F14: =SUMIFS(E$2:E14, C$2:C14, C14)
A15: 4 | B15: 2026-08-04 | C15: WBS-200 | D15: Red de Alcantarillado, Zanjas y Buzones | E15: =IF(AND(A15>='01_PRESUPUESTO_CRONOGRAMA_BASE'!K4, A15<='01_PRESUPUESTO_CRONOGRAMA_BASE'!L4), '01_PRESUPUESTO_CRONOGRAMA_BASE'!M4, 0) + IF(AND(A15>='01_PRESUPUESTO_CRONOGRAMA_BASE'!K5, A15<='01_PRESUPUESTO_CRONOGRAMA_BASE'!L5), '01_PRESUPUESTO_CRONOGRAMA_BASE'!M5, 0) + IF(AND(A15>='01_PRESUPUESTO_CRONOGRAMA_BASE'!K6, A15<='01_PRESUPUESTO_CRONOGRAMA_BASE'!L6), '01_PRESUPUESTO_CRONOGRAMA_BASE'!M6, 0) + IF(AND(A15>='01_PRESUPUESTO_CRONOGRAMA_BASE'!K7, A15<='01_PRESUPUESTO_CRONOGRAMA_BASE'!L7), '01_PRESUPUESTO_CRONOGRAMA_BASE'!M7, 0) + IF(AND(A15>='01_PRESUPUESTO_CRONOGRAMA_BASE'!K8, A15<='01_PRESUPUESTO_CRONOGRAMA_BASE'!L8), '01_PRESUPUESTO_CRONOGRAMA_BASE'!M8, 0) + IF(AND(A15>='01_PRESUPUESTO_CRONOGRAMA_BASE'!K9, A15<='01_PRESUPUESTO_CRONOGRAMA_BASE'!L9), '01_PRESUPUESTO_CRONOGRAMA_BASE'!M9, 0) | F15: =SUMIFS(E$2:E15, C$2:C15, C15)
A16: 4 | B16: 2026-08-04 | C16: WBS-300 | D16: Red de Agua Potable y Conexiones Domiciliarias | E16: =IF(AND(A16>='01_PRESUPUESTO_CRONOGRAMA_BASE'!K10, A16<='01_PRESUPUESTO_CRONOGRAMA_BASE'!L10), '01_PRESUPUESTO_CRONOGRAMA_BASE'!M10, 0) + IF(AND(A16>='01_PRESUPUESTO_CRONOGRAMA_BASE'!K11, A16<='01_PRESUPUESTO_CRONOGRAMA_BASE'!L11), '01_PRESUPUESTO_CRONOGRAMA_BASE'!M11, 0) | F16: =SUMIFS(E$2:E16, C$2:C16, C16)
A17: 4 | B17: 2026-08-04 | C17: WBS-400 | D17: Pruebas Hidráulicas, Desinfección y Entrega | E17: =IF(AND(A17>='01_PRESUPUESTO_CRONOGRAMA_BASE'!K12, A17<='01_PRESUPUESTO_CRONOGRAMA_BASE'!L12), '01_PRESUPUESTO_CRONOGRAMA_BASE'!M12, 0) | F17: =SUMIFS(E$2:E17, C$2:C17, C17)
A18: 5 | B18: 2026-08-05 | C18: WBS-100 | D18: Obras Preliminares, Trazo y Movilización | E18: =IF(AND(A18>='01_PRESUPUESTO_CRONOGRAMA_BASE'!K2, A18<='01_PRESUPUESTO_CRONOGRAMA_BASE'!L2), '01_PRESUPUESTO_CRONOGRAMA_BASE'!M2, 0) + IF(AND(A18>='01_PRESUPUESTO_CRONOGRAMA_BASE'!K3, A18<='01_PRESUPUESTO_CRONOGRAMA_BASE'!L3), '01_PRESUPUESTO_CRONOGRAMA_BASE'!M3, 0) | F18: =SUMIFS(E$2:E18, C$2:C18, C18)
A19: 5 | B19: 2026-08-05 | C19: WBS-200 | D19: Red de Alcantarillado, Zanjas y Buzones | E19: =IF(AND(A19>='01_PRESUPUESTO_CRONOGRAMA_BASE'!K4, A19<='01_PRESUPUESTO_CRONOGRAMA_BASE'!L4), '01_PRESUPUESTO_CRONOGRAMA_BASE'!M4, 0) + IF(AND(A19>='01_PRESUPUESTO_CRONOGRAMA_BASE'!K5, A19<='01_PRESUPUESTO_CRONOGRAMA_BASE'!L5), '01_PRESUPUESTO_CRONOGRAMA_BASE'!M5, 0) + IF(AND(A19>='01_PRESUPUESTO_CRONOGRAMA_BASE'!K6, A19<='01_PRESUPUESTO_CRONOGRAMA_BASE'!L6), '01_PRESUPUESTO_CRONOGRAMA_BASE'!M6, 0) + IF(AND(A19>='01_PRESUPUESTO_CRONOGRAMA_BASE'!K7, A19<='01_PRESUPUESTO_CRONOGRAMA_BASE'!L7), '01_PRESUPUESTO_CRONOGRAMA_BASE'!M7, 0) + IF(AND(A19>='01_PRESUPUESTO_CRONOGRAMA_BASE'!K8, A19<='01_PRESUPUESTO_CRONOGRAMA_BASE'!L8), '01_PRESUPUESTO_CRONOGRAMA_BASE'!M8, 0) + IF(AND(A19>='01_PRESUPUESTO_CRONOGRAMA_BASE'!K9, A19<='01_PRESUPUESTO_CRONOGRAMA_BASE'!L9), '01_PRESUPUESTO_CRONOGRAMA_BASE'!M9, 0) | F19: =SUMIFS(E$2:E19, C$2:C19, C19)
A20: 5 | B20: 2026-08-05 | C20: WBS-300 | D20: Red de Agua Potable y Conexiones Domiciliarias | E20: =IF(AND(A20>='01_PRESUPUESTO_CRONOGRAMA_BASE'!K10, A20<='01_PRESUPUESTO_CRONOGRAMA_BASE'!L10), '01_PRESUPUESTO_CRONOGRAMA_BASE'!M10, 0) + IF(AND(A20>='01_PRESUPUESTO_CRONOGRAMA_BASE'!K11, A20<='01_PRESUPUESTO_CRONOGRAMA_BASE'!L11), '01_PRESUPUESTO_CRONOGRAMA_BASE'!M11, 0) | F20: =SUMIFS(E$2:E20, C$2:C20, C20)
A21: 5 | B21: 2026-08-05 | C21: WBS-400 | D21: Pruebas Hidráulicas, Desinfección y Entrega | E21: =IF(AND(A21>='01_PRESUPUESTO_CRONOGRAMA_BASE'!K12, A21<='01_PRESUPUESTO_CRONOGRAMA_BASE'!L12), '01_PRESUPUESTO_CRONOGRAMA_BASE'!M12, 0) | F21: =SUMIFS(E$2:E21, C$2:C21, C21)
A22: 6 | B22: 2026-08-06 | C22: WBS-100 | D22: Obras Preliminares, Trazo y Movilización | E22: =IF(AND(A22>='01_PRESUPUESTO_CRONOGRAMA_BASE'!K2, A22<='01_PRESUPUESTO_CRONOGRAMA_BASE'!L2), '01_PRESUPUESTO_CRONOGRAMA_BASE'!M2, 0) + IF(AND(A22>='01_PRESUPUESTO_CRONOGRAMA_BASE'!K3, A22<='01_PRESUPUESTO_CRONOGRAMA_BASE'!L3), '01_PRESUPUESTO_CRONOGRAMA_BASE'!M3, 0) | F22: =SUMIFS(E$2:E22, C$2:C22, C22)
A23: 6 | B23: 2026-08-06 | C23: WBS-200 | D23: Red de Alcantarillado, Zanjas y Buzones | E23: =IF(AND(A23>='01_PRESUPUESTO_CRONOGRAMA_BASE'!K4, A23<='01_PRESUPUESTO_CRONOGRAMA_BASE'!L4), '01_PRESUPUESTO_CRONOGRAMA_BASE'!M4, 0) + IF(AND(A23>='01_PRESUPUESTO_CRONOGRAMA_BASE'!K5, A23<='01_PRESUPUESTO_CRONOGRAMA_BASE'!L5), '01_PRESUPUESTO_CRONOGRAMA_BASE'!M5, 0) + IF(AND(A23>='01_PRESUPUESTO_CRONOGRAMA_BASE'!K6, A23<='01_PRESUPUESTO_CRONOGRAMA_BASE'!L6), '01_PRESUPUESTO_CRONOGRAMA_BASE'!M6, 0) + IF(AND(A23>='01_PRESUPUESTO_CRONOGRAMA_BASE'!K7, A23<='01_PRESUPUESTO_CRONOGRAMA_BASE'!L7), '01_PRESUPUESTO_CRONOGRAMA_BASE'!M7, 0) + IF(AND(A23>='01_PRESUPUESTO_CRONOGRAMA_BASE'!K8, A23<='01_PRESUPUESTO_CRONOGRAMA_BASE'!L8), '01_PRESUPUESTO_CRONOGRAMA_BASE'!M8, 0) + IF(AND(A23>='01_PRESUPUESTO_CRONOGRAMA_BASE'!K9, A23<='01_PRESUPUESTO_CRONOGRAMA_BASE'!L9), '01_PRESUPUESTO_CRONOGRAMA_BASE'!M9, 0) | F23: =SUMIFS(E$2:E23, C$2:C23, C23)
A24: 6 | B24: 2026-08-06 | C24: WBS-300 | D24: Red de Agua Potable y Conexiones Domiciliarias | E24: =IF(AND(A24>='01_PRESUPUESTO_CRONOGRAMA_BASE'!K10, A24<='01_PRESUPUESTO_CRONOGRAMA_BASE'!L10), '01_PRESUPUESTO_CRONOGRAMA_BASE'!M10, 0) + IF(AND(A24>='01_PRESUPUESTO_CRONOGRAMA_BASE'!K11, A24<='01_PRESUPUESTO_CRONOGRAMA_BASE'!L11), '01_PRESUPUESTO_CRONOGRAMA_BASE'!M11, 0) | F24: =SUMIFS(E$2:E24, C$2:C24, C24)
A25: 6 | B25: 2026-08-06 | C25: WBS-400 | D25: Pruebas Hidráulicas, Desinfección y Entrega | E25: =IF(AND(A25>='01_PRESUPUESTO_CRONOGRAMA_BASE'!K12, A25<='01_PRESUPUESTO_CRONOGRAMA_BASE'!L12), '01_PRESUPUESTO_CRONOGRAMA_BASE'!M12, 0) | F25: =SUMIFS(E$2:E25, C$2:C25, C25)
A26: 7 | B26: 2026-08-07 | C26: WBS-100 | D26: Obras Preliminares, Trazo y Movilización | E26: =IF(AND(A26>='01_PRESUPUESTO_CRONOGRAMA_BASE'!K2, A26<='01_PRESUPUESTO_CRONOGRAMA_BASE'!L2), '01_PRESUPUESTO_CRONOGRAMA_BASE'!M2, 0) + IF(AND(A26>='01_PRESUPUESTO_CRONOGRAMA_BASE'!K3, A26<='01_PRESUPUESTO_CRONOGRAMA_BASE'!L3), '01_PRESUPUESTO_CRONOGRAMA_BASE'!M3, 0) | F26: =SUMIFS(E$2:E26, C$2:C26, C26)
A27: 7 | B27: 2026-08-07 | C27: WBS-200 | D27: Red de Alcantarillado, Zanjas y Buzones | E27: =IF(AND(A27>='01_PRESUPUESTO_CRONOGRAMA_BASE'!K4, A27<='01_PRESUPUESTO_CRONOGRAMA_BASE'!L4), '01_PRESUPUESTO_CRONOGRAMA_BASE'!M4, 0) + IF(AND(A27>='01_PRESUPUESTO_CRONOGRAMA_BASE'!K5, A27<='01_PRESUPUESTO_CRONOGRAMA_BASE'!L5), '01_PRESUPUESTO_CRONOGRAMA_BASE'!M5, 0) + IF(AND(A27>='01_PRESUPUESTO_CRONOGRAMA_BASE'!K6, A27<='01_PRESUPUESTO_CRONOGRAMA_BASE'!L6), '01_PRESUPUESTO_CRONOGRAMA_BASE'!M6, 0) + IF(AND(A27>='01_PRESUPUESTO_CRONOGRAMA_BASE'!K7, A27<='01_PRESUPUESTO_CRONOGRAMA_BASE'!L7), '01_PRESUPUESTO_CRONOGRAMA_BASE'!M7, 0) + IF(AND(A27>='01_PRESUPUESTO_CRONOGRAMA_BASE'!K8, A27<='01_PRESUPUESTO_CRONOGRAMA_BASE'!L8), '01_PRESUPUESTO_CRONOGRAMA_BASE'!M8, 0) + IF(AND(A27>='01_PRESUPUESTO_CRONOGRAMA_BASE'!K9, A27<='01_PRESUPUESTO_CRONOGRAMA_BASE'!L9), '01_PRESUPUESTO_CRONOGRAMA_BASE'!M9, 0) | F27: =SUMIFS(E$2:E27, C$2:C27, C27)
A28: 7 | B28: 2026-08-07 | C28: WBS-300 | D28: Red de Agua Potable y Conexiones Domiciliarias | E28: =IF(AND(A28>='01_PRESUPUESTO_CRONOGRAMA_BASE'!K10, A28<='01_PRESUPUESTO_CRONOGRAMA_BASE'!L10), '01_PRESUPUESTO_CRONOGRAMA_BASE'!M10, 0) + IF(AND(A28>='01_PRESUPUESTO_CRONOGRAMA_BASE'!K11, A28<='01_PRESUPUESTO_CRONOGRAMA_BASE'!L11), '01_PRESUPUESTO_CRONOGRAMA_BASE'!M11, 0) | F28: =SUMIFS(E$2:E28, C$2:C28, C28)
A29: 7 | B29: 2026-08-07 | C29: WBS-400 | D29: Pruebas Hidráulicas, Desinfección y Entrega | E29: =IF(AND(A29>='01_PRESUPUESTO_CRONOGRAMA_BASE'!K12, A29<='01_PRESUPUESTO_CRONOGRAMA_BASE'!L12), '01_PRESUPUESTO_CRONOGRAMA_BASE'!M12, 0) | F29: =SUMIFS(E$2:E29, C$2:C29, C29)
A30: 8 | B30: 2026-08-08 | C30: WBS-100 | D30: Obras Preliminares, Trazo y Movilización | E30: =IF(AND(A30>='01_PRESUPUESTO_CRONOGRAMA_BASE'!K2, A30<='01_PRESUPUESTO_CRONOGRAMA_BASE'!L2), '01_PRESUPUESTO_CRONOGRAMA_BASE'!M2, 0) + IF(AND(A30>='01_PRESUPUESTO_CRONOGRAMA_BASE'!K3, A30<='01_PRESUPUESTO_CRONOGRAMA_BASE'!L3), '01_PRESUPUESTO_CRONOGRAMA_BASE'!M3, 0) | F30: =SUMIFS(E$2:E30, C$2:C30, C30)
A31: 8 | B31: 2026-08-08 | C31: WBS-200 | D31: Red de Alcantarillado, Zanjas y Buzones | E31: =IF(AND(A31>='01_PRESUPUESTO_CRONOGRAMA_BASE'!K4, A31<='01_PRESUPUESTO_CRONOGRAMA_BASE'!L4), '01_PRESUPUESTO_CRONOGRAMA_BASE'!M4, 0) + IF(AND(A31>='01_PRESUPUESTO_CRONOGRAMA_BASE'!K5, A31<='01_PRESUPUESTO_CRONOGRAMA_BASE'!L5), '01_PRESUPUESTO_CRONOGRAMA_BASE'!M5, 0) + IF(AND(A31>='01_PRESUPUESTO_CRONOGRAMA_BASE'!K6, A31<='01_PRESUPUESTO_CRONOGRAMA_BASE'!L6), '01_PRESUPUESTO_CRONOGRAMA_BASE'!M6, 0) + IF(AND(A31>='01_PRESUPUESTO_CRONOGRAMA_BASE'!K7, A31<='01_PRESUPUESTO_CRONOGRAMA_BASE'!L7), '01_PRESUPUESTO_CRONOGRAMA_BASE'!M7, 0) + IF(AND(A31>='01_PRESUPUESTO_CRONOGRAMA_BASE'!K8, A31<='01_PRESUPUESTO_CRONOGRAMA_BASE'!L8), '01_PRESUPUESTO_CRONOGRAMA_BASE'!M8, 0) + IF(AND(A31>='01_PRESUPUESTO_CRONOGRAMA_BASE'!K9, A31<='01_PRESUPUESTO_CRONOGRAMA_BASE'!L9), '01_PRESUPUESTO_CRONOGRAMA_BASE'!M9, 0) | F31: =SUMIFS(E$2:E31, C$2:C31, C31)
A32: 8 | B32: 2026-08-08 | C32: WBS-300 | D32: Red de Agua Potable y Conexiones Domiciliarias | E32: =IF(AND(A32>='01_PRESUPUESTO_CRONOGRAMA_BASE'!K10, A32<='01_PRESUPUESTO_CRONOGRAMA_BASE'!L10), '01_PRESUPUESTO_CRONOGRAMA_BASE'!M10, 0) + IF(AND(A32>='01_PRESUPUESTO_CRONOGRAMA_BASE'!K11, A32<='01_PRESUPUESTO_CRONOGRAMA_BASE'!L11), '01_PRESUPUESTO_CRONOGRAMA_BASE'!M11, 0) | F32: =SUMIFS(E$2:E32, C$2:C32, C32)
A33: 8 | B33: 2026-08-08 | C33: WBS-400 | D33: Pruebas Hidráulicas, Desinfección y Entrega | E33: =IF(AND(A33>='01_PRESUPUESTO_CRONOGRAMA_BASE'!K12, A33<='01_PRESUPUESTO_CRONOGRAMA_BASE'!L12), '01_PRESUPUESTO_CRONOGRAMA_BASE'!M12, 0) | F33: =SUMIFS(E$2:E33, C$2:C33, C33)
A34: 9 | B34: 2026-08-09 | C34: WBS-100 | D34: Obras Preliminares, Trazo y Movilización | E34: =IF(AND(A34>='01_PRESUPUESTO_CRONOGRAMA_BASE'!K2, A34<='01_PRESUPUESTO_CRONOGRAMA_BASE'!L2), '01_PRESUPUESTO_CRONOGRAMA_BASE'!M2, 0) + IF(AND(A34>='01_PRESUPUESTO_CRONOGRAMA_BASE'!K3, A34<='01_PRESUPUESTO_CRONOGRAMA_BASE'!L3), '01_PRESUPUESTO_CRONOGRAMA_BASE'!M3, 0) | F34: =SUMIFS(E$2:E34, C$2:C34, C34)
A35: 9 | B35: 2026-08-09 | C35: WBS-200 | D35: Red de Alcantarillado, Zanjas y Buzones | E35: =IF(AND(A35>='01_PRESUPUESTO_CRONOGRAMA_BASE'!K4, A35<='01_PRESUPUESTO_CRONOGRAMA_BASE'!L4), '01_PRESUPUESTO_CRONOGRAMA_BASE'!M4, 0) + IF(AND(A35>='01_PRESUPUESTO_CRONOGRAMA_BASE'!K5, A35<='01_PRESUPUESTO_CRONOGRAMA_BASE'!L5), '01_PRESUPUESTO_CRONOGRAMA_BASE'!M5, 0) + IF(AND(A35>='01_PRESUPUESTO_CRONOGRAMA_BASE'!K6, A35<='01_PRESUPUESTO_CRONOGRAMA_BASE'!L6), '01_PRESUPUESTO_CRONOGRAMA_BASE'!M6, 0) + IF(AND(A35>='01_PRESUPUESTO_CRONOGRAMA_BASE'!K7, A35<='01_PRESUPUESTO_CRONOGRAMA_BASE'!L7), '01_PRESUPUESTO_CRONOGRAMA_BASE'!M7, 0) + IF(AND(A35>='01_PRESUPUESTO_CRONOGRAMA_BASE'!K8, A35<='01_PRESUPUESTO_CRONOGRAMA_BASE'!L8), '01_PRESUPUESTO_CRONOGRAMA_BASE'!M8, 0) + IF(AND(A35>='01_PRESUPUESTO_CRONOGRAMA_BASE'!K9, A35<='01_PRESUPUESTO_CRONOGRAMA_BASE'!L9), '01_PRESUPUESTO_CRONOGRAMA_BASE'!M9, 0) | F35: =SUMIFS(E$2:E35, C$2:C35, C35)
A36: 9 | B36: 2026-08-09 | C36: WBS-300 | D36: Red de Agua Potable y Conexiones Domiciliarias | E36: =IF(AND(A36>='01_PRESUPUESTO_CRONOGRAMA_BASE'!K10, A36<='01_PRESUPUESTO_CRONOGRAMA_BASE'!L10), '01_PRESUPUESTO_CRONOGRAMA_BASE'!M10, 0) + IF(AND(A36>='01_PRESUPUESTO_CRONOGRAMA_BASE'!K11, A36<='01_PRESUPUESTO_CRONOGRAMA_BASE'!L11), '01_PRESUPUESTO_CRONOGRAMA_BASE'!M11, 0) | F36: =SUMIFS(E$2:E36, C$2:C36, C36)
A37: 9 | B37: 2026-08-09 | C37: WBS-400 | D37: Pruebas Hidráulicas, Desinfección y Entrega | E37: =IF(AND(A37>='01_PRESUPUESTO_CRONOGRAMA_BASE'!K12, A37<='01_PRESUPUESTO_CRONOGRAMA_BASE'!L12), '01_PRESUPUESTO_CRONOGRAMA_BASE'!M12, 0) | F37: =SUMIFS(E$2:E37, C$2:C37, C37)
A38: 10 | B38: 2026-08-10 | C38: WBS-100 | D38: Obras Preliminares, Trazo y Movilización | E38: =IF(AND(A38>='01_PRESUPUESTO_CRONOGRAMA_BASE'!K2, A38<='01_PRESUPUESTO_CRONOGRAMA_BASE'!L2), '01_PRESUPUESTO_CRONOGRAMA_BASE'!M2, 0) + IF(AND(A38>='01_PRESUPUESTO_CRONOGRAMA_BASE'!K3, A38<='01_PRESUPUESTO_CRONOGRAMA_BASE'!L3), '01_PRESUPUESTO_CRONOGRAMA_BASE'!M3, 0) | F38: =SUMIFS(E$2:E38, C$2:C38, C38)
A39: 10 | B39: 2026-08-10 | C39: WBS-200 | D39: Red de Alcantarillado, Zanjas y Buzones | E39: =IF(AND(A39>='01_PRESUPUESTO_CRONOGRAMA_BASE'!K4, A39<='01_PRESUPUESTO_CRONOGRAMA_BASE'!L4), '01_PRESUPUESTO_CRONOGRAMA_BASE'!M4, 0) + IF(AND(A39>='01_PRESUPUESTO_CRONOGRAMA_BASE'!K5, A39<='01_PRESUPUESTO_CRONOGRAMA_BASE'!L5), '01_PRESUPUESTO_CRONOGRAMA_BASE'!M5, 0) + IF(AND(A39>='01_PRESUPUESTO_CRONOGRAMA_BASE'!K6, A39<='01_PRESUPUESTO_CRONOGRAMA_BASE'!L6), '01_PRESUPUESTO_CRONOGRAMA_BASE'!M6, 0) + IF(AND(A39>='01_PRESUPUESTO_CRONOGRAMA_BASE'!K7, A39<='01_PRESUPUESTO_CRONOGRAMA_BASE'!L7), '01_PRESUPUESTO_CRONOGRAMA_BASE'!M7, 0) + IF(AND(A39>='01_PRESUPUESTO_CRONOGRAMA_BASE'!K8, A39<='01_PRESUPUESTO_CRONOGRAMA_BASE'!L8), '01_PRESUPUESTO_CRONOGRAMA_BASE'!M8, 0) + IF(AND(A39>='01_PRESUPUESTO_CRONOGRAMA_BASE'!K9, A39<='01_PRESUPUESTO_CRONOGRAMA_BASE'!L9), '01_PRESUPUESTO_CRONOGRAMA_BASE'!M9, 0) | F39: =SUMIFS(E$2:E39, C$2:C39, C39)
A40: 10 | B40: 2026-08-10 | C40: WBS-300 | D40: Red de Agua Potable y Conexiones Domiciliarias | E40: =IF(AND(A40>='01_PRESUPUESTO_CRONOGRAMA_BASE'!K10, A40<='01_PRESUPUESTO_CRONOGRAMA_BASE'!L10), '01_PRESUPUESTO_CRONOGRAMA_BASE'!M10, 0) + IF(AND(A40>='01_PRESUPUESTO_CRONOGRAMA_BASE'!K11, A40<='01_PRESUPUESTO_CRONOGRAMA_BASE'!L11), '01_PRESUPUESTO_CRONOGRAMA_BASE'!M11, 0) | F40: =SUMIFS(E$2:E40, C$2:C40, C40)
...

Sheet 03_CONSOLIDADO_DIARIO_EVM_WBS
A1: N° Día Obra | B1: Fecha Obra | C1: Código WBS | D1: Nombre Frente WBS | E1: Presupuesto BAC (S/) | F1: PV Programado Día (S/) | G1: PV Acumulado (S/) | H1: EV Ejecutado Día (S/) | I1: EV Acumulado (S/) | J1: AC Costo Real Día (S/) | K1: AC Acumulado (S/) | L1: Variación Costo CV (S/) | M1: Variación Plazo SV (S/) | N1: SPI Plazo (EV/PV) | O1: CPI Costo (EV/AC) | P1: Estado Alerta WBS
A2: 1 | B2: 46235 | C2: WBS-100 | D2: Obras Preliminares, Trazo y Movilización | E2: =SUM('01_PRESUPUESTO_CRONOGRAMA_BASE'!G2:G3) | F2: =SUMIFS('02_CRONOGRAMA_PV_DIARIO'!E:E, '02_CRONOGRAMA_PV_DIARIO'!A:A, A2, '02_CRONOGRAMA_PV_DIARIO'!C:C, C2) | G2: =SUMIFS(F$2:F2, C$2:C2, C2) | H2: =IF(B2 > MAX('04_LOG_FIELD_ENTRIES'!$B:$B), "", SUMIFS('04_LOG_FIELD_ENTRIES'!$J:$J, '04_LOG_FIELD_ENTRIES'!$B:$B, B2, '04_LOG_FIELD_ENTRIES'!$D:$D, C2, '04_LOG_FIELD_ENTRIES'!$K:$K, "EV_PRODUCCION")) | I2: =IF(B2 > MAX('04_LOG_FIELD_ENTRIES'!$B:$B), "", SUMIFS(H$2:H2, C$2:C2, C2)) | J2: =IF(B2 > MAX('04_LOG_FIELD_ENTRIES'!$B:$B), "", SUMIFS('04_LOG_FIELD_ENTRIES'!$J:$J, '04_LOG_FIELD_ENTRIES'!$B:$B, B2, '04_LOG_FIELD_ENTRIES'!$D:$D, C2, '04_LOG_FIELD_ENTRIES'!$K:$K, "AC_*")) | K2: =IF(B2 > MAX('04_LOG_FIELD_ENTRIES'!$B:$B), "", SUMIFS(J$2:J2, C$2:C2, C2)) | L2: =IF(K2="", "", I2-K2) | M2: =IF(I2="", "", I2-G2) | N2: =IF(I2="", "", IF(G2>0, I2/G2, 1)) | O2: =IF(I2="", "", IF(K2>0, I2/K2, 1)) | P2: =IF(I2="", "", IF(AND(N2>=0.95, O2>=0.95), "SALUDABLE", IF(N2<0.9, "ALERTA RETRASO", "ALERTA SOBRECOSTO")))
A3: 1 | B3: 46235 | C3: WBS-200 | D3: Red de Alcantarillado, Zanjas y Buzones | E3: =SUM('01_PRESUPUESTO_CRONOGRAMA_BASE'!G4:G9) | F3: =SUMIFS('02_CRONOGRAMA_PV_DIARIO'!E:E, '02_CRONOGRAMA_PV_DIARIO'!A:A, A3, '02_CRONOGRAMA_PV_DIARIO'!C:C, C3) | G3: =SUMIFS(F$2:F3, C$2:C3, C3) | H3: =IF(B3 > MAX('04_LOG_FIELD_ENTRIES'!$B:$B), "", SUMIFS('04_LOG_FIELD_ENTRIES'!$J:$J, '04_LOG_FIELD_ENTRIES'!$B:$B, B3, '04_LOG_FIELD_ENTRIES'!$D:$D, C3, '04_LOG_FIELD_ENTRIES'!$K:$K, "EV_PRODUCCION")) | I3: =IF(B3 > MAX('04_LOG_FIELD_ENTRIES'!$B:$B), "", SUMIFS(H$2:H3, C$2:C3, C3)) | J3: =IF(B3 > MAX('04_LOG_FIELD_ENTRIES'!$B:$B), "", SUMIFS('04_LOG_FIELD_ENTRIES'!$J:$J, '04_LOG_FIELD_ENTRIES'!$B:$B, B3, '04_LOG_FIELD_ENTRIES'!$D:$D, C3, '04_LOG_FIELD_ENTRIES'!$K:$K, "AC_*")) | K3: =IF(B3 > MAX('04_LOG_FIELD_ENTRIES'!$B:$B), "", SUMIFS(J$2:J3, C$2:C3, C3)) | L3: =IF(K3="", "", I3-K3) | M3: =IF(I3="", "", I3-G3) | N3: =IF(I3="", "", IF(G3>0, I3/G3, 1)) | O3: =IF(I3="", "", IF(K3>0, I3/K3, 1)) | P3: =IF(I3="", "", IF(AND(N3>=0.95, O3>=0.95), "SALUDABLE", IF(N3<0.9, "ALERTA RETRASO", "ALERTA SOBRECOSTO")))
A4: 1 | B4: 46235 | C4: WBS-300 | D4: Red de Agua Potable y Conexiones Domiciliarias | E4: =SUM('01_PRESUPUESTO_CRONOGRAMA_BASE'!G10:G11) | F4: =SUMIFS('02_CRONOGRAMA_PV_DIARIO'!E:E, '02_CRONOGRAMA_PV_DIARIO'!A:A, A4, '02_CRONOGRAMA_PV_DIARIO'!C:C, C4) | G4: =SUMIFS(F$2:F4, C$2:C4, C4) | H4: =IF(B4 > MAX('04_LOG_FIELD_ENTRIES'!$B:$B), "", SUMIFS('04_LOG_FIELD_ENTRIES'!$J:$J, '04_LOG_FIELD_ENTRIES'!$B:$B, B4, '04_LOG_FIELD_ENTRIES'!$D:$D, C4, '04_LOG_FIELD_ENTRIES'!$K:$K, "EV_PRODUCCION")) | I4: =IF(B4 > MAX('04_LOG_FIELD_ENTRIES'!$B:$B), "", SUMIFS(H$2:H4, C$2:C4, C4)) | J4: =IF(B4 > MAX('04_LOG_FIELD_ENTRIES'!$B:$B), "", SUMIFS('04_LOG_FIELD_ENTRIES'!$J:$J, '04_LOG_FIELD_ENTRIES'!$B:$B, B4, '04_LOG_FIELD_ENTRIES'!$D:$D, C4, '04_LOG_FIELD_ENTRIES'!$K:$K, "AC_*")) | K4: =IF(B4 > MAX('04_LOG_FIELD_ENTRIES'!$B:$B), "", SUMIFS(J$2:J4, C$2:C4, C4)) | L4: =IF(K4="", "", I4-K4) | M4: =IF(I4="", "", I4-G4) | N4: =IF(I4="", "", IF(G4>0, I4/G4, 1)) | O4: =IF(I4="", "", IF(K4>0, I4/K4, 1)) | P4: =IF(I4="", "", IF(AND(N4>=0.95, O4>=0.95), "SALUDABLE", IF(N4<0.9, "ALERTA RETRASO", "ALERTA SOBRECOSTO")))
A5: 1 | B5: 46235 | C5: WBS-400 | D5: Pruebas Hidráulicas, Desinfección y Entrega | E5: =SUM('01_PRESUPUESTO_CRONOGRAMA_BASE'!G12:G12) | F5: =SUMIFS('02_CRONOGRAMA_PV_DIARIO'!E:E, '02_CRONOGRAMA_PV_DIARIO'!A:A, A5, '02_CRONOGRAMA_PV_DIARIO'!C:C, C5) | G5: =SUMIFS(F$2:F5, C$2:C5, C5) | H5: =IF(B5 > MAX('04_LOG_FIELD_ENTRIES'!$B:$B), "", SUMIFS('04_LOG_FIELD_ENTRIES'!$J:$J, '04_LOG_FIELD_ENTRIES'!$B:$B, B5, '04_LOG_FIELD_ENTRIES'!$D:$D, C5, '04_LOG_FIELD_ENTRIES'!$K:$K, "EV_PRODUCCION")) | I5: =IF(B5 > MAX('04_LOG_FIELD_ENTRIES'!$B:$B), "", SUMIFS(H$2:H5, C$2:C5, C5)) | J5: =IF(B5 > MAX('04_LOG_FIELD_ENTRIES'!$B:$B), "", SUMIFS('04_LOG_FIELD_ENTRIES'!$J:$J, '04_LOG_FIELD_ENTRIES'!$B:$B, B5, '04_LOG_FIELD_ENTRIES'!$D:$D, C5, '04_LOG_FIELD_ENTRIES'!$K:$K, "AC_*")) | K5: =IF(B5 > MAX('04_LOG_FIELD_ENTRIES'!$B:$B), "", SUMIFS(J$2:J5, C$2:C5, C5)) | L5: =IF(K5="", "", I5-K5) | M5: =IF(I5="", "", I5-G5) | N5: =IF(I5="", "", IF(G5>0, I5/G5, 1)) | O5: =IF(I5="", "", IF(K5>0, I5/K5, 1)) | P5: =IF(I5="", "", IF(AND(N5>=0.95, O5>=0.95), "SALUDABLE", IF(N5<0.9, "ALERTA RETRASO", "ALERTA SOBRECOSTO")))
A6: 2 | B6: 46236 | C6: WBS-100 | D6: Obras Preliminares, Trazo y Movilización | E6: =SUM('01_PRESUPUESTO_CRONOGRAMA_BASE'!G2:G3) | F6: =SUMIFS('02_CRONOGRAMA_PV_DIARIO'!E:E, '02_CRONOGRAMA_PV_DIARIO'!A:A, A6, '02_CRONOGRAMA_PV_DIARIO'!C:C, C6) | G6: =SUMIFS(F$2:F6, C$2:C6, C6) | H6: =IF(B6 > MAX('04_LOG_FIELD_ENTRIES'!$B:$B), "", SUMIFS('04_LOG_FIELD_ENTRIES'!$J:$J, '04_LOG_FIELD_ENTRIES'!$B:$B, B6, '04_LOG_FIELD_ENTRIES'!$D:$D, C6, '04_LOG_FIELD_ENTRIES'!$K:$K, "EV_PRODUCCION")) | I6: =IF(B6 > MAX('04_LOG_FIELD_ENTRIES'!$B:$B), "", SUMIFS(H$2:H6, C$2:C6, C6)) | J6: =IF(B6 > MAX('04_LOG_FIELD_ENTRIES'!$B:$B), "", SUMIFS('04_LOG_FIELD_ENTRIES'!$J:$J, '04_LOG_FIELD_ENTRIES'!$B:$B, B6, '04_LOG_FIELD_ENTRIES'!$D:$D, C6, '04_LOG_FIELD_ENTRIES'!$K:$K, "AC_*")) | K6: =IF(B6 > MAX('04_LOG_FIELD_ENTRIES'!$B:$B), "", SUMIFS(J$2:J6, C$2:C6, C6)) | L6: =IF(K6="", "", I6-K6) | M6: =IF(I6="", "", I6-G6) | N6: =IF(I6="", "", IF(G6>0, I6/G6, 1)) | O6: =IF(I6="", "", IF(K6>0, I6/K6, 1)) | P6: =IF(I6="", "", IF(AND(N6>=0.95, O6>=0.95), "SALUDABLE", IF(N6<0.9, "ALERTA RETRASO", "ALERTA SOBRECOSTO")))
A7: 2 | B7: 46236 | C7: WBS-200 | D7: Red de Alcantarillado, Zanjas y Buzones | E7: =SUM('01_PRESUPUESTO_CRONOGRAMA_BASE'!G4:G9) | F7: =SUMIFS('02_CRONOGRAMA_PV_DIARIO'!E:E, '02_CRONOGRAMA_PV_DIARIO'!A:A, A7, '02_CRONOGRAMA_PV_DIARIO'!C:C, C7) | G7: =SUMIFS(F$2:F7, C$2:C7, C7) | H7: =IF(B7 > MAX('04_LOG_FIELD_ENTRIES'!$B:$B), "", SUMIFS('04_LOG_FIELD_ENTRIES'!$J:$J, '04_LOG_FIELD_ENTRIES'!$B:$B, B7, '04_LOG_FIELD_ENTRIES'!$D:$D, C7, '04_LOG_FIELD_ENTRIES'!$K:$K, "EV_PRODUCCION")) | I7: =IF(B7 > MAX('04_LOG_FIELD_ENTRIES'!$B:$B), "", SUMIFS(H$2:H7, C$2:C7, C7)) | J7: =IF(B7 > MAX('04_LOG_FIELD_ENTRIES'!$B:$B), "", SUMIFS('04_LOG_FIELD_ENTRIES'!$J:$J, '04_LOG_FIELD_ENTRIES'!$B:$B, B7, '04_LOG_FIELD_ENTRIES'!$D:$D, C7, '04_LOG_FIELD_ENTRIES'!$K:$K, "AC_*")) | K7: =IF(B7 > MAX('04_LOG_FIELD_ENTRIES'!$B:$B), "", SUMIFS(J$2:J7, C$2:C7, C7)) | L7: =IF(K7="", "", I7-K7) | M7: =IF(I7="", "", I7-G7) | N7: =IF(I7="", "", IF(G7>0, I7/G7, 1)) | O7: =IF(I7="", "", IF(K7>0, I7/K7, 1)) | P7: =IF(I7="", "", IF(AND(N7>=0.95, O7>=0.95), "SALUDABLE", IF(N7<0.9, "ALERTA RETRASO", "ALERTA SOBRECOSTO")))
A8: 2 | B8: 46236 | C8: WBS-300 | D8: Red de Agua Potable y Conexiones Domiciliarias | E8: =SUM('01_PRESUPUESTO_CRONOGRAMA_BASE'!G10:G11) | F8: =SUMIFS('02_CRONOGRAMA_PV_DIARIO'!E:E, '02_CRONOGRAMA_PV_DIARIO'!A:A, A8, '02_CRONOGRAMA_PV_DIARIO'!C:C, C8) | G8: =SUMIFS(F$2:F8, C$2:C8, C8) | H8: =IF(B8 > MAX('04_LOG_FIELD_ENTRIES'!$B:$B), "", SUMIFS('04_LOG_FIELD_ENTRIES'!$J:$J, '04_LOG_FIELD_ENTRIES'!$B:$B, B8, '04_LOG_FIELD_ENTRIES'!$D:$D, C8, '04_LOG_FIELD_ENTRIES'!$K:$K, "EV_PRODUCCION")) | I8: =IF(B8 > MAX('04_LOG_FIELD_ENTRIES'!$B:$B), "", SUMIFS(H$2:H8, C$2:C8, C8)) | J8: =IF(B8 > MAX('04_LOG_FIELD_ENTRIES'!$B:$B), "", SUMIFS('04_LOG_FIELD_ENTRIES'!$J:$J, '04_LOG_FIELD_ENTRIES'!$B:$B, B8, '04_LOG_FIELD_ENTRIES'!$D:$D, C8, '04_LOG_FIELD_ENTRIES'!$K:$K, "AC_*")) | K8: =IF(B8 > MAX('04_LOG_FIELD_ENTRIES'!$B:$B), "", SUMIFS(J$2:J8, C$2:C8, C8)) | L8: =IF(K8="", "", I8-K8) | M8: =IF(I8="", "", I8-G8) | N8: =IF(I8="", "", IF(G8>0, I8/G8, 1)) | O8: =IF(I8="", "", IF(K8>0, I8/K8, 1)) | P8: =IF(I8="", "", IF(AND(N8>=0.95, O8>=0.95), "SALUDABLE", IF(N8<0.9, "ALERTA RETRASO", "ALERTA SOBRECOSTO")))
A9: 2 | B9: 46236 | C9: WBS-400 | D9: Pruebas Hidráulicas, Desinfección y Entrega | E9: =SUM('01_PRESUPUESTO_CRONOGRAMA_BASE'!G12:G12) | F9: =SUMIFS('02_CRONOGRAMA_PV_DIARIO'!E:E, '02_CRONOGRAMA_PV_DIARIO'!A:A, A9, '02_CRONOGRAMA_PV_DIARIO'!C:C, C9) | G9: =SUMIFS(F$2:F9, C$2:C9, C9) | H9: =IF(B9 > MAX('04_LOG_FIELD_ENTRIES'!$B:$B), "", SUMIFS('04_LOG_FIELD_ENTRIES'!$J:$J, '04_LOG_FIELD_ENTRIES'!$B:$B, B9, '04_LOG_FIELD_ENTRIES'!$D:$D, C9, '04_LOG_FIELD_ENTRIES'!$K:$K, "EV_PRODUCCION")) | I9: =IF(B9 > MAX('04_LOG_FIELD_ENTRIES'!$B:$B), "", SUMIFS(H$2:H9, C$2:C9, C9)) | J9: =IF(B9 > MAX('04_LOG_FIELD_ENTRIES'!$B:$B), "", SUMIFS('04_LOG_FIELD_ENTRIES'!$J:$J, '04_LOG_FIELD_ENTRIES'!$B:$B, B9, '04_LOG_FIELD_ENTRIES'!$D:$D, C9, '04_LOG_FIELD_ENTRIES'!$K:$K, "AC_*")) | K9: =IF(B9 > MAX('04_LOG_FIELD_ENTRIES'!$B:$B), "", SUMIFS(J$2:J9, C$2:C9, C9)) | L9: =IF(K9="", "", I9-K9) | M9: =IF(I9="", "", I9-G9) | N9: =IF(I9="", "", IF(G9>0, I9/G9, 1)) | O9: =IF(I9="", "", IF(K9>0, I9/K9, 1)) | P9: =IF(I9="", "", IF(AND(N9>=0.95, O9>=0.95), "SALUDABLE", IF(N9<0.9, "ALERTA RETRASO", "ALERTA SOBRECOSTO")))
A10: 3 | B10: 46237 | C10: WBS-100 | D10: Obras Preliminares, Trazo y Movilización | E10: =SUM('01_PRESUPUESTO_CRONOGRAMA_BASE'!G2:G3) | F10: =SUMIFS('02_CRONOGRAMA_PV_DIARIO'!E:E, '02_CRONOGRAMA_PV_DIARIO'!A:A, A10, '02_CRONOGRAMA_PV_DIARIO'!C:C, C10) | G10: =SUMIFS(F$2:F10, C$2:C10, C10) | H10: =IF(B10 > MAX('04_LOG_FIELD_ENTRIES'!$B:$B), "", SUMIFS('04_LOG_FIELD_ENTRIES'!$J:$J, '04_LOG_FIELD_ENTRIES'!$B:$B, B10, '04_LOG_FIELD_ENTRIES'!$D:$D, C10, '04_LOG_FIELD_ENTRIES'!$K:$K, "EV_PRODUCCION")) | I10: =IF(B10 > MAX('04_LOG_FIELD_ENTRIES'!$B:$B), "", SUMIFS(H$2:H10, C$2:C10, C10)) | J10: =IF(B10 > MAX('04_LOG_FIELD_ENTRIES'!$B:$B), "", SUMIFS('04_LOG_FIELD_ENTRIES'!$J:$J, '04_LOG_FIELD_ENTRIES'!$B:$B, B10, '04_LOG_FIELD_ENTRIES'!$D:$D, C10, '04_LOG_FIELD_ENTRIES'!$K:$K, "AC_*")) | K10: =IF(B10 > MAX('04_LOG_FIELD_ENTRIES'!$B:$B), "", SUMIFS(J$2:J10, C$2:C10, C10)) | L10: =IF(K10="", "", I10-K10) | M10: =IF(I10="", "", I10-G10) | N10: =IF(I10="", "", IF(G10>0, I10/G10, 1)) | O10: =IF(I10="", "", IF(K10>0, I10/K10, 1)) | P10: =IF(I10="", "", IF(AND(N10>=0.95, O10>=0.95), "SALUDABLE", IF(N10<0.9, "ALERTA RETRASO", "ALERTA SOBRECOSTO")))
A11: 3 | B11: 46237 | C11: WBS-200 | D11: Red de Alcantarillado, Zanjas y Buzones | E11: =SUM('01_PRESUPUESTO_CRONOGRAMA_BASE'!G4:G9) | F11: =SUMIFS('02_CRONOGRAMA_PV_DIARIO'!E:E, '02_CRONOGRAMA_PV_DIARIO'!A:A, A11, '02_CRONOGRAMA_PV_DIARIO'!C:C, C11) | G11: =SUMIFS(F$2:F11, C$2:C11, C11) | H11: =IF(B11 > MAX('04_LOG_FIELD_ENTRIES'!$B:$B), "", SUMIFS('04_LOG_FIELD_ENTRIES'!$J:$J, '04_LOG_FIELD_ENTRIES'!$B:$B, B11, '04_LOG_FIELD_ENTRIES'!$D:$D, C11, '04_LOG_FIELD_ENTRIES'!$K:$K, "EV_PRODUCCION")) | I11: =IF(B11 > MAX('04_LOG_FIELD_ENTRIES'!$B:$B), "", SUMIFS(H$2:H11, C$2:C11, C11)) | J11: =IF(B11 > MAX('04_LOG_FIELD_ENTRIES'!$B:$B), "", SUMIFS('04_LOG_FIELD_ENTRIES'!$J:$J, '04_LOG_FIELD_ENTRIES'!$B:$B, B11, '04_LOG_FIELD_ENTRIES'!$D:$D, C11, '04_LOG_FIELD_ENTRIES'!$K:$K, "AC_*")) | K11: =IF(B11 > MAX('04_LOG_FIELD_ENTRIES'!$B:$B), "", SUMIFS(J$2:J11, C$2:C11, C11)) | L11: =IF(K11="", "", I11-K11) | M11: =IF(I11="", "", I11-G11) | N11: =IF(I11="", "", IF(G11>0, I11/G11, 1)) | O11: =IF(I11="", "", IF(K11>0, I11/K11, 1)) | P11: =IF(I11="", "", IF(AND(N11>=0.95, O11>=0.95), "SALUDABLE", IF(N11<0.9, "ALERTA RETRASO", "ALERTA SOBRECOSTO")))
A12: 3 | B12: 46237 | C12: WBS-300 | D12: Red de Agua Potable y Conexiones Domiciliarias | E12: =SUM('01_PRESUPUESTO_CRONOGRAMA_BASE'!G10:G11) | F12: =SUMIFS('02_CRONOGRAMA_PV_DIARIO'!E:E, '02_CRONOGRAMA_PV_DIARIO'!A:A, A12, '02_CRONOGRAMA_PV_DIARIO'!C:C, C12) | G12: =SUMIFS(F$2:F12, C$2:C12, C12) | H12: =IF(B12 > MAX('04_LOG_FIELD_ENTRIES'!$B:$B), "", SUMIFS('04_LOG_FIELD_ENTRIES'!$J:$J, '04_LOG_FIELD_ENTRIES'!$B:$B, B12, '04_LOG_FIELD_ENTRIES'!$D:$D, C12, '04_LOG_FIELD_ENTRIES'!$K:$K, "EV_PRODUCCION")) | I12: =IF(B12 > MAX('04_LOG_FIELD_ENTRIES'!$B:$B), "", SUMIFS(H$2:H12, C$2:C12, C12)) | J12: =IF(B12 > MAX('04_LOG_FIELD_ENTRIES'!$B:$B), "", SUMIFS('04_LOG_FIELD_ENTRIES'!$J:$J, '04_LOG_FIELD_ENTRIES'!$B:$B, B12, '04_LOG_FIELD_ENTRIES'!$D:$D, C12, '04_LOG_FIELD_ENTRIES'!$K:$K, "AC_*")) | K12: =IF(B12 > MAX('04_LOG_FIELD_ENTRIES'!$B:$B), "", SUMIFS(J$2:J12, C$2:C12, C12)) | L12: =IF(K12="", "", I12-K12) | M12: =IF(I12="", "", I12-G12) | N12: =IF(I12="", "", IF(G12>0, I12/G12, 1)) | O12: =IF(I12="", "", IF(K12>0, I12/K12, 1)) | P12: =IF(I12="", "", IF(AND(N12>=0.95, O12>=0.95), "SALUDABLE", IF(N12<0.9, "ALERTA RETRASO", "ALERTA SOBRECOSTO")))
A13: 3 | B13: 46237 | C13: WBS-400 | D13: Pruebas Hidráulicas, Desinfección y Entrega | E13: =SUM('01_PRESUPUESTO_CRONOGRAMA_BASE'!G12:G12) | F13: =SUMIFS('02_CRONOGRAMA_PV_DIARIO'!E:E, '02_CRONOGRAMA_PV_DIARIO'!A:A, A13, '02_CRONOGRAMA_PV_DIARIO'!C:C, C13) | G13: =SUMIFS(F$2:F13, C$2:C13, C13) | H13: =IF(B13 > MAX('04_LOG_FIELD_ENTRIES'!$B:$B), "", SUMIFS('04_LOG_FIELD_ENTRIES'!$J:$J, '04_LOG_FIELD_ENTRIES'!$B:$B, B13, '04_LOG_FIELD_ENTRIES'!$D:$D, C13, '04_LOG_FIELD_ENTRIES'!$K:$K, "EV_PRODUCCION")) | I13: =IF(B13 > MAX('04_LOG_FIELD_ENTRIES'!$B:$B), "", SUMIFS(H$2:H13, C$2:C13, C13)) | J13: =IF(B13 > MAX('04_LOG_FIELD_ENTRIES'!$B:$B), "", SUMIFS('04_LOG_FIELD_ENTRIES'!$J:$J, '04_LOG_FIELD_ENTRIES'!$B:$B, B13, '04_LOG_FIELD_ENTRIES'!$D:$D, C13, '04_LOG_FIELD_ENTRIES'!$K:$K, "AC_*")) | K13: =IF(B13 > MAX('04_LOG_FIELD_ENTRIES'!$B:$B), "", SUMIFS(J$2:J13, C$2:C13, C13)) | L13: =IF(K13="", "", I13-K13) | M13: =IF(I13="", "", I13-G13) | N13: =IF(I13="", "", IF(G13>0, I13/G13, 1)) | O13: =IF(I13="", "", IF(K13>0, I13/K13, 1)) | P13: =IF(I13="", "", IF(AND(N13>=0.95, O13>=0.95), "SALUDABLE", IF(N13<0.9, "ALERTA RETRASO", "ALERTA SOBRECOSTO")))
A14: 4 | B14: 46238 | C14: WBS-100 | D14: Obras Preliminares, Trazo y Movilización | E14: =SUM('01_PRESUPUESTO_CRONOGRAMA_BASE'!G2:G3) | F14: =SUMIFS('02_CRONOGRAMA_PV_DIARIO'!E:E, '02_CRONOGRAMA_PV_DIARIO'!A:A, A14, '02_CRONOGRAMA_PV_DIARIO'!C:C, C14) | G14: =SUMIFS(F$2:F14, C$2:C14, C14) | H14: =IF(B14 > MAX('04_LOG_FIELD_ENTRIES'!$B:$B), "", SUMIFS('04_LOG_FIELD_ENTRIES'!$J:$J, '04_LOG_FIELD_ENTRIES'!$B:$B, B14, '04_LOG_FIELD_ENTRIES'!$D:$D, C14, '04_LOG_FIELD_ENTRIES'!$K:$K, "EV_PRODUCCION")) | I14: =IF(B14 > MAX('04_LOG_FIELD_ENTRIES'!$B:$B), "", SUMIFS(H$2:H14, C$2:C14, C14)) | J14: =IF(B14 > MAX('04_LOG_FIELD_ENTRIES'!$B:$B), "", SUMIFS('04_LOG_FIELD_ENTRIES'!$J:$J, '04_LOG_FIELD_ENTRIES'!$B:$B, B14, '04_LOG_FIELD_ENTRIES'!$D:$D, C14, '04_LOG_FIELD_ENTRIES'!$K:$K, "AC_*")) | K14: =IF(B14 > MAX('04_LOG_FIELD_ENTRIES'!$B:$B), "", SUMIFS(J$2:J14, C$2:C14, C14)) | L14: =IF(K14="", "", I14-K14) | M14: =IF(I14="", "", I14-G14) | N14: =IF(I14="", "", IF(G14>0, I14/G14, 1)) | O14: =IF(I14="", "", IF(K14>0, I14/K14, 1)) | P14: =IF(I14="", "", IF(AND(N14>=0.95, O14>=0.95), "SALUDABLE", IF(N14<0.9, "ALERTA RETRASO", "ALERTA SOBRECOSTO")))
A15: 4 | B15: 46238 | C15: WBS-200 | D15: Red de Alcantarillado, Zanjas y Buzones | E15: =SUM('01_PRESUPUESTO_CRONOGRAMA_BASE'!G4:G9) | F15: =SUMIFS('02_CRONOGRAMA_PV_DIARIO'!E:E, '02_CRONOGRAMA_PV_DIARIO'!A:A, A15, '02_CRONOGRAMA_PV_DIARIO'!C:C, C15) | G15: =SUMIFS(F$2:F15, C$2:C15, C15) | H15: =IF(B15 > MAX('04_LOG_FIELD_ENTRIES'!$B:$B), "", SUMIFS('04_LOG_FIELD_ENTRIES'!$J:$J, '04_LOG_FIELD_ENTRIES'!$B:$B, B15, '04_LOG_FIELD_ENTRIES'!$D:$D, C15, '04_LOG_FIELD_ENTRIES'!$K:$K, "EV_PRODUCCION")) | I15: =IF(B15 > MAX('04_LOG_FIELD_ENTRIES'!$B:$B), "", SUMIFS(H$2:H15, C$2:C15, C15)) | J15: =IF(B15 > MAX('04_LOG_FIELD_ENTRIES'!$B:$B), "", SUMIFS('04_LOG_FIELD_ENTRIES'!$J:$J, '04_LOG_FIELD_ENTRIES'!$B:$B, B15, '04_LOG_FIELD_ENTRIES'!$D:$D, C15, '04_LOG_FIELD_ENTRIES'!$K:$K, "AC_*")) | K15: =IF(B15 > MAX('04_LOG_FIELD_ENTRIES'!$B:$B), "", SUMIFS(J$2:J15, C$2:C15, C15)) | L15: =IF(K15="", "", I15-K15) | M15: =IF(I15="", "", I15-G15) | N15: =IF(I15="", "", IF(G15>0, I15/G15, 1)) | O15: =IF(I15="", "", IF(K15>0, I15/K15, 1)) | P15: =IF(I15="", "", IF(AND(N15>=0.95, O15>=0.95), "SALUDABLE", IF(N15<0.9, "ALERTA RETRASO", "ALERTA SOBRECOSTO")))
A16: 4 | B16: 46238 | C16: WBS-300 | D16: Red de Agua Potable y Conexiones Domiciliarias | E16: =SUM('01_PRESUPUESTO_CRONOGRAMA_BASE'!G10:G11) | F16: =SUMIFS('02_CRONOGRAMA_PV_DIARIO'!E:E, '02_CRONOGRAMA_PV_DIARIO'!A:A, A16, '02_CRONOGRAMA_PV_DIARIO'!C:C, C16) | G16: =SUMIFS(F$2:F16, C$2:C16, C16) | H16: =IF(B16 > MAX('04_LOG_FIELD_ENTRIES'!$B:$B), "", SUMIFS('04_LOG_FIELD_ENTRIES'!$J:$J, '04_LOG_FIELD_ENTRIES'!$B:$B, B16, '04_LOG_FIELD_ENTRIES'!$D:$D, C16, '04_LOG_FIELD_ENTRIES'!$K:$K, "EV_PRODUCCION")) | I16: =IF(B16 > MAX('04_LOG_FIELD_ENTRIES'!$B:$B), "", SUMIFS(H$2:H16, C$2:C16, C16)) | J16: =IF(B16 > MAX('04_LOG_FIELD_ENTRIES'!$B:$B), "", SUMIFS('04_LOG_FIELD_ENTRIES'!$J:$J, '04_LOG_FIELD_ENTRIES'!$B:$B, B16, '04_LOG_FIELD_ENTRIES'!$D:$D, C16, '04_LOG_FIELD_ENTRIES'!$K:$K, "AC_*")) | K16: =IF(B16 > MAX('04_LOG_FIELD_ENTRIES'!$B:$B), "", SUMIFS(J$2:J16, C$2:C16, C16)) | L16: =IF(K16="", "", I16-K16) | M16: =IF(I16="", "", I16-G16) | N16: =IF(I16="", "", IF(G16>0, I16/G16, 1)) | O16: =IF(I16="", "", IF(K16>0, I16/K16, 1)) | P16: =IF(I16="", "", IF(AND(N16>=0.95, O16>=0.95), "SALUDABLE", IF(N16<0.9, "ALERTA RETRASO", "ALERTA SOBRECOSTO")))
A17: 4 | B17: 46238 | C17: WBS-400 | D17: Pruebas Hidráulicas, Desinfección y Entrega | E17: =SUM('01_PRESUPUESTO_CRONOGRAMA_BASE'!G12:G12) | F17: =SUMIFS('02_CRONOGRAMA_PV_DIARIO'!E:E, '02_CRONOGRAMA_PV_DIARIO'!A:A, A17, '02_CRONOGRAMA_PV_DIARIO'!C:C, C17) | G17: =SUMIFS(F$2:F17, C$2:C17, C17) | H17: =IF(B17 > MAX('04_LOG_FIELD_ENTRIES'!$B:$B), "", SUMIFS('04_LOG_FIELD_ENTRIES'!$J:$J, '04_LOG_FIELD_ENTRIES'!$B:$B, B17, '04_LOG_FIELD_ENTRIES'!$D:$D, C17, '04_LOG_FIELD_ENTRIES'!$K:$K, "EV_PRODUCCION")) | I17: =IF(B17 > MAX('04_LOG_FIELD_ENTRIES'!$B:$B), "", SUMIFS(H$2:H17, C$2:C17, C17)) | J17: =IF(B17 > MAX('04_LOG_FIELD_ENTRIES'!$B:$B), "", SUMIFS('04_LOG_FIELD_ENTRIES'!$J:$J, '04_LOG_FIELD_ENTRIES'!$B:$B, B17, '04_LOG_FIELD_ENTRIES'!$D:$D, C17, '04_LOG_FIELD_ENTRIES'!$K:$K, "AC_*")) | K17: =IF(B17 > MAX('04_LOG_FIELD_ENTRIES'!$B:$B), "", SUMIFS(J$2:J17, C$2:C17, C17)) | L17: =IF(K17="", "", I17-K17) | M17: =IF(I17="", "", I17-G17) | N17: =IF(I17="", "", IF(G17>0, I17/G17, 1)) | O17: =IF(I17="", "", IF(K17>0, I17/K17, 1)) | P17: =IF(I17="", "", IF(AND(N17>=0.95, O17>=0.95), "SALUDABLE", IF(N17<0.9, "ALERTA RETRASO", "ALERTA SOBRECOSTO")))
A18: 5 | B18: 46239 | C18: WBS-100 | D18: Obras Preliminares, Trazo y Movilización | E18: =SUM('01_PRESUPUESTO_CRONOGRAMA_BASE'!G2:G3) | F18: =SUMIFS('02_CRONOGRAMA_PV_DIARIO'!E:E, '02_CRONOGRAMA_PV_DIARIO'!A:A, A18, '02_CRONOGRAMA_PV_DIARIO'!C:C, C18) | G18: =SUMIFS(F$2:F18, C$2:C18, C18) | H18: =IF(B18 > MAX('04_LOG_FIELD_ENTRIES'!$B:$B), "", SUMIFS('04_LOG_FIELD_ENTRIES'!$J:$J, '04_LOG_FIELD_ENTRIES'!$B:$B, B18, '04_LOG_FIELD_ENTRIES'!$D:$D, C18, '04_LOG_FIELD_ENTRIES'!$K:$K, "EV_PRODUCCION")) | I18: =IF(B18 > MAX('04_LOG_FIELD_ENTRIES'!$B:$B), "", SUMIFS(H$2:H18, C$2:C18, C18)) | J18: =IF(B18 > MAX('04_LOG_FIELD_ENTRIES'!$B:$B), "", SUMIFS('04_LOG_FIELD_ENTRIES'!$J:$J, '04_LOG_FIELD_ENTRIES'!$B:$B, B18, '04_LOG_FIELD_ENTRIES'!$D:$D, C18, '04_LOG_FIELD_ENTRIES'!$K:$K, "AC_*")) | K18: =IF(B18 > MAX('04_LOG_FIELD_ENTRIES'!$B:$B), "", SUMIFS(J$2:J18, C$2:C18, C18)) | L18: =IF(K18="", "", I18-K18) | M18: =IF(I18="", "", I18-G18) | N18: =IF(I18="", "", IF(G18>0, I18/G18, 1)) | O18: =IF(I18="", "", IF(K18>0, I18/K18, 1)) | P18: =IF(I18="", "", IF(AND(N18>=0.95, O18>=0.95), "SALUDABLE", IF(N18<0.9, "ALERTA RETRASO", "ALERTA SOBRECOSTO")))
A19: 5 | B19: 46239 | C19: WBS-200 | D19: Red de Alcantarillado, Zanjas y Buzones | E19: =SUM('01_PRESUPUESTO_CRONOGRAMA_BASE'!G4:G9) | F19: =SUMIFS('02_CRONOGRAMA_PV_DIARIO'!E:E, '02_CRONOGRAMA_PV_DIARIO'!A:A, A19, '02_CRONOGRAMA_PV_DIARIO'!C:C, C19) | G19: =SUMIFS(F$2:F19, C$2:C19, C19) | H19: =IF(B19 > MAX('04_LOG_FIELD_ENTRIES'!$B:$B), "", SUMIFS('04_LOG_FIELD_ENTRIES'!$J:$J, '04_LOG_FIELD_ENTRIES'!$B:$B, B19, '04_LOG_FIELD_ENTRIES'!$D:$D, C19, '04_LOG_FIELD_ENTRIES'!$K:$K, "EV_PRODUCCION")) | I19: =IF(B19 > MAX('04_LOG_FIELD_ENTRIES'!$B:$B), "", SUMIFS(H$2:H19, C$2:C19, C19)) | J19: =IF(B19 > MAX('04_LOG_FIELD_ENTRIES'!$B:$B), "", SUMIFS('04_LOG_FIELD_ENTRIES'!$J:$J, '04_LOG_FIELD_ENTRIES'!$B:$B, B19, '04_LOG_FIELD_ENTRIES'!$D:$D, C19, '04_LOG_FIELD_ENTRIES'!$K:$K, "AC_*")) | K19: =IF(B19 > MAX('04_LOG_FIELD_ENTRIES'!$B:$B), "", SUMIFS(J$2:J19, C$2:C19, C19)) | L19: =IF(K19="", "", I19-K19) | M19: =IF(I19="", "", I19-G19) | N19: =IF(I19="", "", IF(G19>0, I19/G19, 1)) | O19: =IF(I19="", "", IF(K19>0, I19/K19, 1)) | P19: =IF(I19="", "", IF(AND(N19>=0.95, O19>=0.95), "SALUDABLE", IF(N19<0.9, "ALERTA RETRASO", "ALERTA SOBRECOSTO")))
A20: 5 | B20: 46239 | C20: WBS-300 | D20: Red de Agua Potable y Conexiones Domiciliarias | E20: =SUM('01_PRESUPUESTO_CRONOGRAMA_BASE'!G10:G11) | F20: =SUMIFS('02_CRONOGRAMA_PV_DIARIO'!E:E, '02_CRONOGRAMA_PV_DIARIO'!A:A, A20, '02_CRONOGRAMA_PV_DIARIO'!C:C, C20) | G20: =SUMIFS(F$2:F20, C$2:C20, C20) | H20: =IF(B20 > MAX('04_LOG_FIELD_ENTRIES'!$B:$B), "", SUMIFS('04_LOG_FIELD_ENTRIES'!$J:$J, '04_LOG_FIELD_ENTRIES'!$B:$B, B20, '04_LOG_FIELD_ENTRIES'!$D:$D, C20, '04_LOG_FIELD_ENTRIES'!$K:$K, "EV_PRODUCCION")) | I20: =IF(B20 > MAX('04_LOG_FIELD_ENTRIES'!$B:$B), "", SUMIFS(H$2:H20, C$2:C20, C20)) | J20: =IF(B20 > MAX('04_LOG_FIELD_ENTRIES'!$B:$B), "", SUMIFS('04_LOG_FIELD_ENTRIES'!$J:$J, '04_LOG_FIELD_ENTRIES'!$B:$B, B20, '04_LOG_FIELD_ENTRIES'!$D:$D, C20, '04_LOG_FIELD_ENTRIES'!$K:$K, "AC_*")) | K20: =IF(B20 > MAX('04_LOG_FIELD_ENTRIES'!$B:$B), "", SUMIFS(J$2:J20, C$2:C20, C20)) | L20: =IF(K20="", "", I20-K20) | M20: =IF(I20="", "", I20-G20) | N20: =IF(I20="", "", IF(G20>0, I20/G20, 1)) | O20: =IF(I20="", "", IF(K20>0, I20/K20, 1)) | P20: =IF(I20="", "", IF(AND(N20>=0.95, O20>=0.95), "SALUDABLE", IF(N20<0.9, "ALERTA RETRASO", "ALERTA SOBRECOSTO")))
A21: 5 | B21: 46239 | C21: WBS-400 | D21: Pruebas Hidráulicas, Desinfección y Entrega | E21: =SUM('01_PRESUPUESTO_CRONOGRAMA_BASE'!G12:G12) | F21: =SUMIFS('02_CRONOGRAMA_PV_DIARIO'!E:E, '02_CRONOGRAMA_PV_DIARIO'!A:A, A21, '02_CRONOGRAMA_PV_DIARIO'!C:C, C21) | G21: =SUMIFS(F$2:F21, C$2:C21, C21) | H21: =IF(B21 > MAX('04_LOG_FIELD_ENTRIES'!$B:$B), "", SUMIFS('04_LOG_FIELD_ENTRIES'!$J:$J, '04_LOG_FIELD_ENTRIES'!$B:$B, B21, '04_LOG_FIELD_ENTRIES'!$D:$D, C21, '04_LOG_FIELD_ENTRIES'!$K:$K, "EV_PRODUCCION")) | I21: =IF(B21 > MAX('04_LOG_FIELD_ENTRIES'!$B:$B), "", SUMIFS(H$2:H21, C$2:C21, C21)) | J21: =IF(B21 > MAX('04_LOG_FIELD_ENTRIES'!$B:$B), "", SUMIFS('04_LOG_FIELD_ENTRIES'!$J:$J, '04_LOG_FIELD_ENTRIES'!$B:$B, B21, '04_LOG_FIELD_ENTRIES'!$D:$D, C21, '04_LOG_FIELD_ENTRIES'!$K:$K, "AC_*")) | K21: =IF(B21 > MAX('04_LOG_FIELD_ENTRIES'!$B:$B), "", SUMIFS(J$2:J21, C$2:C21, C21)) | L21: =IF(K21="", "", I21-K21) | M21: =IF(I21="", "", I21-G21) | N21: =IF(I21="", "", IF(G21>0, I21/G21, 1)) | O21: =IF(I21="", "", IF(K21>0, I21/K21, 1)) | P21: =IF(I21="", "", IF(AND(N21>=0.95, O21>=0.95), "SALUDABLE", IF(N21<0.9, "ALERTA RETRASO", "ALERTA SOBRECOSTO")))
A22: 6 | B22: 46240 | C22: WBS-100 | D22: Obras Preliminares, Trazo y Movilización | E22: =SUM('01_PRESUPUESTO_CRONOGRAMA_BASE'!G2:G3) | F22: =SUMIFS('02_CRONOGRAMA_PV_DIARIO'!E:E, '02_CRONOGRAMA_PV_DIARIO'!A:A, A22, '02_CRONOGRAMA_PV_DIARIO'!C:C, C22) | G22: =SUMIFS(F$2:F22, C$2:C22, C22) | H22: =IF(B22 > MAX('04_LOG_FIELD_ENTRIES'!$B:$B), "", SUMIFS('04_LOG_FIELD_ENTRIES'!$J:$J, '04_LOG_FIELD_ENTRIES'!$B:$B, B22, '04_LOG_FIELD_ENTRIES'!$D:$D, C22, '04_LOG_FIELD_ENTRIES'!$K:$K, "EV_PRODUCCION")) | I22: =IF(B22 > MAX('04_LOG_FIELD_ENTRIES'!$B:$B), "", SUMIFS(H$2:H22, C$2:C22, C22)) | J22: =IF(B22 > MAX('04_LOG_FIELD_ENTRIES'!$B:$B), "", SUMIFS('04_LOG_FIELD_ENTRIES'!$J:$J, '04_LOG_FIELD_ENTRIES'!$B:$B, B22, '04_LOG_FIELD_ENTRIES'!$D:$D, C22, '04_LOG_FIELD_ENTRIES'!$K:$K, "AC_*")) | K22: =IF(B22 > MAX('04_LOG_FIELD_ENTRIES'!$B:$B), "", SUMIFS(J$2:J22, C$2:C22, C22)) | L22: =IF(K22="", "", I22-K22) | M22: =IF(I22="", "", I22-G22) | N22: =IF(I22="", "", IF(G22>0, I22/G22, 1)) | O22: =IF(I22="", "", IF(K22>0, I22/K22, 1)) | P22: =IF(I22="", "", IF(AND(N22>=0.95, O22>=0.95), "SALUDABLE", IF(N22<0.9, "ALERTA RETRASO", "ALERTA SOBRECOSTO")))
A23: 6 | B23: 46240 | C23: WBS-200 | D23: Red de Alcantarillado, Zanjas y Buzones | E23: =SUM('01_PRESUPUESTO_CRONOGRAMA_BASE'!G4:G9) | F23: =SUMIFS('02_CRONOGRAMA_PV_DIARIO'!E:E, '02_CRONOGRAMA_PV_DIARIO'!A:A, A23, '02_CRONOGRAMA_PV_DIARIO'!C:C, C23) | G23: =SUMIFS(F$2:F23, C$2:C23, C23) | H23: =IF(B23 > MAX('04_LOG_FIELD_ENTRIES'!$B:$B), "", SUMIFS('04_LOG_FIELD_ENTRIES'!$J:$J, '04_LOG_FIELD_ENTRIES'!$B:$B, B23, '04_LOG_FIELD_ENTRIES'!$D:$D, C23, '04_LOG_FIELD_ENTRIES'!$K:$K, "EV_PRODUCCION")) | I23: =IF(B23 > MAX('04_LOG_FIELD_ENTRIES'!$B:$B), "", SUMIFS(H$2:H23, C$2:C23, C23)) | J23: =IF(B23 > MAX('04_LOG_FIELD_ENTRIES'!$B:$B), "", SUMIFS('04_LOG_FIELD_ENTRIES'!$J:$J, '04_LOG_FIELD_ENTRIES'!$B:$B, B23, '04_LOG_FIELD_ENTRIES'!$D:$D, C23, '04_LOG_FIELD_ENTRIES'!$K:$K, "AC_*")) | K23: =IF(B23 > MAX('04_LOG_FIELD_ENTRIES'!$B:$B), "", SUMIFS(J$2:J23, C$2:C23, C23)) | L23: =IF(K23="", "", I23-K23) | M23: =IF(I23="", "", I23-G23) | N23: =IF(I23="", "", IF(G23>0, I23/G23, 1)) | O23: =IF(I23="", "", IF(K23>0, I23/K23, 1)) | P23: =IF(I23="", "", IF(AND(N23>=0.95, O23>=0.95), "SALUDABLE", IF(N23<0.9, "ALERTA RETRASO", "ALERTA SOBRECOSTO")))
A24: 6 | B24: 46240 | C24: WBS-300 | D24: Red de Agua Potable y Conexiones Domiciliarias | E24: =SUM('01_PRESUPUESTO_CRONOGRAMA_BASE'!G10:G11) | F24: =SUMIFS('02_CRONOGRAMA_PV_DIARIO'!E:E, '02_CRONOGRAMA_PV_DIARIO'!A:A, A24, '02_CRONOGRAMA_PV_DIARIO'!C:C, C24) | G24: =SUMIFS(F$2:F24, C$2:C24, C24) | H24: =IF(B24 > MAX('04_LOG_FIELD_ENTRIES'!$B:$B), "", SUMIFS('04_LOG_FIELD_ENTRIES'!$J:$J, '04_LOG_FIELD_ENTRIES'!$B:$B, B24, '04_LOG_FIELD_ENTRIES'!$D:$D, C24, '04_LOG_FIELD_ENTRIES'!$K:$K, "EV_PRODUCCION")) | I24: =IF(B24 > MAX('04_LOG_FIELD_ENTRIES'!$B:$B), "", SUMIFS(H$2:H24, C$2:C24, C24)) | J24: =IF(B24 > MAX('04_LOG_FIELD_ENTRIES'!$B:$B), "", SUMIFS('04_LOG_FIELD_ENTRIES'!$J:$J, '04_LOG_FIELD_ENTRIES'!$B:$B, B24, '04_LOG_FIELD_ENTRIES'!$D:$D, C24, '04_LOG_FIELD_ENTRIES'!$K:$K, "AC_*")) | K24: =IF(B24 > MAX('04_LOG_FIELD_ENTRIES'!$B:$B), "", SUMIFS(J$2:J24, C$2:C24, C24)) | L24: =IF(K24="", "", I24-K24) | M24: =IF(I24="", "", I24-G24) | N24: =IF(I24="", "", IF(G24>0, I24/G24, 1)) | O24: =IF(I24="", "", IF(K24>0, I24/K24, 1)) | P24: =IF(I24="", "", IF(AND(N24>=0.95, O24>=0.95), "SALUDABLE", IF(N24<0.9, "ALERTA RETRASO", "ALERTA SOBRECOSTO")))
A25: 6 | B25: 46240 | C25: WBS-400 | D25: Pruebas Hidráulicas, Desinfección y Entrega | E25: =SUM('01_PRESUPUESTO_CRONOGRAMA_BASE'!G12:G12) | F25: =SUMIFS('02_CRONOGRAMA_PV_DIARIO'!E:E, '02_CRONOGRAMA_PV_DIARIO'!A:A, A25, '02_CRONOGRAMA_PV_DIARIO'!C:C, C25) | G25: =SUMIFS(F$2:F25, C$2:C25, C25) | H25: =IF(B25 > MAX('04_LOG_FIELD_ENTRIES'!$B:$B), "", SUMIFS('04_LOG_FIELD_ENTRIES'!$J:$J, '04_LOG_FIELD_ENTRIES'!$B:$B, B25, '04_LOG_FIELD_ENTRIES'!$D:$D, C25, '04_LOG_FIELD_ENTRIES'!$K:$K, "EV_PRODUCCION")) | I25: =IF(B25 > MAX('04_LOG_FIELD_ENTRIES'!$B:$B), "", SUMIFS(H$2:H25, C$2:C25, C25)) | J25: =IF(B25 > MAX('04_LOG_FIELD_ENTRIES'!$B:$B), "", SUMIFS('04_LOG_FIELD_ENTRIES'!$J:$J, '04_LOG_FIELD_ENTRIES'!$B:$B, B25, '04_LOG_FIELD_ENTRIES'!$D:$D, C25, '04_LOG_FIELD_ENTRIES'!$K:$K, "AC_*")) | K25: =IF(B25 > MAX('04_LOG_FIELD_ENTRIES'!$B:$B), "", SUMIFS(J$2:J25, C$2:C25, C25)) | L25: =IF(K25="", "", I25-K25) | M25: =IF(I25="", "", I25-G25) | N25: =IF(I25="", "", IF(G25>0, I25/G25, 1)) | O25: =IF(I25="", "", IF(K25>0, I25/K25, 1)) | P25: =IF(I25="", "", IF(AND(N25>=0.95, O25>=0.95), "SALUDABLE", IF(N25<0.9, "ALERTA RETRASO", "ALERTA SOBRECOSTO")))
A26: 7 | B26: 46241 | C26: WBS-100 | D26: Obras Preliminares, Trazo y Movilización | E26: =SUM('01_PRESUPUESTO_CRONOGRAMA_BASE'!G2:G3) | F26: =SUMIFS('02_CRONOGRAMA_PV_DIARIO'!E:E, '02_CRONOGRAMA_PV_DIARIO'!A:A, A26, '02_CRONOGRAMA_PV_DIARIO'!C:C, C26) | G26: =SUMIFS(F$2:F26, C$2:C26, C26) | H26: =IF(B26 > MAX('04_LOG_FIELD_ENTRIES'!$B:$B), "", SUMIFS('04_LOG_FIELD_ENTRIES'!$J:$J, '04_LOG_FIELD_ENTRIES'!$B:$B, B26, '04_LOG_FIELD_ENTRIES'!$D:$D, C26, '04_LOG_FIELD_ENTRIES'!$K:$K, "EV_PRODUCCION")) | I26: =IF(B26 > MAX('04_LOG_FIELD_ENTRIES'!$B:$B), "", SUMIFS(H$2:H26, C$2:C26, C26)) | J26: =IF(B26 > MAX('04_LOG_FIELD_ENTRIES'!$B:$B), "", SUMIFS('04_LOG_FIELD_ENTRIES'!$J:$J, '04_LOG_FIELD_ENTRIES'!$B:$B, B26, '04_LOG_FIELD_ENTRIES'!$D:$D, C26, '04_LOG_FIELD_ENTRIES'!$K:$K, "AC_*")) | K26: =IF(B26 > MAX('04_LOG_FIELD_ENTRIES'!$B:$B), "", SUMIFS(J$2:J26, C$2:C26, C26)) | L26: =IF(K26="", "", I26-K26) | M26: =IF(I26="", "", I26-G26) | N26: =IF(I26="", "", IF(G26>0, I26/G26, 1)) | O26: =IF(I26="", "", IF(K26>0, I26/K26, 1)) | P26: =IF(I26="", "", IF(AND(N26>=0.95, O26>=0.95), "SALUDABLE", IF(N26<0.9, "ALERTA RETRASO", "ALERTA SOBRECOSTO")))
A27: 7 | B27: 46241 | C27: WBS-200 | D27: Red de Alcantarillado, Zanjas y Buzones | E27: =SUM('01_PRESUPUESTO_CRONOGRAMA_BASE'!G4:G9) | F27: =SUMIFS('02_CRONOGRAMA_PV_DIARIO'!E:E, '02_CRONOGRAMA_PV_DIARIO'!A:A, A27, '02_CRONOGRAMA_PV_DIARIO'!C:C, C27) | G27: =SUMIFS(F$2:F27, C$2:C27, C27) | H27: =IF(B27 > MAX('04_LOG_FIELD_ENTRIES'!$B:$B), "", SUMIFS('04_LOG_FIELD_ENTRIES'!$J:$J, '04_LOG_FIELD_ENTRIES'!$B:$B, B27, '04_LOG_FIELD_ENTRIES'!$D:$D, C27, '04_LOG_FIELD_ENTRIES'!$K:$K, "EV_PRODUCCION")) | I27: =IF(B27 > MAX('04_LOG_FIELD_ENTRIES'!$B:$B), "", SUMIFS(H$2:H27, C$2:C27, C27)) | J27: =IF(B27 > MAX('04_LOG_FIELD_ENTRIES'!$B:$B), "", SUMIFS('04_LOG_FIELD_ENTRIES'!$J:$J, '04_LOG_FIELD_ENTRIES'!$B:$B, B27, '04_LOG_FIELD_ENTRIES'!$D:$D, C27, '04_LOG_FIELD_ENTRIES'!$K:$K, "AC_*")) | K27: =IF(B27 > MAX('04_LOG_FIELD_ENTRIES'!$B:$B), "", SUMIFS(J$2:J27, C$2:C27, C27)) | L27: =IF(K27="", "", I27-K27) | M27: =IF(I27="", "", I27-G27) | N27: =IF(I27="", "", IF(G27>0, I27/G27, 1)) | O27: =IF(I27="", "", IF(K27>0, I27/K27, 1)) | P27: =IF(I27="", "", IF(AND(N27>=0.95, O27>=0.95), "SALUDABLE", IF(N27<0.9, "ALERTA RETRASO", "ALERTA SOBRECOSTO")))
A28: 7 | B28: 46241 | C28: WBS-300 | D28: Red de Agua Potable y Conexiones Domiciliarias | E28: =SUM('01_PRESUPUESTO_CRONOGRAMA_BASE'!G10:G11) | F28: =SUMIFS('02_CRONOGRAMA_PV_DIARIO'!E:E, '02_CRONOGRAMA_PV_DIARIO'!A:A, A28, '02_CRONOGRAMA_PV_DIARIO'!C:C, C28) | G28: =SUMIFS(F$2:F28, C$2:C28, C28) | H28: =IF(B28 > MAX('04_LOG_FIELD_ENTRIES'!$B:$B), "", SUMIFS('04_LOG_FIELD_ENTRIES'!$J:$J, '04_LOG_FIELD_ENTRIES'!$B:$B, B28, '04_LOG_FIELD_ENTRIES'!$D:$D, C28, '04_LOG_FIELD_ENTRIES'!$K:$K, "EV_PRODUCCION")) | I28: =IF(B28 > MAX('04_LOG_FIELD_ENTRIES'!$B:$B), "", SUMIFS(H$2:H28, C$2:C28, C28)) | J28: =IF(B28 > MAX('04_LOG_FIELD_ENTRIES'!$B:$B), "", SUMIFS('04_LOG_FIELD_ENTRIES'!$J:$J, '04_LOG_FIELD_ENTRIES'!$B:$B, B28, '04_LOG_FIELD_ENTRIES'!$D:$D, C28, '04_LOG_FIELD_ENTRIES'!$K:$K, "AC_*")) | K28: =IF(B28 > MAX('04_LOG_FIELD_ENTRIES'!$B:$B), "", SUMIFS(J$2:J28, C$2:C28, C28)) | L28: =IF(K28="", "", I28-K28) | M28: =IF(I28="", "", I28-G28) | N28: =IF(I28="", "", IF(G28>0, I28/G28, 1)) | O28: =IF(I28="", "", IF(K28>0, I28/K28, 1)) | P28: =IF(I28="", "", IF(AND(N28>=0.95, O28>=0.95), "SALUDABLE", IF(N28<0.9, "ALERTA RETRASO", "ALERTA SOBRECOSTO")))
A29: 7 | B29: 46241 | C29: WBS-400 | D29: Pruebas Hidráulicas, Desinfección y Entrega | E29: =SUM('01_PRESUPUESTO_CRONOGRAMA_BASE'!G12:G12) | F29: =SUMIFS('02_CRONOGRAMA_PV_DIARIO'!E:E, '02_CRONOGRAMA_PV_DIARIO'!A:A, A29, '02_CRONOGRAMA_PV_DIARIO'!C:C, C29) | G29: =SUMIFS(F$2:F29, C$2:C29, C29) | H29: =IF(B29 > MAX('04_LOG_FIELD_ENTRIES'!$B:$B), "", SUMIFS('04_LOG_FIELD_ENTRIES'!$J:$J, '04_LOG_FIELD_ENTRIES'!$B:$B, B29, '04_LOG_FIELD_ENTRIES'!$D:$D, C29, '04_LOG_FIELD_ENTRIES'!$K:$K, "EV_PRODUCCION")) | I29: =IF(B29 > MAX('04_LOG_FIELD_ENTRIES'!$B:$B), "", SUMIFS(H$2:H29, C$2:C29, C29)) | J29: =IF(B29 > MAX('04_LOG_FIELD_ENTRIES'!$B:$B), "", SUMIFS('04_LOG_FIELD_ENTRIES'!$J:$J, '04_LOG_FIELD_ENTRIES'!$B:$B, B29, '04_LOG_FIELD_ENTRIES'!$D:$D, C29, '04_LOG_FIELD_ENTRIES'!$K:$K, "AC_*")) | K29: =IF(B29 > MAX('04_LOG_FIELD_ENTRIES'!$B:$B), "", SUMIFS(J$2:J29, C$2:C29, C29)) | L29: =IF(K29="", "", I29-K29) | M29: =IF(I29="", "", I29-G29) | N29: =IF(I29="", "", IF(G29>0, I29/G29, 1)) | O29: =IF(I29="", "", IF(K29>0, I29/K29, 1)) | P29: =IF(I29="", "", IF(AND(N29>=0.95, O29>=0.95), "SALUDABLE", IF(N29<0.9, "ALERTA RETRASO", "ALERTA SOBRECOSTO")))
A30: 8 | B30: 46242 | C30: WBS-100 | D30: Obras Preliminares, Trazo y Movilización | E30: =SUM('01_PRESUPUESTO_CRONOGRAMA_BASE'!G2:G3) | F30: =SUMIFS('02_CRONOGRAMA_PV_DIARIO'!E:E, '02_CRONOGRAMA_PV_DIARIO'!A:A, A30, '02_CRONOGRAMA_PV_DIARIO'!C:C, C30) | G30: =SUMIFS(F$2:F30, C$2:C30, C30) | H30: =IF(B30 > MAX('04_LOG_FIELD_ENTRIES'!$B:$B), "", SUMIFS('04_LOG_FIELD_ENTRIES'!$J:$J, '04_LOG_FIELD_ENTRIES'!$B:$B, B30, '04_LOG_FIELD_ENTRIES'!$D:$D, C30, '04_LOG_FIELD_ENTRIES'!$K:$K, "EV_PRODUCCION")) | I30: =IF(B30 > MAX('04_LOG_FIELD_ENTRIES'!$B:$B), "", SUMIFS(H$2:H30, C$2:C30, C30)) | J30: =IF(B30 > MAX('04_LOG_FIELD_ENTRIES'!$B:$B), "", SUMIFS('04_LOG_FIELD_ENTRIES'!$J:$J, '04_LOG_FIELD_ENTRIES'!$B:$B, B30, '04_LOG_FIELD_ENTRIES'!$D:$D, C30, '04_LOG_FIELD_ENTRIES'!$K:$K, "AC_*")) | K30: =IF(B30 > MAX('04_LOG_FIELD_ENTRIES'!$B:$B), "", SUMIFS(J$2:J30, C$2:C30, C30)) | L30: =IF(K30="", "", I30-K30) | M30: =IF(I30="", "", I30-G30) | N30: =IF(I30="", "", IF(G30>0, I30/G30, 1)) | O30: =IF(I30="", "", IF(K30>0, I30/K30, 1)) | P30: =IF(I30="", "", IF(AND(N30>=0.95, O30>=0.95), "SALUDABLE", IF(N30<0.9, "ALERTA RETRASO", "ALERTA SOBRECOSTO")))
A31: 8 | B31: 46242 | C31: WBS-200 | D31: Red de Alcantarillado, Zanjas y Buzones | E31: =SUM('01_PRESUPUESTO_CRONOGRAMA_BASE'!G4:G9) | F31: =SUMIFS('02_CRONOGRAMA_PV_DIARIO'!E:E, '02_CRONOGRAMA_PV_DIARIO'!A:A, A31, '02_CRONOGRAMA_PV_DIARIO'!C:C, C31) | G31: =SUMIFS(F$2:F31, C$2:C31, C31) | H31: =IF(B31 > MAX('04_LOG_FIELD_ENTRIES'!$B:$B), "", SUMIFS('04_LOG_FIELD_ENTRIES'!$J:$J, '04_LOG_FIELD_ENTRIES'!$B:$B, B31, '04_LOG_FIELD_ENTRIES'!$D:$D, C31, '04_LOG_FIELD_ENTRIES'!$K:$K, "EV_PRODUCCION")) | I31: =IF(B31 > MAX('04_LOG_FIELD_ENTRIES'!$B:$B), "", SUMIFS(H$2:H31, C$2:C31, C31)) | J31: =IF(B31 > MAX('04_LOG_FIELD_ENTRIES'!$B:$B), "", SUMIFS('04_LOG_FIELD_ENTRIES'!$J:$J, '04_LOG_FIELD_ENTRIES'!$B:$B, B31, '04_LOG_FIELD_ENTRIES'!$D:$D, C31, '04_LOG_FIELD_ENTRIES'!$K:$K, "AC_*")) | K31: =IF(B31 > MAX('04_LOG_FIELD_ENTRIES'!$B:$B), "", SUMIFS(J$2:J31, C$2:C31, C31)) | L31: =IF(K31="", "", I31-K31) | M31: =IF(I31="", "", I31-G31) | N31: =IF(I31="", "", IF(G31>0, I31/G31, 1)) | O31: =IF(I31="", "", IF(K31>0, I31/K31, 1)) | P31: =IF(I31="", "", IF(AND(N31>=0.95, O31>=0.95), "SALUDABLE", IF(N31<0.9, "ALERTA RETRASO", "ALERTA SOBRECOSTO")))
A32: 8 | B32: 46242 | C32: WBS-300 | D32: Red de Agua Potable y Conexiones Domiciliarias | E32: =SUM('01_PRESUPUESTO_CRONOGRAMA_BASE'!G10:G11) | F32: =SUMIFS('02_CRONOGRAMA_PV_DIARIO'!E:E, '02_CRONOGRAMA_PV_DIARIO'!A:A, A32, '02_CRONOGRAMA_PV_DIARIO'!C:C, C32) | G32: =SUMIFS(F$2:F32, C$2:C32, C32) | H32: =IF(B32 > MAX('04_LOG_FIELD_ENTRIES'!$B:$B), "", SUMIFS('04_LOG_FIELD_ENTRIES'!$J:$J, '04_LOG_FIELD_ENTRIES'!$B:$B, B32, '04_LOG_FIELD_ENTRIES'!$D:$D, C32, '04_LOG_FIELD_ENTRIES'!$K:$K, "EV_PRODUCCION")) | I32: =IF(B32 > MAX('04_LOG_FIELD_ENTRIES'!$B:$B), "", SUMIFS(H$2:H32, C$2:C32, C32)) | J32: =IF(B32 > MAX('04_LOG_FIELD_ENTRIES'!$B:$B), "", SUMIFS('04_LOG_FIELD_ENTRIES'!$J:$J, '04_LOG_FIELD_ENTRIES'!$B:$B, B32, '04_LOG_FIELD_ENTRIES'!$D:$D, C32, '04_LOG_FIELD_ENTRIES'!$K:$K, "AC_*")) | K32: =IF(B32 > MAX('04_LOG_FIELD_ENTRIES'!$B:$B), "", SUMIFS(J$2:J32, C$2:C32, C32)) | L32: =IF(K32="", "", I32-K32) | M32: =IF(I32="", "", I32-G32) | N32: =IF(I32="", "", IF(G32>0, I32/G32, 1)) | O32: =IF(I32="", "", IF(K32>0, I32/K32, 1)) | P32: =IF(I32="", "", IF(AND(N32>=0.95, O32>=0.95), "SALUDABLE", IF(N32<0.9, "ALERTA RETRASO", "ALERTA SOBRECOSTO")))
