Workbook

Sheet 01_PRESUPUESTO_CRONOGRAMA_BASE
A1: Item | B1: Código WBS | C1: Descripción de la Partida Presupuestal | D1: Unidad | E1: Metrado Meta | F1: P.U. Directo (S/) | G1: Parcial Directo (S/) | H1: Fecha Inicio | I1: Fecha Fin | J1: Duración (Días) | K1: Día Inicio Obra | L1: Día Fin Obra | M1: Tasa PV Diario (S/Día)
A2: 01.01 | B2: WBS-100 | C2: Obras Preliminares y Trabajos Provisionales | D2: GLB | E2: 1 | F2: 8296.4 | G2: =ROUND(E2*F2, 2) -> 8296.4 | H2: 2026-08-01 | I2: 2026-08-14 | J2: =(L2-K2)+1 -> 14 | K2: 1 | L2: 14 | M2: =ROUND(G2/J2, 2) -> 592.6
A3: 01.02.01 | B3: WBS-100 | C3: Trazo, Nivelación y Replanteo de Zanjas | D3: M | E3: 2400 | F3: 3.35 | G3: =ROUND(E3*F3, 2) -> 8040 | H3: 2026-08-01 | I3: 2026-08-14 | J3: =(L3-K3)+1 -> 14 | K3: 1 | L3: 14 | M3: =ROUND(G3/J3, 2) -> 574.29
A4: 01.02.02 | B4: WBS-200 | C4: Excavación de Zanja H=1.50m - 2.20m a Máquina (Terreno Normal) | D4: M3 | E4: 3840 | F4: 11.66 | G4: =ROUND(E4*F4, 2) -> 44774.4 | H4: 2026-08-10 | I4: 2026-08-25 | J4: =(L4-K4)+1 -> 16 | K4: 10 | L4: 25 | M4: =ROUND(G4/J4, 2) -> 2798.4
A5: 01.02.03 | B5: WBS-200 | C5: Preparación y Colocación de Cama de Arena e=0.10m | D5: M | E5: 2400 | F5: 11.12 | G5: =ROUND(E5*F5, 2) -> 26688 | H5: 2026-08-12 | I5: 2026-08-28 | J5: =(L5-K5)+1 -> 17 | K5: 12 | L5: 28 | M5: =ROUND(G5/J5, 2) -> 1569.88
A6: 01.02.04 | B6: WBS-200 | C6: Suministro e Instalación de Tubería PVC UF DN 200mm Serie S-20 para Alcantarillado | D6: M | E6: 1400 | F6: 55.51 | G6: =ROUND(E6*F6, 2) -> 77714 | H6: 2026-08-15 | I6: 2026-08-31 | J6: =(L6-K6)+1 -> 17 | K6: 15 | L6: 31 | M6: =ROUND(G6/J6, 2) -> 4571.41
A7: 01.02.05 | B7: WBS-200 | C7: Relleno Compactado de Zanja en Capas de 0.20m con Maquinaria/Plancha | D7: M3 | E7: 3300 | F7: 28.54 | G7: =ROUND(E7*F7, 2) -> 94182 | H7: 2026-08-18 | I7: 2026-09-05 | J7: =(L7-K7)+1 -> 19 | K7: 18 | L7: 36 | M7: =ROUND(G7/J7, 2) -> 4956.95
A8: 01.02.06 | B8: WBS-200 | C8: Construcción de Buzones Prefabricados de Concreto h=1.50m - 2.50m (Inc. Marco y Tapa) | D8: UND | E8: 32 | F8: 2500.73 | G8: =ROUND(E8*F8, 2) -> 80023.36 | H8: 2026-08-22 | I8: 2026-09-10 | J8: =(L8-K8)+1 -> 20 | K8: 22 | L8: 41 | M8: =ROUND(G8/J8, 2) -> 4001.17
A9: 01.02.07 | B9: WBS-200 | C9: Conexiones Domiciliarias de Alcantarillado (Caja de Registro + Acometida) | D9: UND | E9: 120 | F9: 405.54 | G9: =ROUND(E9*F9, 2) -> 48664.8 | H9: 2026-08-28 | I9: 2026-09-12 | J9: =(L9-K9)+1 -> 16 | K9: 28 | L9: 43 | M9: =ROUND(G9/J9, 2) -> 3041.55
A10: 01.03.01 | B10: WBS-300 | C10: Suministro e Instalación de Tubería PVC C-10 DN 110mm para Agua Potable | D10: M | E10: 1000 | F10: 38.76 | G10: =ROUND(E10*F10, 2) -> 38760 | H10: 2026-08-22 | I10: 2026-09-12 | J10: =(L10-K10)+1 -> 22 | K10: 22 | L10: 43 | M10: =ROUND(G10/J10, 2) -> 1761.82
A11: 01.03.02 | B11: WBS-300 | C11: Conexiones Domiciliarias de Agua Potable (Caja de Agua + Abrazadera + Acometida) | D11: UND | E11: 120 | F11: 156.71 | G11: =ROUND(E11*F11, 2) -> 18805.2 | H11: 2026-09-01 | I11: 2026-09-20 | J11: =(L11-K11)+1 -> 20 | K11: 32 | L11: 51 | M11: =ROUND(G11/J11, 2) -> 940.26
A12: 01.04.01 | B12: WBS-400 | C12: Pruebas Hidráulicas de Redes de Agua y Alcantarillado + Desinfección | D12: GLB | E12: 1 | F12: 9348.06 | G12: =ROUND(E12*F12, 2) -> 9348.06 | H12: 2026-09-17 | I12: 2026-09-29 | J12: =(L12-K12)+1 -> 13 | K12: 48 | L12: 60 | M12: =ROUND(G12/J12, 2) -> 719.08
C13: COSTO DIRECTO TOTAL (S/) | G13: =SUM(G2:G12) -> 455296.22
C14: GASTOS GENERALES (10.00%) | G14: =ROUND(G13*0.1, 2) -> 45529.62
C15: UTILIDAD (8.00%) | G15: =ROUND(G13*0.08, 2) -> 36423.7
C16: SUB TOTAL / VALOR VENTA (SIN IGV) | G16: =SUM(G13:G15) -> 537249.54
C17: IMPUESTO GENERAL A LAS VENTAS (IGV 18%) | G17: =ROUND(G16*0.18, 2) -> 96704.92
C18: PRECIO TOTAL COMERCIAL DE OBRA (CON IGV) | G18: =G16+G17 -> 633954.46

Sheet 02_CRONOGRAMA_PV_DIARIO
A1: N° Día Obra | B1: Fecha Obra | C1: Código WBS | D1: Nombre Frente WBS | E1: PV Diario Programado (S/) | F1: PV Acumulado WBS (S/)
A2: 1 | B2: 2026-08-01 | C2: WBS-100 | D2: Obras Preliminares, Trazo y Movilización | E2: =IF(AND(A2>='01_PRESUPUESTO_CRONOGRAMA_BASE'!K2, A2<='01_PRESUPUESTO_CRONOGRAMA_BASE'!L2), '01_PRESUPUESTO_CRONOGRAMA_BASE'!M2, 0) + IF(AND(A2>='01_PRESUPUESTO_CRONOGRAMA_BASE'!K3, A2<='01_PRESUPUESTO_CRONOGRAMA_BASE'!L3), '01_PRESUPUESTO_CRONOGRAMA_BASE'!M3, 0) -> 1166.89 | F2: =SUMIFS(E$2:E2, C$2:C2, C2) -> 1166.89
A3: 1 | B3: 2026-08-01 | C3: WBS-200 | D3: Red de Alcantarillado, Zanjas y Buzones | E3: =IF(AND(A3>='01_PRESUPUESTO_CRONOGRAMA_BASE'!K4, A3<='01_PRESUPUESTO_CRONOGRAMA_BASE'!L4), '01_PRESUPUESTO_CRONOGRAMA_BASE'!M4, 0) + IF(AND(A3>='01_PRESUPUESTO_CRONOGRAMA_BASE'!K5, A3<='01_PRESUPUESTO_CRONOGRAMA_BASE'!L5), '01_PRESUPUESTO_CRONOGRAMA_BASE'!M5, 0) + IF(AND(A3>='01_PRESUPUESTO_CRONOGRAMA_BASE'!K6, A3<='01_PRESUPUESTO_CRONOGRAMA_BASE'!L6), '01_PRESUPUESTO_CRONOGRAMA_BASE'!M6, 0) + IF(AND(A3>='01_PRESUPUESTO_CRONOGRAMA_BASE'!K7, A3<='01_PRESUPUESTO_CRONOGRAMA_BASE'!L7), '01_PRESUPUESTO_CRONOGRAMA_BASE'!M7, 0) + IF(AND(A3>='01_PRESUPUESTO_CRONOGRAMA_BASE'!K8, A3<='01_PRESUPUESTO_CRONOGRAMA_BASE'!L8), '01_PRESUPUESTO_CRONOGRAMA_BASE'!M8, 0) + IF(AND(A3>='01_PRESUPUESTO_CRONOGRAMA_BASE'!K9, A3<='01_PRESUPUESTO_CRONOGRAMA_BASE'!L9), '01_PRESUPUESTO_CRONOGRAMA_BASE'!M9, 0) -> 0 | F3: =SUMIFS(E$2:E3, C$2:C3, C3) -> 0
A4: 1 | B4: 2026-08-01 | C4: WBS-300 | D4: Red de Agua Potable y Conexiones Domiciliarias | E4: =IF(AND(A4>='01_PRESUPUESTO_CRONOGRAMA_BASE'!K10, A4<='01_PRESUPUESTO_CRONOGRAMA_BASE'!L10), '01_PRESUPUESTO_CRONOGRAMA_BASE'!M10, 0) + IF(AND(A4>='01_PRESUPUESTO_CRONOGRAMA_BASE'!K11, A4<='01_PRESUPUESTO_CRONOGRAMA_BASE'!L11), '01_PRESUPUESTO_CRONOGRAMA_BASE'!M11, 0) -> 0 | F4: =SUMIFS(E$2:E4, C$2:C4, C4) -> 0
A5: 1 | B5: 2026-08-01 | C5: WBS-400 | D5: Pruebas Hidráulicas, Desinfección y Entrega | E5: =IF(AND(A5>='01_PRESUPUESTO_CRONOGRAMA_BASE'!K12, A5<='01_PRESUPUESTO_CRONOGRAMA_BASE'!L12), '01_PRESUPUESTO_CRONOGRAMA_BASE'!M12, 0) -> 0 | F5: =SUMIFS(E$2:E5, C$2:C5, C5) -> 0
A6: 2 | B6: 2026-08-02 | C6: WBS-100 | D6: Obras Preliminares, Trazo y Movilización | E6: =IF(AND(A6>='01_PRESUPUESTO_CRONOGRAMA_BASE'!K2, A6<='01_PRESUPUESTO_CRONOGRAMA_BASE'!L2), '01_PRESUPUESTO_CRONOGRAMA_BASE'!M2, 0) + IF(AND(A6>='01_PRESUPUESTO_CRONOGRAMA_BASE'!K3, A6<='01_PRESUPUESTO_CRONOGRAMA_BASE'!L3), '01_PRESUPUESTO_CRONOGRAMA_BASE'!M3, 0) -> 1166.89 | F6: =SUMIFS(E$2:E6, C$2:C6, C6) -> 2333.78
A7: 2 | B7: 2026-08-02 | C7: WBS-200 | D7: Red de Alcantarillado, Zanjas y Buzones | E7: =IF(AND(A7>='01_PRESUPUESTO_CRONOGRAMA_BASE'!K4, A7<='01_PRESUPUESTO_CRONOGRAMA_BASE'!L4), '01_PRESUPUESTO_CRONOGRAMA_BASE'!M4, 0) + IF(AND(A7>='01_PRESUPUESTO_CRONOGRAMA_BASE'!K5, A7<='01_PRESUPUESTO_CRONOGRAMA_BASE'!L5), '01_PRESUPUESTO_CRONOGRAMA_BASE'!M5, 0) + IF(AND(A7>='01_PRESUPUESTO_CRONOGRAMA_BASE'!K6, A7<='01_PRESUPUESTO_CRONOGRAMA_BASE'!L6), '01_PRESUPUESTO_CRONOGRAMA_BASE'!M6, 0) + IF(AND(A7>='01_PRESUPUESTO_CRONOGRAMA_BASE'!K7, A7<='01_PRESUPUESTO_CRONOGRAMA_BASE'!L7), '01_PRESUPUESTO_CRONOGRAMA_BASE'!M7, 0) + IF(AND(A7>='01_PRESUPUESTO_CRONOGRAMA_BASE'!K8, A7<='01_PRESUPUESTO_CRONOGRAMA_BASE'!L8), '01_PRESUPUESTO_CRONOGRAMA_BASE'!M8, 0) + IF(AND(A7>='01_PRESUPUESTO_CRONOGRAMA_BASE'!K9, A7<='01_PRESUPUESTO_CRONOGRAMA_BASE'!L9), '01_PRESUPUESTO_CRONOGRAMA_BASE'!M9, 0) -> 0 | F7: =SUMIFS(E$2:E7, C$2:C7, C7) -> 0
A8: 2 | B8: 2026-08-02 | C8: WBS-300 | D8: Red de Agua Potable y Conexiones Domiciliarias | E8: =IF(AND(A8>='01_PRESUPUESTO_CRONOGRAMA_BASE'!K10, A8<='01_PRESUPUESTO_CRONOGRAMA_BASE'!L10), '01_PRESUPUESTO_CRONOGRAMA_BASE'!M10, 0) + IF(AND(A8>='01_PRESUPUESTO_CRONOGRAMA_BASE'!K11, A8<='01_PRESUPUESTO_CRONOGRAMA_BASE'!L11), '01_PRESUPUESTO_CRONOGRAMA_BASE'!M11, 0) -> 0 | F8: =SUMIFS(E$2:E8, C$2:C8, C8) -> 0
A9: 2 | B9: 2026-08-02 | C9: WBS-400 | D9: Pruebas Hidráulicas, Desinfección y Entrega | E9: =IF(AND(A9>='01_PRESUPUESTO_CRONOGRAMA_BASE'!K12, A9<='01_PRESUPUESTO_CRONOGRAMA_BASE'!L12), '01_PRESUPUESTO_CRONOGRAMA_BASE'!M12, 0) -> 0 | F9: =SUMIFS(E$2:E9, C$2:C9, C9) -> 0
A10: 3 | B10: 2026-08-03 | C10: WBS-100 | D10: Obras Preliminares, Trazo y Movilización | E10: =IF(AND(A10>='01_PRESUPUESTO_CRONOGRAMA_BASE'!K2, A10<='01_PRESUPUESTO_CRONOGRAMA_BASE'!L2), '01_PRESUPUESTO_CRONOGRAMA_BASE'!M2, 0) + IF(AND(A10>='01_PRESUPUESTO_CRONOGRAMA_BASE'!K3, A10<='01_PRESUPUESTO_CRONOGRAMA_BASE'!L3), '01_PRESUPUESTO_CRONOGRAMA_BASE'!M3, 0) -> 1166.89 | F10: =SUMIFS(E$2:E10, C$2:C10, C10) -> 3500.67
A11: 3 | B11: 2026-08-03 | C11: WBS-200 | D11: Red de Alcantarillado, Zanjas y Buzones | E11: =IF(AND(A11>='01_PRESUPUESTO_CRONOGRAMA_BASE'!K4, A11<='01_PRESUPUESTO_CRONOGRAMA_BASE'!L4), '01_PRESUPUESTO_CRONOGRAMA_BASE'!M4, 0) + IF(AND(A11>='01_PRESUPUESTO_CRONOGRAMA_BASE'!K5, A11<='01_PRESUPUESTO_CRONOGRAMA_BASE'!L5), '01_PRESUPUESTO_CRONOGRAMA_BASE'!M5, 0) + IF(AND(A11>='01_PRESUPUESTO_CRONOGRAMA_BASE'!K6, A11<='01_PRESUPUESTO_CRONOGRAMA_BASE'!L6), '01_PRESUPUESTO_CRONOGRAMA_BASE'!M6, 0) + IF(AND(A11>='01_PRESUPUESTO_CRONOGRAMA_BASE'!K7, A11<='01_PRESUPUESTO_CRONOGRAMA_BASE'!L7), '01_PRESUPUESTO_CRONOGRAMA_BASE'!M7, 0) + IF(AND(A11>='01_PRESUPUESTO_CRONOGRAMA_BASE'!K8, A11<='01_PRESUPUESTO_CRONOGRAMA_BASE'!L8), '01_PRESUPUESTO_CRONOGRAMA_BASE'!M8, 0) + IF(AND(A11>='01_PRESUPUESTO_CRONOGRAMA_BASE'!K9, A11<='01_PRESUPUESTO_CRONOGRAMA_BASE'!L9), '01_PRESUPUESTO_CRONOGRAMA_BASE'!M9, 0) -> 0 | F11: =SUMIFS(E$2:E11, C$2:C11, C11) -> 0
A12: 3 | B12: 2026-08-03 | C12: WBS-300 | D12: Red de Agua Potable y Conexiones Domiciliarias | E12: =IF(AND(A12>='01_PRESUPUESTO_CRONOGRAMA_BASE'!K10, A12<='01_PRESUPUESTO_CRONOGRAMA_BASE'!L10), '01_PRESUPUESTO_CRONOGRAMA_BASE'!M10, 0) + IF(AND(A12>='01_PRESUPUESTO_CRONOGRAMA_BASE'!K11, A12<='01_PRESUPUESTO_CRONOGRAMA_BASE'!L11), '01_PRESUPUESTO_CRONOGRAMA_BASE'!M11, 0) -> 0 | F12: =SUMIFS(E$2:E12, C$2:C12, C12) -> 0
A13: 3 | B13: 2026-08-03 | C13: WBS-400 | D13: Pruebas Hidráulicas, Desinfección y Entrega | E13: =IF(AND(A13>='01_PRESUPUESTO_CRONOGRAMA_BASE'!K12, A13<='01_PRESUPUESTO_CRONOGRAMA_BASE'!L12), '01_PRESUPUESTO_CRONOGRAMA_BASE'!M12, 0) -> 0 | F13: =SUMIFS(E$2:E13, C$2:C13, C13) -> 0
A14: 4 | B14: 2026-08-04 | C14: WBS-100 | D14: Obras Preliminares, Trazo y Movilización | E14: =IF(AND(A14>='01_PRESUPUESTO_CRONOGRAMA_BASE'!K2, A14<='01_PRESUPUESTO_CRONOGRAMA_BASE'!L2), '01_PRESUPUESTO_CRONOGRAMA_BASE'!M2, 0) + IF(AND(A14>='01_PRESUPUESTO_CRONOGRAMA_BASE'!K3, A14<='01_PRESUPUESTO_CRONOGRAMA_BASE'!L3), '01_PRESUPUESTO_CRONOGRAMA_BASE'!M3, 0) -> 1166.89 | F14: =SUMIFS(E$2:E14, C$2:C14, C14) -> 4667.56
A15: 4 | B15: 2026-08-04 | C15: WBS-200 | D15: Red de Alcantarillado, Zanjas y Buzones | E15: =IF(AND(A15>='01_PRESUPUESTO_CRONOGRAMA_BASE'!K4, A15<='01_PRESUPUESTO_CRONOGRAMA_BASE'!L4), '01_PRESUPUESTO_CRONOGRAMA_BASE'!M4, 0) + IF(AND(A15>='01_PRESUPUESTO_CRONOGRAMA_BASE'!K5, A15<='01_PRESUPUESTO_CRONOGRAMA_BASE'!L5), '01_PRESUPUESTO_CRONOGRAMA_BASE'!M5, 0) + IF(AND(A15>='01_PRESUPUESTO_CRONOGRAMA_BASE'!K6, A15<='01_PRESUPUESTO_CRONOGRAMA_BASE'!L6), '01_PRESUPUESTO_CRONOGRAMA_BASE'!M6, 0) + IF(AND(A15>='01_PRESUPUESTO_CRONOGRAMA_BASE'!K7, A15<='01_PRESUPUESTO_CRONOGRAMA_BASE'!L7), '01_PRESUPUESTO_CRONOGRAMA_BASE'!M7, 0) + IF(AND(A15>='01_PRESUPUESTO_CRONOGRAMA_BASE'!K8, A15<='01_PRESUPUESTO_CRONOGRAMA_BASE'!L8), '01_PRESUPUESTO_CRONOGRAMA_BASE'!M8, 0) + IF(AND(A15>='01_PRESUPUESTO_CRONOGRAMA_BASE'!K9, A15<='01_PRESUPUESTO_CRONOGRAMA_BASE'!L9), '01_PRESUPUESTO_CRONOGRAMA_BASE'!M9, 0) -> 0 | F15: =SUMIFS(E$2:E15, C$2:C15, C15) -> 0
A16: 4 | B16: 2026-08-04 | C16: WBS-300 | D16: Red de Agua Potable y Conexiones Domiciliarias | E16: =IF(AND(A16>='01_PRESUPUESTO_CRONOGRAMA_BASE'!K10, A16<='01_PRESUPUESTO_CRONOGRAMA_BASE'!L10), '01_PRESUPUESTO_CRONOGRAMA_BASE'!M10, 0) + IF(AND(A16>='01_PRESUPUESTO_CRONOGRAMA_BASE'!K11, A16<='01_PRESUPUESTO_CRONOGRAMA_BASE'!L11), '01_PRESUPUESTO_CRONOGRAMA_BASE'!M11, 0) -> 0 | F16: =SUMIFS(E$2:E16, C$2:C16, C16) -> 0
A17: 4 | B17: 2026-08-04 | C17: WBS-400 | D17: Pruebas Hidráulicas, Desinfección y Entrega | E17: =IF(AND(A17>='01_PRESUPUESTO_CRONOGRAMA_BASE'!K12, A17<='01_PRESUPUESTO_CRONOGRAMA_BASE'!L12), '01_PRESUPUESTO_CRONOGRAMA_BASE'!M12, 0) -> 0 | F17: =SUMIFS(E$2:E17, C$2:C17, C17) -> 0
A18: 5 | B18: 2026-08-05 | C18: WBS-100 | D18: Obras Preliminares, Trazo y Movilización | E18: =IF(AND(A18>='01_PRESUPUESTO_CRONOGRAMA_BASE'!K2, A18<='01_PRESUPUESTO_CRONOGRAMA_BASE'!L2), '01_PRESUPUESTO_CRONOGRAMA_BASE'!M2, 0) + IF(AND(A18>='01_PRESUPUESTO_CRONOGRAMA_BASE'!K3, A18<='01_PRESUPUESTO_CRONOGRAMA_BASE'!L3), '01_PRESUPUESTO_CRONOGRAMA_BASE'!M3, 0) -> 1166.89 | F18: =SUMIFS(E$2:E18, C$2:C18, C18) -> 5834.45
A19: 5 | B19: 2026-08-05 | C19: WBS-200 | D19: Red de Alcantarillado, Zanjas y Buzones | E19: =IF(AND(A19>='01_PRESUPUESTO_CRONOGRAMA_BASE'!K4, A19<='01_PRESUPUESTO_CRONOGRAMA_BASE'!L4), '01_PRESUPUESTO_CRONOGRAMA_BASE'!M4, 0) + IF(AND(A19>='01_PRESUPUESTO_CRONOGRAMA_BASE'!K5, A19<='01_PRESUPUESTO_CRONOGRAMA_BASE'!L5), '01_PRESUPUESTO_CRONOGRAMA_BASE'!M5, 0) + IF(AND(A19>='01_PRESUPUESTO_CRONOGRAMA_BASE'!K6, A19<='01_PRESUPUESTO_CRONOGRAMA_BASE'!L6), '01_PRESUPUESTO_CRONOGRAMA_BASE'!M6, 0) + IF(AND(A19>='01_PRESUPUESTO_CRONOGRAMA_BASE'!K7, A19<='01_PRESUPUESTO_CRONOGRAMA_BASE'!L7), '01_PRESUPUESTO_CRONOGRAMA_BASE'!M7, 0) + IF(AND(A19>='01_PRESUPUESTO_CRONOGRAMA_BASE'!K8, A19<='01_PRESUPUESTO_CRONOGRAMA_BASE'!L8), '01_PRESUPUESTO_CRONOGRAMA_BASE'!M8, 0) + IF(AND(A19>='01_PRESUPUESTO_CRONOGRAMA_BASE'!K9, A19<='01_PRESUPUESTO_CRONOGRAMA_BASE'!L9), '01_PRESUPUESTO_CRONOGRAMA_BASE'!M9, 0) -> 0 | F19: =SUMIFS(E$2:E19, C$2:C19, C19) -> 0
A20: 5 | B20: 2026-08-05 | C20: WBS-300 | D20: Red de Agua Potable y Conexiones Domiciliarias | E20: =IF(AND(A20>='01_PRESUPUESTO_CRONOGRAMA_BASE'!K10, A20<='01_PRESUPUESTO_CRONOGRAMA_BASE'!L10), '01_PRESUPUESTO_CRONOGRAMA_BASE'!M10, 0) + IF(AND(A20>='01_PRESUPUESTO_CRONOGRAMA_BASE'!K11, A20<='01_PRESUPUESTO_CRONOGRAMA_BASE'!L11), '01_PRESUPUESTO_CRONOGRAMA_BASE'!M11, 0) -> 0 | F20: =SUMIFS(E$2:E20, C$2:C20, C20) -> 0
A21: 5 | B21: 2026-08-05 | C21: WBS-400 | D21: Pruebas Hidráulicas, Desinfección y Entrega | E21: =IF(AND(A21>='01_PRESUPUESTO_CRONOGRAMA_BASE'!K12, A21<='01_PRESUPUESTO_CRONOGRAMA_BASE'!L12), '01_PRESUPUESTO_CRONOGRAMA_BASE'!M12, 0) -> 0 | F21: =SUMIFS(E$2:E21, C$2:C21, C21) -> 0
A22: 6 | B22: 2026-08-06 | C22: WBS-100 | D22: Obras Preliminares, Trazo y Movilización | E22: =IF(AND(A22>='01_PRESUPUESTO_CRONOGRAMA_BASE'!K2, A22<='01_PRESUPUESTO_CRONOGRAMA_BASE'!L2), '01_PRESUPUESTO_CRONOGRAMA_BASE'!M2, 0) + IF(AND(A22>='01_PRESUPUESTO_CRONOGRAMA_BASE'!K3, A22<='01_PRESUPUESTO_CRONOGRAMA_BASE'!L3), '01_PRESUPUESTO_CRONOGRAMA_BASE'!M3, 0) -> 1166.89 | F22: =SUMIFS(E$2:E22, C$2:C22, C22) -> 7001.34
A23: 6 | B23: 2026-08-06 | C23: WBS-200 | D23: Red de Alcantarillado, Zanjas y Buzones | E23: =IF(AND(A23>='01_PRESUPUESTO_CRONOGRAMA_BASE'!K4, A23<='01_PRESUPUESTO_CRONOGRAMA_BASE'!L4), '01_PRESUPUESTO_CRONOGRAMA_BASE'!M4, 0) + IF(AND(A23>='01_PRESUPUESTO_CRONOGRAMA_BASE'!K5, A23<='01_PRESUPUESTO_CRONOGRAMA_BASE'!L5), '01_PRESUPUESTO_CRONOGRAMA_BASE'!M5, 0) + IF(AND(A23>='01_PRESUPUESTO_CRONOGRAMA_BASE'!K6, A23<='01_PRESUPUESTO_CRONOGRAMA_BASE'!L6), '01_PRESUPUESTO_CRONOGRAMA_BASE'!M6, 0) + IF(AND(A23>='01_PRESUPUESTO_CRONOGRAMA_BASE'!K7, A23<='01_PRESUPUESTO_CRONOGRAMA_BASE'!L7), '01_PRESUPUESTO_CRONOGRAMA_BASE'!M7, 0) + IF(AND(A23>='01_PRESUPUESTO_CRONOGRAMA_BASE'!K8, A23<='01_PRESUPUESTO_CRONOGRAMA_BASE'!L8), '01_PRESUPUESTO_CRONOGRAMA_BASE'!M8, 0) + IF(AND(A23>='01_PRESUPUESTO_CRONOGRAMA_BASE'!K9, A23<='01_PRESUPUESTO_CRONOGRAMA_BASE'!L9), '01_PRESUPUESTO_CRONOGRAMA_BASE'!M9, 0) -> 0 | F23: =SUMIFS(E$2:E23, C$2:C23, C23) -> 0
A24: 6 | B24: 2026-08-06 | C24: WBS-300 | D24: Red de Agua Potable y Conexiones Domiciliarias | E24: =IF(AND(A24>='01_PRESUPUESTO_CRONOGRAMA_BASE'!K10, A24<='01_PRESUPUESTO_CRONOGRAMA_BASE'!L10), '01_PRESUPUESTO_CRONOGRAMA_BASE'!M10, 0) + IF(AND(A24>='01_PRESUPUESTO_CRONOGRAMA_BASE'!K11, A24<='01_PRESUPUESTO_CRONOGRAMA_BASE'!L11), '01_PRESUPUESTO_CRONOGRAMA_BASE'!M11, 0) -> 0 | F24: =SUMIFS(E$2:E24, C$2:C24, C24) -> 0
A25: 6 | B25: 2026-08-06 | C25: WBS-400 | D25: Pruebas Hidráulicas, Desinfección y Entrega | E25: =IF(AND(A25>='01_PRESUPUESTO_CRONOGRAMA_BASE'!K12, A25<='01_PRESUPUESTO_CRONOGRAMA_BASE'!L12), '01_PRESUPUESTO_CRONOGRAMA_BASE'!M12, 0) -> 0 | F25: =SUMIFS(E$2:E25, C$2:C25, C25) -> 0
A26: 7 | B26: 2026-08-07 | C26: WBS-100 | D26: Obras Preliminares, Trazo y Movilización | E26: =IF(AND(A26>='01_PRESUPUESTO_CRONOGRAMA_BASE'!K2, A26<='01_PRESUPUESTO_CRONOGRAMA_BASE'!L2), '01_PRESUPUESTO_CRONOGRAMA_BASE'!M2, 0) + IF(AND(A26>='01_PRESUPUESTO_CRONOGRAMA_BASE'!K3, A26<='01_PRESUPUESTO_CRONOGRAMA_BASE'!L3), '01_PRESUPUESTO_CRONOGRAMA_BASE'!M3, 0) -> 1166.89 | F26: =SUMIFS(E$2:E26, C$2:C26, C26) -> 8168.23
A27: 7 | B27: 2026-08-07 | C27: WBS-200 | D27: Red de Alcantarillado, Zanjas y Buzones | E27: =IF(AND(A27>='01_PRESUPUESTO_CRONOGRAMA_BASE'!K4, A27<='01_PRESUPUESTO_CRONOGRAMA_BASE'!L4), '01_PRESUPUESTO_CRONOGRAMA_BASE'!M4, 0) + IF(AND(A27>='01_PRESUPUESTO_CRONOGRAMA_BASE'!K5, A27<='01_PRESUPUESTO_CRONOGRAMA_BASE'!L5), '01_PRESUPUESTO_CRONOGRAMA_BASE'!M5, 0) + IF(AND(A27>='01_PRESUPUESTO_CRONOGRAMA_BASE'!K6, A27<='01_PRESUPUESTO_CRONOGRAMA_BASE'!L6), '01_PRESUPUESTO_CRONOGRAMA_BASE'!M6, 0) + IF(AND(A27>='01_PRESUPUESTO_CRONOGRAMA_BASE'!K7, A27<='01_PRESUPUESTO_CRONOGRAMA_BASE'!L7), '01_PRESUPUESTO_CRONOGRAMA_BASE'!M7, 0) + IF(AND(A27>='01_PRESUPUESTO_CRONOGRAMA_BASE'!K8, A27<='01_PRESUPUESTO_CRONOGRAMA_BASE'!L8), '01_PRESUPUESTO_CRONOGRAMA_BASE'!M8, 0) + IF(AND(A27>='01_PRESUPUESTO_CRONOGRAMA_BASE'!K9, A27<='01_PRESUPUESTO_CRONOGRAMA_BASE'!L9), '01_PRESUPUESTO_CRONOGRAMA_BASE'!M9, 0) -> 0 | F27: =SUMIFS(E$2:E27, C$2:C27, C27) -> 0
A28: 7 | B28: 2026-08-07 | C28: WBS-300 | D28: Red de Agua Potable y Conexiones Domiciliarias | E28: =IF(AND(A28>='01_PRESUPUESTO_CRONOGRAMA_BASE'!K10, A28<='01_PRESUPUESTO_CRONOGRAMA_BASE'!L10), '01_PRESUPUESTO_CRONOGRAMA_BASE'!M10, 0) + IF(AND(A28>='01_PRESUPUESTO_CRONOGRAMA_BASE'!K11, A28<='01_PRESUPUESTO_CRONOGRAMA_BASE'!L11), '01_PRESUPUESTO_CRONOGRAMA_BASE'!M11, 0) -> 0 | F28: =SUMIFS(E$2:E28, C$2:C28, C28) -> 0
A29: 7 | B29: 2026-08-07 | C29: WBS-400 | D29: Pruebas Hidráulicas, Desinfección y Entrega | E29: =IF(AND(A29>='01_PRESUPUESTO_CRONOGRAMA_BASE'!K12, A29<='01_PRESUPUESTO_CRONOGRAMA_BASE'!L12), '01_PRESUPUESTO_CRONOGRAMA_BASE'!M12, 0) -> 0 | F29: =SUMIFS(E$2:E29, C$2:C29, C29) -> 0
A30: 8 | B30: 2026-08-08 | C30: WBS-100 | D30: Obras Preliminares, Trazo y Movilización | E30: =IF(AND(A30>='01_PRESUPUESTO_CRONOGRAMA_BASE'!K2, A30<='01_PRESUPUESTO_CRONOGRAMA_BASE'!L2), '01_PRESUPUESTO_CRONOGRAMA_BASE'!M2, 0) + IF(AND(A30>='01_PRESUPUESTO_CRONOGRAMA_BASE'!K3, A30<='01_PRESUPUESTO_CRONOGRAMA_BASE'!L3), '01_PRESUPUESTO_CRONOGRAMA_BASE'!M3, 0) -> 1166.89 | F30: =SUMIFS(E$2:E30, C$2:C30, C30) -> 9335.12
A31: 8 | B31: 2026-08-08 | C31: WBS-200 | D31: Red de Alcantarillado, Zanjas y Buzones | E31: =IF(AND(A31>='01_PRESUPUESTO_CRONOGRAMA_BASE'!K4, A31<='01_PRESUPUESTO_CRONOGRAMA_BASE'!L4), '01_PRESUPUESTO_CRONOGRAMA_BASE'!M4, 0) + IF(AND(A31>='01_PRESUPUESTO_CRONOGRAMA_BASE'!K5, A31<='01_PRESUPUESTO_CRONOGRAMA_BASE'!L5), '01_PRESUPUESTO_CRONOGRAMA_BASE'!M5, 0) + IF(AND(A31>='01_PRESUPUESTO_CRONOGRAMA_BASE'!K6, A31<='01_PRESUPUESTO_CRONOGRAMA_BASE'!L6), '01_PRESUPUESTO_CRONOGRAMA_BASE'!M6, 0) + IF(AND(A31>='01_PRESUPUESTO_CRONOGRAMA_BASE'!K7, A31<='01_PRESUPUESTO_CRONOGRAMA_BASE'!L7), '01_PRESUPUESTO_CRONOGRAMA_BASE'!M7, 0) + IF(AND(A31>='01_PRESUPUESTO_CRONOGRAMA_BASE'!K8, A31<='01_PRESUPUESTO_CRONOGRAMA_BASE'!L8), '01_PRESUPUESTO_CRONOGRAMA_BASE'!M8, 0) + IF(AND(A31>='01_PRESUPUESTO_CRONOGRAMA_BASE'!K9, A31<='01_PRESUPUESTO_CRONOGRAMA_BASE'!L9), '01_PRESUPUESTO_CRONOGRAMA_BASE'!M9, 0) -> 0 | F31: =SUMIFS(E$2:E31, C$2:C31, C31) -> 0
A32: 8 | B32: 2026-08-08 | C32: WBS-300 | D32: Red de Agua Potable y Conexiones Domiciliarias | E32: =IF(AND(A32>='01_PRESUPUESTO_CRONOGRAMA_BASE'!K10, A32<='01_PRESUPUESTO_CRONOGRAMA_BASE'!L10), '01_PRESUPUESTO_CRONOGRAMA_BASE'!M10, 0) + IF(AND(A32>='01_PRESUPUESTO_CRONOGRAMA_BASE'!K11, A32<='01_PRESUPUESTO_CRONOGRAMA_BASE'!L11), '01_PRESUPUESTO_CRONOGRAMA_BASE'!M11, 0) -> 0 | F32: =SUMIFS(E$2:E32, C$2:C32, C32) -> 0
A33: 8 | B33: 2026-08-08 | C33: WBS-400 | D33: Pruebas Hidráulicas, Desinfección y Entrega | E33: =IF(AND(A33>='01_PRESUPUESTO_CRONOGRAMA_BASE'!K12, A33<='01_PRESUPUESTO_CRONOGRAMA_BASE'!L12), '01_PRESUPUESTO_CRONOGRAMA_BASE'!M12, 0) -> 0 | F33: =SUMIFS(E$2:E33, C$2:C33, C33) -> 0
A34: 9 | B34: 2026-08-09 | C34: WBS-100 | D34: Obras Preliminares, Trazo y Movilización | E34: =IF(AND(A34>='01_PRESUPUESTO_CRONOGRAMA_BASE'!K2, A34<='01_PRESUPUESTO_CRONOGRAMA_BASE'!L2), '01_PRESUPUESTO_CRONOGRAMA_BASE'!M2, 0) + IF(AND(A34>='01_PRESUPUESTO_CRONOGRAMA_BASE'!K3, A34<='01_PRESUPUESTO_CRONOGRAMA_BASE'!L3), '01_PRESUPUESTO_CRONOGRAMA_BASE'!M3, 0) -> 1166.89 | F34: =SUMIFS(E$2:E34, C$2:C34, C34) -> 10502.01
A35: 9 | B35: 2026-08-09 | C35: WBS-200 | D35: Red de Alcantarillado, Zanjas y Buzones | E35: =IF(AND(A35>='01_PRESUPUESTO_CRONOGRAMA_BASE'!K4, A35<='01_PRESUPUESTO_CRONOGRAMA_BASE'!L4), '01_PRESUPUESTO_CRONOGRAMA_BASE'!M4, 0) + IF(AND(A35>='01_PRESUPUESTO_CRONOGRAMA_BASE'!K5, A35<='01_PRESUPUESTO_CRONOGRAMA_BASE'!L5), '01_PRESUPUESTO_CRONOGRAMA_BASE'!M5, 0) + IF(AND(A35>='01_PRESUPUESTO_CRONOGRAMA_BASE'!K6, A35<='01_PRESUPUESTO_CRONOGRAMA_BASE'!L6), '01_PRESUPUESTO_CRONOGRAMA_BASE'!M6, 0) + IF(AND(A35>='01_PRESUPUESTO_CRONOGRAMA_BASE'!K7, A35<='01_PRESUPUESTO_CRONOGRAMA_BASE'!L7), '01_PRESUPUESTO_CRONOGRAMA_BASE'!M7, 0) + IF(AND(A35>='01_PRESUPUESTO_CRONOGRAMA_BASE'!K8, A35<='01_PRESUPUESTO_CRONOGRAMA_BASE'!L8), '01_PRESUPUESTO_CRONOGRAMA_BASE'!M8, 0) + IF(AND(A35>='01_PRESUPUESTO_CRONOGRAMA_BASE'!K9, A35<='01_PRESUPUESTO_CRONOGRAMA_BASE'!L9), '01_PRESUPUESTO_CRONOGRAMA_BASE'!M9, 0) -> 0 | F35: =SUMIFS(E$2:E35, C$2:C35, C35) -> 0
A36: 9 | B36: 2026-08-09 | C36: WBS-300 | D36: Red de Agua Potable y Conexiones Domiciliarias | E36: =IF(AND(A36>='01_PRESUPUESTO_CRONOGRAMA_BASE'!K10, A36<='01_PRESUPUESTO_CRONOGRAMA_BASE'!L10), '01_PRESUPUESTO_CRONOGRAMA_BASE'!M10, 0) + IF(AND(A36>='01_PRESUPUESTO_CRONOGRAMA_BASE'!K11, A36<='01_PRESUPUESTO_CRONOGRAMA_BASE'!L11), '01_PRESUPUESTO_CRONOGRAMA_BASE'!M11, 0) -> 0 | F36: =SUMIFS(E$2:E36, C$2:C36, C36) -> 0
A37: 9 | B37: 2026-08-09 | C37: WBS-400 | D37: Pruebas Hidráulicas, Desinfección y Entrega | E37: =IF(AND(A37>='01_PRESUPUESTO_CRONOGRAMA_BASE'!K12, A37<='01_PRESUPUESTO_CRONOGRAMA_BASE'!L12), '01_PRESUPUESTO_CRONOGRAMA_BASE'!M12, 0) -> 0 | F37: =SUMIFS(E$2:E37, C$2:C37, C37) -> 0
A38: 10 | B38: 2026-08-10 | C38: WBS-100 | D38: Obras Preliminares, Trazo y Movilización | E38: =IF(AND(A38>='01_PRESUPUESTO_CRONOGRAMA_BASE'!K2, A38<='01_PRESUPUESTO_CRONOGRAMA_BASE'!L2), '01_PRESUPUESTO_CRONOGRAMA_BASE'!M2, 0) + IF(AND(A38>='01_PRESUPUESTO_CRONOGRAMA_BASE'!K3, A38<='01_PRESUPUESTO_CRONOGRAMA_BASE'!L3), '01_PRESUPUESTO_CRONOGRAMA_BASE'!M3, 0) -> 1166.89 | F38: =SUMIFS(E$2:E38, C$2:C38, C38) -> 11668.9
A39: 10 | B39: 2026-08-10 | C39: WBS-200 | D39: Red de Alcantarillado, Zanjas y Buzones | E39: =IF(AND(A39>='01_PRESUPUESTO_CRONOGRAMA_BASE'!K4, A39<='01_PRESUPUESTO_CRONOGRAMA_BASE'!L4), '01_PRESUPUESTO_CRONOGRAMA_BASE'!M4, 0) + IF(AND(A39>='01_PRESUPUESTO_CRONOGRAMA_BASE'!K5, A39<='01_PRESUPUESTO_CRONOGRAMA_BASE'!L5), '01_PRESUPUESTO_CRONOGRAMA_BASE'!M5, 0) + IF(AND(A39>='01_PRESUPUESTO_CRONOGRAMA_BASE'!K6, A39<='01_PRESUPUESTO_CRONOGRAMA_BASE'!L6), '01_PRESUPUESTO_CRONOGRAMA_BASE'!M6, 0) + IF(AND(A39>='01_PRESUPUESTO_CRONOGRAMA_BASE'!K7, A39<='01_PRESUPUESTO_CRONOGRAMA_BASE'!L7), '01_PRESUPUESTO_CRONOGRAMA_BASE'!M7, 0) + IF(AND(A39>='01_PRESUPUESTO_CRONOGRAMA_BASE'!K8, A39<='01_PRESUPUESTO_CRONOGRAMA_BASE'!L8), '01_PRESUPUESTO_CRONOGRAMA_BASE'!M8, 0) + IF(AND(A39>='01_PRESUPUESTO_CRONOGRAMA_BASE'!K9, A39<='01_PRESUPUESTO_CRONOGRAMA_BASE'!L9), '01_PRESUPUESTO_CRONOGRAMA_BASE'!M9, 0) -> 2798.4 | F39: =SUMIFS(E$2:E39, C$2:C39, C39) -> 2798.4
A40: 10 | B40: 2026-08-10 | C40: WBS-300 | D40: Red de Agua Potable y Conexiones Domiciliarias | E40: =IF(AND(A40>='01_PRESUPUESTO_CRONOGRAMA_BASE'!K10, A40<='01_PRESUPUESTO_CRONOGRAMA_BASE'!L10), '01_PRESUPUESTO_CRONOGRAMA_BASE'!M10, 0) + IF(AND(A40>='01_PRESUPUESTO_CRONOGRAMA_BASE'!K11, A40<='01_PRESUPUESTO_CRONOGRAMA_BASE'!L11), '01_PRESUPUESTO_CRONOGRAMA_BASE'!M11, 0) -> 0 | F40: =SUMIFS(E$2:E40, C$2:C40, C40) -> 0
...

Sheet 03_CONSOLIDADO_DIARIO_EVM_WBS
A1: N° Día Obra | B1: Fecha Obra | C1: Código WBS | D1: Nombre Frente WBS | E1: Presupuesto BAC (S/) | F1: PV Programado Día (S/) | G1: PV Acumulado (S/) | H1: EV Ejecutado Día (S/) | I1: EV Acumulado (S/) | J1: AC Costo Real Día (S/) | K1: AC Acumulado (S/) | L1: Variación Costo CV (S/) | M1: Variación Plazo SV (S/) | N1: SPI Plazo (EV/PV) | O1: CPI Costo (EV/AC) | P1: Estado Alerta WBS
A2: 1 | B2: 2026-08-01 | C2: WBS-100 | D2: Obras Preliminares, Trazo y Movilización | E2: =SUM('01_PRESUPUESTO_CRONOGRAMA_BASE'!G2:G3) -> 16336.4 | F2: =SUMIFS('02_CRONOGRAMA_PV_DIARIO'!E:E, '02_CRONOGRAMA_PV_DIARIO'!A:A, A2, '02_CRONOGRAMA_PV_DIARIO'!C:C, C2) -> 1166.89 | G2: =SUMIFS(F$2:F2, C$2:C2, C2) -> 1166.89 | H2: =SUMIFS('04_LOG_FIELD_ENTRIES'!J:J, '04_LOG_FIELD_ENTRIES'!B:B, B2, '04_LOG_FIELD_ENTRIES'!D:D, C2, '04_LOG_FIELD_ENTRIES'!K:K, "EV_PRODUCCION") -> 5823.2 | I2: =SUMIFS(H$2:H2, C$2:C2, C2) -> 5823.2 | J2: =SUMIFS('04_LOG_FIELD_ENTRIES'!J:J, '04_LOG_FIELD_ENTRIES'!B:B, B2, '04_LOG_FIELD_ENTRIES'!D:D, C2, '04_LOG_FIELD_ENTRIES'!K:K, "AC_*") -> 6331 | K2: =SUMIFS(J$2:J2, C$2:C2, C2) -> 6331 | L2: =I2-K2 -> -507.8 | M2: =I2-G2 -> 4656.31 | N2: =IF(G2>0, I2/G2, 1) -> 4.990359 | O2: =IF(K2>0, I2/K2, 1) -> 0.9197915 | P2: =IF(AND(N2>=0.95, O2>=0.95), "SALUDABLE", IF(N2<0.9, "ALERTA RETRASO", "ALERTA SOBRECOSTO")) -> ALERTA SOBRECOSTO
A3: 1 | B3: 2026-08-01 | C3: WBS-200 | D3: Red de Alcantarillado, Zanjas y Buzones | E3: =SUM('01_PRESUPUESTO_CRONOGRAMA_BASE'!G4:G9) -> 372046.56 | F3: =SUMIFS('02_CRONOGRAMA_PV_DIARIO'!E:E, '02_CRONOGRAMA_PV_DIARIO'!A:A, A3, '02_CRONOGRAMA_PV_DIARIO'!C:C, C3) -> 0 | G3: =SUMIFS(F$2:F3, C$2:C3, C3) -> 0 | H3: =SUMIFS('04_LOG_FIELD_ENTRIES'!J:J, '04_LOG_FIELD_ENTRIES'!B:B, B3, '04_LOG_FIELD_ENTRIES'!D:D, C3, '04_LOG_FIELD_ENTRIES'!K:K, "EV_PRODUCCION") -> 0 | I3: =SUMIFS(H$2:H3, C$2:C3, C3) -> 0 | J3: =SUMIFS('04_LOG_FIELD_ENTRIES'!J:J, '04_LOG_FIELD_ENTRIES'!B:B, B3, '04_LOG_FIELD_ENTRIES'!D:D, C3, '04_LOG_FIELD_ENTRIES'!K:K, "AC_*") -> 0 | K3: =SUMIFS(J$2:J3, C$2:C3, C3) -> 0 | L3: =I3-K3 -> 0 | M3: =I3-G3 -> 0 | N3: =IF(G3>0, I3/G3, 1) -> 1 | O3: =IF(K3>0, I3/K3, 1) -> 1 | P3: =IF(AND(N3>=0.95, O3>=0.95), "SALUDABLE", IF(N3<0.9, "ALERTA RETRASO", "ALERTA SOBRECOSTO")) -> SALUDABLE
A4: 1 | B4: 2026-08-01 | C4: WBS-300 | D4: Red de Agua Potable y Conexiones Domiciliarias | E4: =SUM('01_PRESUPUESTO_CRONOGRAMA_BASE'!G10:G11) -> 57565.2 | F4: =SUMIFS('02_CRONOGRAMA_PV_DIARIO'!E:E, '02_CRONOGRAMA_PV_DIARIO'!A:A, A4, '02_CRONOGRAMA_PV_DIARIO'!C:C, C4) -> 0 | G4: =SUMIFS(F$2:F4, C$2:C4, C4) -> 0 | H4: =SUMIFS('04_LOG_FIELD_ENTRIES'!J:J, '04_LOG_FIELD_ENTRIES'!B:B, B4, '04_LOG_FIELD_ENTRIES'!D:D, C4, '04_LOG_FIELD_ENTRIES'!K:K, "EV_PRODUCCION") -> 0 | I4: =SUMIFS(H$2:H4, C$2:C4, C4) -> 0 | J4: =SUMIFS('04_LOG_FIELD_ENTRIES'!J:J, '04_LOG_FIELD_ENTRIES'!B:B, B4, '04_LOG_FIELD_ENTRIES'!D:D, C4, '04_LOG_FIELD_ENTRIES'!K:K, "AC_*") -> 0 | K4: =SUMIFS(J$2:J4, C$2:C4, C4) -> 0 | L4: =I4-K4 -> 0 | M4: =I4-G4 -> 0 | N4: =IF(G4>0, I4/G4, 1) -> 1 | O4: =IF(K4>0, I4/K4, 1) -> 1 | P4: =IF(AND(N4>=0.95, O4>=0.95), "SALUDABLE", IF(N4<0.9, "ALERTA RETRASO", "ALERTA SOBRECOSTO")) -> SALUDABLE
A5: 1 | B5: 2026-08-01 | C5: WBS-400 | D5: Pruebas Hidráulicas, Desinfección y Entrega | E5: =SUM('01_PRESUPUESTO_CRONOGRAMA_BASE'!G12:G12) -> 9348.06 | F5: =SUMIFS('02_CRONOGRAMA_PV_DIARIO'!E:E, '02_CRONOGRAMA_PV_DIARIO'!A:A, A5, '02_CRONOGRAMA_PV_DIARIO'!C:C, C5) -> 0 | G5: =SUMIFS(F$2:F5, C$2:C5, C5) -> 0 | H5: =SUMIFS('04_LOG_FIELD_ENTRIES'!J:J, '04_LOG_FIELD_ENTRIES'!B:B, B5, '04_LOG_FIELD_ENTRIES'!D:D, C5, '04_LOG_FIELD_ENTRIES'!K:K, "EV_PRODUCCION") -> 0 | I5: =SUMIFS(H$2:H5, C$2:C5, C5) -> 0 | J5: =SUMIFS('04_LOG_FIELD_ENTRIES'!J:J, '04_LOG_FIELD_ENTRIES'!B:B, B5, '04_LOG_FIELD_ENTRIES'!D:D, C5, '04_LOG_FIELD_ENTRIES'!K:K, "AC_*") -> 0 | K5: =SUMIFS(J$2:J5, C$2:C5, C5) -> 0 | L5: =I5-K5 -> 0 | M5: =I5-G5 -> 0 | N5: =IF(G5>0, I5/G5, 1) -> 1 | O5: =IF(K5>0, I5/K5, 1) -> 1 | P5: =IF(AND(N5>=0.95, O5>=0.95), "SALUDABLE", IF(N5<0.9, "ALERTA RETRASO", "ALERTA SOBRECOSTO")) -> SALUDABLE
A6: 2 | B6: 2026-08-02 | C6: WBS-100 | D6: Obras Preliminares, Trazo y Movilización | E6: =SUM('01_PRESUPUESTO_CRONOGRAMA_BASE'!G2:G3) -> 16336.4 | F6: =SUMIFS('02_CRONOGRAMA_PV_DIARIO'!E:E, '02_CRONOGRAMA_PV_DIARIO'!A:A, A6, '02_CRONOGRAMA_PV_DIARIO'!C:C, C6) -> 1166.89 | G6: =SUMIFS(F$2:F6, C$2:C6, C6) -> 2333.78 | H6: =SUMIFS('04_LOG_FIELD_ENTRIES'!J:J, '04_LOG_FIELD_ENTRIES'!B:B, B6, '04_LOG_FIELD_ENTRIES'!D:D, C6, '04_LOG_FIELD_ENTRIES'!K:K, "EV_PRODUCCION") -> 0 | I6: =SUMIFS(H$2:H6, C$2:C6, C6) -> 5823.2 | J6: =SUMIFS('04_LOG_FIELD_ENTRIES'!J:J, '04_LOG_FIELD_ENTRIES'!B:B, B6, '04_LOG_FIELD_ENTRIES'!D:D, C6, '04_LOG_FIELD_ENTRIES'!K:K, "AC_*") -> 0 | K6: =SUMIFS(J$2:J6, C$2:C6, C6) -> 6331 | L6: =I6-K6 -> -507.8 | M6: =I6-G6 -> 3489.42 | N6: =IF(G6>0, I6/G6, 1) -> 2.4951795 | O6: =IF(K6>0, I6/K6, 1) -> 0.9197915 | P6: =IF(AND(N6>=0.95, O6>=0.95), "SALUDABLE", IF(N6<0.9, "ALERTA RETRASO", "ALERTA SOBRECOSTO")) -> ALERTA SOBRECOSTO
A7: 2 | B7: 2026-08-02 | C7: WBS-200 | D7: Red de Alcantarillado, Zanjas y Buzones | E7: =SUM('01_PRESUPUESTO_CRONOGRAMA_BASE'!G4:G9) -> 372046.56 | F7: =SUMIFS('02_CRONOGRAMA_PV_DIARIO'!E:E, '02_CRONOGRAMA_PV_DIARIO'!A:A, A7, '02_CRONOGRAMA_PV_DIARIO'!C:C, C7) -> 0 | G7: =SUMIFS(F$2:F7, C$2:C7, C7) -> 0 | H7: =SUMIFS('04_LOG_FIELD_ENTRIES'!J:J, '04_LOG_FIELD_ENTRIES'!B:B, B7, '04_LOG_FIELD_ENTRIES'!D:D, C7, '04_LOG_FIELD_ENTRIES'!K:K, "EV_PRODUCCION") -> 8583 | I7: =SUMIFS(H$2:H7, C$2:C7, C7) -> 8583 | J7: =SUMIFS('04_LOG_FIELD_ENTRIES'!J:J, '04_LOG_FIELD_ENTRIES'!B:B, B7, '04_LOG_FIELD_ENTRIES'!D:D, C7, '04_LOG_FIELD_ENTRIES'!K:K, "AC_*") -> 4923 | K7: =SUMIFS(J$2:J7, C$2:C7, C7) -> 4923 | L7: =I7-K7 -> 3660 | M7: =I7-G7 -> 8583 | N7: =IF(G7>0, I7/G7, 1) -> 1 | O7: =IF(K7>0, I7/K7, 1) -> 1.7434491 | P7: =IF(AND(N7>=0.95, O7>=0.95), "SALUDABLE", IF(N7<0.9, "ALERTA RETRASO", "ALERTA SOBRECOSTO")) -> SALUDABLE
A8: 2 | B8: 2026-08-02 | C8: WBS-300 | D8: Red de Agua Potable y Conexiones Domiciliarias | E8: =SUM('01_PRESUPUESTO_CRONOGRAMA_BASE'!G10:G11) -> 57565.2 | F8: =SUMIFS('02_CRONOGRAMA_PV_DIARIO'!E:E, '02_CRONOGRAMA_PV_DIARIO'!A:A, A8, '02_CRONOGRAMA_PV_DIARIO'!C:C, C8) -> 0 | G8: =SUMIFS(F$2:F8, C$2:C8, C8) -> 0 | H8: =SUMIFS('04_LOG_FIELD_ENTRIES'!J:J, '04_LOG_FIELD_ENTRIES'!B:B, B8, '04_LOG_FIELD_ENTRIES'!D:D, C8, '04_LOG_FIELD_ENTRIES'!K:K, "EV_PRODUCCION") -> 0 | I8: =SUMIFS(H$2:H8, C$2:C8, C8) -> 0 | J8: =SUMIFS('04_LOG_FIELD_ENTRIES'!J:J, '04_LOG_FIELD_ENTRIES'!B:B, B8, '04_LOG_FIELD_ENTRIES'!D:D, C8, '04_LOG_FIELD_ENTRIES'!K:K, "AC_*") -> 0 | K8: =SUMIFS(J$2:J8, C$2:C8, C8) -> 0 | L8: =I8-K8 -> 0 | M8: =I8-G8 -> 0 | N8: =IF(G8>0, I8/G8, 1) -> 1 | O8: =IF(K8>0, I8/K8, 1) -> 1 | P8: =IF(AND(N8>=0.95, O8>=0.95), "SALUDABLE", IF(N8<0.9, "ALERTA RETRASO", "ALERTA SOBRECOSTO")) -> SALUDABLE
A9: 2 | B9: 2026-08-02 | C9: WBS-400 | D9: Pruebas Hidráulicas, Desinfección y Entrega | E9: =SUM('01_PRESUPUESTO_CRONOGRAMA_BASE'!G12:G12) -> 9348.06 | F9: =SUMIFS('02_CRONOGRAMA_PV_DIARIO'!E:E, '02_CRONOGRAMA_PV_DIARIO'!A:A, A9, '02_CRONOGRAMA_PV_DIARIO'!C:C, C9) -> 0 | G9: =SUMIFS(F$2:F9, C$2:C9, C9) -> 0 | H9: =SUMIFS('04_LOG_FIELD_ENTRIES'!J:J, '04_LOG_FIELD_ENTRIES'!B:B, B9, '04_LOG_FIELD_ENTRIES'!D:D, C9, '04_LOG_FIELD_ENTRIES'!K:K, "EV_PRODUCCION") -> 0 | I9: =SUMIFS(H$2:H9, C$2:C9, C9) -> 0 | J9: =SUMIFS('04_LOG_FIELD_ENTRIES'!J:J, '04_LOG_FIELD_ENTRIES'!B:B, B9, '04_LOG_FIELD_ENTRIES'!D:D, C9, '04_LOG_FIELD_ENTRIES'!K:K, "AC_*") -> 0 | K9: =SUMIFS(J$2:J9, C$2:C9, C9) -> 0 | L9: =I9-K9 -> 0 | M9: =I9-G9 -> 0 | N9: =IF(G9>0, I9/G9, 1) -> 1 | O9: =IF(K9>0, I9/K9, 1) -> 1 | P9: =IF(AND(N9>=0.95, O9>=0.95), "SALUDABLE", IF(N9<0.9, "ALERTA RETRASO", "ALERTA SOBRECOSTO")) -> SALUDABLE
A10: 3 | B10: 2026-08-03 | C10: WBS-100 | D10: Obras Preliminares, Trazo y Movilización | E10: =SUM('01_PRESUPUESTO_CRONOGRAMA_BASE'!G2:G3) -> 16336.4 | F10: =SUMIFS('02_CRONOGRAMA_PV_DIARIO'!E:E, '02_CRONOGRAMA_PV_DIARIO'!A:A, A10, '02_CRONOGRAMA_PV_DIARIO'!C:C, C10) -> 1166.89 | G10: =SUMIFS(F$2:F10, C$2:C10, C10) -> 3500.67 | H10: =SUMIFS('04_LOG_FIELD_ENTRIES'!J:J, '04_LOG_FIELD_ENTRIES'!B:B, B10, '04_LOG_FIELD_ENTRIES'!D:D, C10, '04_LOG_FIELD_ENTRIES'!K:K, "EV_PRODUCCION") -> 0 | I10: =SUMIFS(H$2:H10, C$2:C10, C10) -> 5823.2 | J10: =SUMIFS('04_LOG_FIELD_ENTRIES'!J:J, '04_LOG_FIELD_ENTRIES'!B:B, B10, '04_LOG_FIELD_ENTRIES'!D:D, C10, '04_LOG_FIELD_ENTRIES'!K:K, "AC_*") -> 0 | K10: =SUMIFS(J$2:J10, C$2:C10, C10) -> 6331 | L10: =I10-K10 -> -507.8 | M10: =I10-G10 -> 2322.53 | N10: =IF(G10>0, I10/G10, 1) -> 1.663453 | O10: =IF(K10>0, I10/K10, 1) -> 0.9197915 | P10: =IF(AND(N10>=0.95, O10>=0.95), "SALUDABLE", IF(N10<0.9, "ALERTA RETRASO", "ALERTA SOBRECOSTO")) -> ALERTA SOBRECOSTO
A11: 3 | B11: 2026-08-03 | C11: WBS-200 | D11: Red de Alcantarillado, Zanjas y Buzones | E11: =SUM('01_PRESUPUESTO_CRONOGRAMA_BASE'!G4:G9) -> 372046.56 | F11: =SUMIFS('02_CRONOGRAMA_PV_DIARIO'!E:E, '02_CRONOGRAMA_PV_DIARIO'!A:A, A11, '02_CRONOGRAMA_PV_DIARIO'!C:C, C11) -> 0 | G11: =SUMIFS(F$2:F11, C$2:C11, C11) -> 0 | H11: =SUMIFS('04_LOG_FIELD_ENTRIES'!J:J, '04_LOG_FIELD_ENTRIES'!B:B, B11, '04_LOG_FIELD_ENTRIES'!D:D, C11, '04_LOG_FIELD_ENTRIES'!K:K, "EV_PRODUCCION") -> 19585.5 | I11: =SUMIFS(H$2:H11, C$2:C11, C11) -> 28168.5 | J11: =SUMIFS('04_LOG_FIELD_ENTRIES'!J:J, '04_LOG_FIELD_ENTRIES'!B:B, B11, '04_LOG_FIELD_ENTRIES'!D:D, C11, '04_LOG_FIELD_ENTRIES'!K:K, "AC_*") -> 17373.6 | K11: =SUMIFS(J$2:J11, C$2:C11, C11) -> 22296.6 | L11: =I11-K11 -> 5871.9 | M11: =I11-G11 -> 28168.5 | N11: =IF(G11>0, I11/G11, 1) -> 1 | O11: =IF(K11>0, I11/K11, 1) -> 1.2633541 | P11: =IF(AND(N11>=0.95, O11>=0.95), "SALUDABLE", IF(N11<0.9, "ALERTA RETRASO", "ALERTA SOBRECOSTO")) -> SALUDABLE
A12: 3 | B12: 2026-08-03 | C12: WBS-300 | D12: Red de Agua Potable y Conexiones Domiciliarias | E12: =SUM('01_PRESUPUESTO_CRONOGRAMA_BASE'!G10:G11) -> 57565.2 | F12: =SUMIFS('02_CRONOGRAMA_PV_DIARIO'!E:E, '02_CRONOGRAMA_PV_DIARIO'!A:A, A12, '02_CRONOGRAMA_PV_DIARIO'!C:C, C12) -> 0 | G12: =SUMIFS(F$2:F12, C$2:C12, C12) -> 0 | H12: =SUMIFS('04_LOG_FIELD_ENTRIES'!J:J, '04_LOG_FIELD_ENTRIES'!B:B, B12, '04_LOG_FIELD_ENTRIES'!D:D, C12, '04_LOG_FIELD_ENTRIES'!K:K, "EV_PRODUCCION") -> 0 | I12: =SUMIFS(H$2:H12, C$2:C12, C12) -> 0 | J12: =SUMIFS('04_LOG_FIELD_ENTRIES'!J:J, '04_LOG_FIELD_ENTRIES'!B:B, B12, '04_LOG_FIELD_ENTRIES'!D:D, C12, '04_LOG_FIELD_ENTRIES'!K:K, "AC_*") -> 0 | K12: =SUMIFS(J$2:J12, C$2:C12, C12) -> 0 | L12: =I12-K12 -> 0 | M12: =I12-G12 -> 0 | N12: =IF(G12>0, I12/G12, 1) -> 1 | O12: =IF(K12>0, I12/K12, 1) -> 1 | P12: =IF(AND(N12>=0.95, O12>=0.95), "SALUDABLE", IF(N12<0.9, "ALERTA RETRASO", "ALERTA SOBRECOSTO")) -> SALUDABLE
A13: 3 | B13: 2026-08-03 | C13: WBS-400 | D13: Pruebas Hidráulicas, Desinfección y Entrega | E13: =SUM('01_PRESUPUESTO_CRONOGRAMA_BASE'!G12:G12) -> 9348.06 | F13: =SUMIFS('02_CRONOGRAMA_PV_DIARIO'!E:E, '02_CRONOGRAMA_PV_DIARIO'!A:A, A13, '02_CRONOGRAMA_PV_DIARIO'!C:C, C13) -> 0 | G13: =SUMIFS(F$2:F13, C$2:C13, C13) -> 0 | H13: =SUMIFS('04_LOG_FIELD_ENTRIES'!J:J, '04_LOG_FIELD_ENTRIES'!B:B, B13, '04_LOG_FIELD_ENTRIES'!D:D, C13, '04_LOG_FIELD_ENTRIES'!K:K, "EV_PRODUCCION") -> 0 | I13: =SUMIFS(H$2:H13, C$2:C13, C13) -> 0 | J13: =SUMIFS('04_LOG_FIELD_ENTRIES'!J:J, '04_LOG_FIELD_ENTRIES'!B:B, B13, '04_LOG_FIELD_ENTRIES'!D:D, C13, '04_LOG_FIELD_ENTRIES'!K:K, "AC_*") -> 0 | K13: =SUMIFS(J$2:J13, C$2:C13, C13) -> 0 | L13: =I13-K13 -> 0 | M13: =I13-G13 -> 0 | N13: =IF(G13>0, I13/G13, 1) -> 1 | O13: =IF(K13>0, I13/K13, 1) -> 1 | P13: =IF(AND(N13>=0.95, O13>=0.95), "SALUDABLE", IF(N13<0.9, "ALERTA RETRASO", "ALERTA SOBRECOSTO")) -> SALUDABLE
A14: 4 | B14: 2026-08-04 | C14: WBS-100 | D14: Obras Preliminares, Trazo y Movilización | E14: =SUM('01_PRESUPUESTO_CRONOGRAMA_BASE'!G2:G3) -> 16336.4 | F14: =SUMIFS('02_CRONOGRAMA_PV_DIARIO'!E:E, '02_CRONOGRAMA_PV_DIARIO'!A:A, A14, '02_CRONOGRAMA_PV_DIARIO'!C:C, C14) -> 1166.89 | G14: =SUMIFS(F$2:F14, C$2:C14, C14) -> 4667.56 | H14: =SUMIFS('04_LOG_FIELD_ENTRIES'!J:J, '04_LOG_FIELD_ENTRIES'!B:B, B14, '04_LOG_FIELD_ENTRIES'!D:D, C14, '04_LOG_FIELD_ENTRIES'!K:K, "EV_PRODUCCION") -> 0 | I14: =SUMIFS(H$2:H14, C$2:C14, C14) -> 5823.2 | J14: =SUMIFS('04_LOG_FIELD_ENTRIES'!J:J, '04_LOG_FIELD_ENTRIES'!B:B, B14, '04_LOG_FIELD_ENTRIES'!D:D, C14, '04_LOG_FIELD_ENTRIES'!K:K, "AC_*") -> 0 | K14: =SUMIFS(J$2:J14, C$2:C14, C14) -> 6331 | L14: =I14-K14 -> -507.8 | M14: =I14-G14 -> 1155.64 | N14: =IF(G14>0, I14/G14, 1) -> 1.2475897 | O14: =IF(K14>0, I14/K14, 1) -> 0.9197915 | P14: =IF(AND(N14>=0.95, O14>=0.95), "SALUDABLE", IF(N14<0.9, "ALERTA RETRASO", "ALERTA SOBRECOSTO")) -> ALERTA SOBRECOSTO
A15: 4 | B15: 2026-08-04 | C15: WBS-200 | D15: Red de Alcantarillado, Zanjas y Buzones | E15: =SUM('01_PRESUPUESTO_CRONOGRAMA_BASE'!G4:G9) -> 372046.56 | F15: =SUMIFS('02_CRONOGRAMA_PV_DIARIO'!E:E, '02_CRONOGRAMA_PV_DIARIO'!A:A, A15, '02_CRONOGRAMA_PV_DIARIO'!C:C, C15) -> 0 | G15: =SUMIFS(F$2:F15, C$2:C15, C15) -> 0 | H15: =SUMIFS('04_LOG_FIELD_ENTRIES'!J:J, '04_LOG_FIELD_ENTRIES'!B:B, B15, '04_LOG_FIELD_ENTRIES'!D:D, C15, '04_LOG_FIELD_ENTRIES'!K:K, "EV_PRODUCCION") -> 10002.92 | I15: =SUMIFS(H$2:H15, C$2:C15, C15) -> 38171.42 | J15: =SUMIFS('04_LOG_FIELD_ENTRIES'!J:J, '04_LOG_FIELD_ENTRIES'!B:B, B15, '04_LOG_FIELD_ENTRIES'!D:D, C15, '04_LOG_FIELD_ENTRIES'!K:K, "AC_*") -> 6588.8 | K15: =SUMIFS(J$2:J15, C$2:C15, C15) -> 28885.4 | L15: =I15-K15 -> 9286.02 | M15: =I15-G15 -> 38171.42 | N15: =IF(G15>0, I15/G15, 1) -> 1 | O15: =IF(K15>0, I15/K15, 1) -> 1.321478 | P15: =IF(AND(N15>=0.95, O15>=0.95), "SALUDABLE", IF(N15<0.9, "ALERTA RETRASO", "ALERTA SOBRECOSTO")) -> SALUDABLE
A16: 4 | B16: 2026-08-04 | C16: WBS-300 | D16: Red de Agua Potable y Conexiones Domiciliarias | E16: =SUM('01_PRESUPUESTO_CRONOGRAMA_BASE'!G10:G11) -> 57565.2 | F16: =SUMIFS('02_CRONOGRAMA_PV_DIARIO'!E:E, '02_CRONOGRAMA_PV_DIARIO'!A:A, A16, '02_CRONOGRAMA_PV_DIARIO'!C:C, C16) -> 0 | G16: =SUMIFS(F$2:F16, C$2:C16, C16) -> 0 | H16: =SUMIFS('04_LOG_FIELD_ENTRIES'!J:J, '04_LOG_FIELD_ENTRIES'!B:B, B16, '04_LOG_FIELD_ENTRIES'!D:D, C16, '04_LOG_FIELD_ENTRIES'!K:K, "EV_PRODUCCION") -> 6976.8 | I16: =SUMIFS(H$2:H16, C$2:C16, C16) -> 6976.8 | J16: =SUMIFS('04_LOG_FIELD_ENTRIES'!J:J, '04_LOG_FIELD_ENTRIES'!B:B, B16, '04_LOG_FIELD_ENTRIES'!D:D, C16, '04_LOG_FIELD_ENTRIES'!K:K, "AC_*") -> 6372 | K16: =SUMIFS(J$2:J16, C$2:C16, C16) -> 6372 | L16: =I16-K16 -> 604.8 | M16: =I16-G16 -> 6976.8 | N16: =IF(G16>0, I16/G16, 1) -> 1 | O16: =IF(K16>0, I16/K16, 1) -> 1.0949153 | P16: =IF(AND(N16>=0.95, O16>=0.95), "SALUDABLE", IF(N16<0.9, "ALERTA RETRASO", "ALERTA SOBRECOSTO")) -> SALUDABLE
A17: 4 | B17: 2026-08-04 | C17: WBS-400 | D17: Pruebas Hidráulicas, Desinfección y Entrega | E17: =SUM('01_PRESUPUESTO_CRONOGRAMA_BASE'!G12:G12) -> 9348.06 | F17: =SUMIFS('02_CRONOGRAMA_PV_DIARIO'!E:E, '02_CRONOGRAMA_PV_DIARIO'!A:A, A17, '02_CRONOGRAMA_PV_DIARIO'!C:C, C17) -> 0 | G17: =SUMIFS(F$2:F17, C$2:C17, C17) -> 0 | H17: =SUMIFS('04_LOG_FIELD_ENTRIES'!J:J, '04_LOG_FIELD_ENTRIES'!B:B, B17, '04_LOG_FIELD_ENTRIES'!D:D, C17, '04_LOG_FIELD_ENTRIES'!K:K, "EV_PRODUCCION") -> 0 | I17: =SUMIFS(H$2:H17, C$2:C17, C17) -> 0 | J17: =SUMIFS('04_LOG_FIELD_ENTRIES'!J:J, '04_LOG_FIELD_ENTRIES'!B:B, B17, '04_LOG_FIELD_ENTRIES'!D:D, C17, '04_LOG_FIELD_ENTRIES'!K:K, "AC_*") -> 0 | K17: =SUMIFS(J$2:J17, C$2:C17, C17) -> 0 | L17: =I17-K17 -> 0 | M17: =I17-G17 -> 0 | N17: =IF(G17>0, I17/G17, 1) -> 1 | O17: =IF(K17>0, I17/K17, 1) -> 1 | P17: =IF(AND(N17>=0.95, O17>=0.95), "SALUDABLE", IF(N17<0.9, "ALERTA RETRASO", "ALERTA SOBRECOSTO")) -> SALUDABLE
A18: 5 | B18: 2026-08-05 | C18: WBS-100 | D18: Obras Preliminares, Trazo y Movilización | E18: =SUM('01_PRESUPUESTO_CRONOGRAMA_BASE'!G2:G3) -> 16336.4 | F18: =SUMIFS('02_CRONOGRAMA_PV_DIARIO'!E:E, '02_CRONOGRAMA_PV_DIARIO'!A:A, A18, '02_CRONOGRAMA_PV_DIARIO'!C:C, C18) -> 1166.89 | G18: =SUMIFS(F$2:F18, C$2:C18, C18) -> 5834.45 | H18: =SUMIFS('04_LOG_FIELD_ENTRIES'!J:J, '04_LOG_FIELD_ENTRIES'!B:B, B18, '04_LOG_FIELD_ENTRIES'!D:D, C18, '04_LOG_FIELD_ENTRIES'!K:K, "EV_PRODUCCION") -> 0 | I18: =SUMIFS(H$2:H18, C$2:C18, C18) -> 5823.2 | J18: =SUMIFS('04_LOG_FIELD_ENTRIES'!J:J, '04_LOG_FIELD_ENTRIES'!B:B, B18, '04_LOG_FIELD_ENTRIES'!D:D, C18, '04_LOG_FIELD_ENTRIES'!K:K, "AC_*") -> 0 | K18: =SUMIFS(J$2:J18, C$2:C18, C18) -> 6331 | L18: =I18-K18 -> -507.8 | M18: =I18-G18 -> -11.25 | N18: =IF(G18>0, I18/G18, 1) -> 0.9980718 | O18: =IF(K18>0, I18/K18, 1) -> 0.9197915 | P18: =IF(AND(N18>=0.95, O18>=0.95), "SALUDABLE", IF(N18<0.9, "ALERTA RETRASO", "ALERTA SOBRECOSTO")) -> ALERTA SOBRECOSTO
A19: 5 | B19: 2026-08-05 | C19: WBS-200 | D19: Red de Alcantarillado, Zanjas y Buzones | E19: =SUM('01_PRESUPUESTO_CRONOGRAMA_BASE'!G4:G9) -> 372046.56 | F19: =SUMIFS('02_CRONOGRAMA_PV_DIARIO'!E:E, '02_CRONOGRAMA_PV_DIARIO'!A:A, A19, '02_CRONOGRAMA_PV_DIARIO'!C:C, C19) -> 0 | G19: =SUMIFS(F$2:F19, C$2:C19, C19) -> 0 | H19: =SUMIFS('04_LOG_FIELD_ENTRIES'!J:J, '04_LOG_FIELD_ENTRIES'!B:B, B19, '04_LOG_FIELD_ENTRIES'!D:D, C19, '04_LOG_FIELD_ENTRIES'!K:K, "EV_PRODUCCION") -> 6083.1 | I19: =SUMIFS(H$2:H19, C$2:C19, C19) -> 44254.52 | J19: =SUMIFS('04_LOG_FIELD_ENTRIES'!J:J, '04_LOG_FIELD_ENTRIES'!B:B, B19, '04_LOG_FIELD_ENTRIES'!D:D, C19, '04_LOG_FIELD_ENTRIES'!K:K, "AC_*") -> 5383.8 | K19: =SUMIFS(J$2:J19, C$2:C19, C19) -> 34269.2 | L19: =I19-K19 -> 9985.32 | M19: =I19-G19 -> 44254.52 | N19: =IF(G19>0, I19/G19, 1) -> 1 | O19: =IF(K19>0, I19/K19, 1) -> 1.2913788 | P19: =IF(AND(N19>=0.95, O19>=0.95), "SALUDABLE", IF(N19<0.9, "ALERTA RETRASO", "ALERTA SOBRECOSTO")) -> SALUDABLE
A20: 5 | B20: 2026-08-05 | C20: WBS-300 | D20: Red de Agua Potable y Conexiones Domiciliarias | E20: =SUM('01_PRESUPUESTO_CRONOGRAMA_BASE'!G10:G11) -> 57565.2 | F20: =SUMIFS('02_CRONOGRAMA_PV_DIARIO'!E:E, '02_CRONOGRAMA_PV_DIARIO'!A:A, A20, '02_CRONOGRAMA_PV_DIARIO'!C:C, C20) -> 0 | G20: =SUMIFS(F$2:F20, C$2:C20, C20) -> 0 | H20: =SUMIFS('04_LOG_FIELD_ENTRIES'!J:J, '04_LOG_FIELD_ENTRIES'!B:B, B20, '04_LOG_FIELD_ENTRIES'!D:D, C20, '04_LOG_FIELD_ENTRIES'!K:K, "EV_PRODUCCION") -> 2350.65 | I20: =SUMIFS(H$2:H20, C$2:C20, C20) -> 9327.45 | J20: =SUMIFS('04_LOG_FIELD_ENTRIES'!J:J, '04_LOG_FIELD_ENTRIES'!B:B, B20, '04_LOG_FIELD_ENTRIES'!D:D, C20, '04_LOG_FIELD_ENTRIES'!K:K, "AC_*") -> 1358.8 | K20: =SUMIFS(J$2:J20, C$2:C20, C20) -> 7730.8 | L20: =I20-K20 -> 1596.65 | M20: =I20-G20 -> 9327.45 | N20: =IF(G20>0, I20/G20, 1) -> 1 | O20: =IF(K20>0, I20/K20, 1) -> 1.206531 | P20: =IF(AND(N20>=0.95, O20>=0.95), "SALUDABLE", IF(N20<0.9, "ALERTA RETRASO", "ALERTA SOBRECOSTO")) -> SALUDABLE
A21: 5 | B21: 2026-08-05 | C21: WBS-400 | D21: Pruebas Hidráulicas, Desinfección y Entrega | E21: =SUM('01_PRESUPUESTO_CRONOGRAMA_BASE'!G12:G12) -> 9348.06 | F21: =SUMIFS('02_CRONOGRAMA_PV_DIARIO'!E:E, '02_CRONOGRAMA_PV_DIARIO'!A:A, A21, '02_CRONOGRAMA_PV_DIARIO'!C:C, C21) -> 0 | G21: =SUMIFS(F$2:F21, C$2:C21, C21) -> 0 | H21: =SUMIFS('04_LOG_FIELD_ENTRIES'!J:J, '04_LOG_FIELD_ENTRIES'!B:B, B21, '04_LOG_FIELD_ENTRIES'!D:D, C21, '04_LOG_FIELD_ENTRIES'!K:K, "EV_PRODUCCION") -> 2337.02 | I21: =SUMIFS(H$2:H21, C$2:C21, C21) -> 2337.02 | J21: =SUMIFS('04_LOG_FIELD_ENTRIES'!J:J, '04_LOG_FIELD_ENTRIES'!B:B, B21, '04_LOG_FIELD_ENTRIES'!D:D, C21, '04_LOG_FIELD_ENTRIES'!K:K, "AC_*") -> 1299.2 | K21: =SUMIFS(J$2:J21, C$2:C21, C21) -> 1299.2 | L21: =I21-K21 -> 1037.82 | M21: =I21-G21 -> 2337.02 | N21: =IF(G21>0, I21/G21, 1) -> 1 | O21: =IF(K21>0, I21/K21, 1) -> 1.7988147 | P21: =IF(AND(N21>=0.95, O21>=0.95), "SALUDABLE", IF(N21<0.9, "ALERTA RETRASO", "ALERTA SOBRECOSTO")) -> SALUDABLE
A22: 6 | B22: 2026-08-06 | C22: WBS-100 | D22: Obras Preliminares, Trazo y Movilización | E22: =SUM('01_PRESUPUESTO_CRONOGRAMA_BASE'!G2:G3) -> 16336.4 | F22: =SUMIFS('02_CRONOGRAMA_PV_DIARIO'!E:E, '02_CRONOGRAMA_PV_DIARIO'!A:A, A22, '02_CRONOGRAMA_PV_DIARIO'!C:C, C22) -> 1166.89 | G22: =SUMIFS(F$2:F22, C$2:C22, C22) -> 7001.34 | H22: =SUMIFS('04_LOG_FIELD_ENTRIES'!J:J, '04_LOG_FIELD_ENTRIES'!B:B, B22, '04_LOG_FIELD_ENTRIES'!D:D, C22, '04_LOG_FIELD_ENTRIES'!K:K, "EV_PRODUCCION") -> 0 | I22: =SUMIFS(H$2:H22, C$2:C22, C22) -> 5823.2 | J22: =SUMIFS('04_LOG_FIELD_ENTRIES'!J:J, '04_LOG_FIELD_ENTRIES'!B:B, B22, '04_LOG_FIELD_ENTRIES'!D:D, C22, '04_LOG_FIELD_ENTRIES'!K:K, "AC_*") -> 0 | K22: =SUMIFS(J$2:J22, C$2:C22, C22) -> 6331 | L22: =I22-K22 -> -507.8 | M22: =I22-G22 -> -1178.14 | N22: =IF(G22>0, I22/G22, 1) -> 0.8317265 | O22: =IF(K22>0, I22/K22, 1) -> 0.9197915 | P22: =IF(AND(N22>=0.95, O22>=0.95), "SALUDABLE", IF(N22<0.9, "ALERTA RETRASO", "ALERTA SOBRECOSTO")) -> ALERTA RETRASO
A23: 6 | B23: 2026-08-06 | C23: WBS-200 | D23: Red de Alcantarillado, Zanjas y Buzones | E23: =SUM('01_PRESUPUESTO_CRONOGRAMA_BASE'!G4:G9) -> 372046.56 | F23: =SUMIFS('02_CRONOGRAMA_PV_DIARIO'!E:E, '02_CRONOGRAMA_PV_DIARIO'!A:A, A23, '02_CRONOGRAMA_PV_DIARIO'!C:C, C23) -> 0 | G23: =SUMIFS(F$2:F23, C$2:C23, C23) -> 0 | H23: =SUMIFS('04_LOG_FIELD_ENTRIES'!J:J, '04_LOG_FIELD_ENTRIES'!B:B, B23, '04_LOG_FIELD_ENTRIES'!D:D, C23, '04_LOG_FIELD_ENTRIES'!K:K, "EV_PRODUCCION") -> 0 | I23: =SUMIFS(H$2:H23, C$2:C23, C23) -> 44254.52 | J23: =SUMIFS('04_LOG_FIELD_ENTRIES'!J:J, '04_LOG_FIELD_ENTRIES'!B:B, B23, '04_LOG_FIELD_ENTRIES'!D:D, C23, '04_LOG_FIELD_ENTRIES'!K:K, "AC_*") -> 0 | K23: =SUMIFS(J$2:J23, C$2:C23, C23) -> 34269.2 | L23: =I23-K23 -> 9985.32 | M23: =I23-G23 -> 44254.52 | N23: =IF(G23>0, I23/G23, 1) -> 1 | O23: =IF(K23>0, I23/K23, 1) -> 1.2913788 | P23: =IF(AND(N23>=0.95, O23>=0.95), "SALUDABLE", IF(N23<0.9, "ALERTA RETRASO", "ALERTA SOBRECOSTO")) -> SALUDABLE
A24: 6 | B24: 2026-08-06 | C24: WBS-300 | D24: Red de Agua Potable y Conexiones Domiciliarias | E24: =SUM('01_PRESUPUESTO_CRONOGRAMA_BASE'!G10:G11) -> 57565.2 | F24: =SUMIFS('02_CRONOGRAMA_PV_DIARIO'!E:E, '02_CRONOGRAMA_PV_DIARIO'!A:A, A24, '02_CRONOGRAMA_PV_DIARIO'!C:C, C24) -> 0 | G24: =SUMIFS(F$2:F24, C$2:C24, C24) -> 0 | H24: =SUMIFS('04_LOG_FIELD_ENTRIES'!J:J, '04_LOG_FIELD_ENTRIES'!B:B, B24, '04_LOG_FIELD_ENTRIES'!D:D, C24, '04_LOG_FIELD_ENTRIES'!K:K, "EV_PRODUCCION") -> 0 | I24: =SUMIFS(H$2:H24, C$2:C24, C24) -> 9327.45 | J24: =SUMIFS('04_LOG_FIELD_ENTRIES'!J:J, '04_LOG_FIELD_ENTRIES'!B:B, B24, '04_LOG_FIELD_ENTRIES'!D:D, C24, '04_LOG_FIELD_ENTRIES'!K:K, "AC_*") -> 0 | K24: =SUMIFS(J$2:J24, C$2:C24, C24) -> 7730.8 | L24: =I24-K24 -> 1596.65 | M24: =I24-G24 -> 9327.45 | N24: =IF(G24>0, I24/G24, 1) -> 1 | O24: =IF(K24>0, I24/K24, 1) -> 1.206531 | P24: =IF(AND(N24>=0.95, O24>=0.95), "SALUDABLE", IF(N24<0.9, "ALERTA RETRASO", "ALERTA SOBRECOSTO")) -> SALUDABLE
A25: 6 | B25: 2026-08-06 | C25: WBS-400 | D25: Pruebas Hidráulicas, Desinfección y Entrega | E25: =SUM('01_PRESUPUESTO_CRONOGRAMA_BASE'!G12:G12) -> 9348.06 | F25: =SUMIFS('02_CRONOGRAMA_PV_DIARIO'!E:E, '02_CRONOGRAMA_PV_DIARIO'!A:A, A25, '02_CRONOGRAMA_PV_DIARIO'!C:C, C25) -> 0 | G25: =SUMIFS(F$2:F25, C$2:C25, C25) -> 0 | H25: =SUMIFS('04_LOG_FIELD_ENTRIES'!J:J, '04_LOG_FIELD_ENTRIES'!B:B, B25, '04_LOG_FIELD_ENTRIES'!D:D, C25, '04_LOG_FIELD_ENTRIES'!K:K, "EV_PRODUCCION") -> 0 | I25: =SUMIFS(H$2:H25, C$2:C25, C25) -> 2337.02 | J25: =SUMIFS('04_LOG_FIELD_ENTRIES'!J:J, '04_LOG_FIELD_ENTRIES'!B:B, B25, '04_LOG_FIELD_ENTRIES'!D:D, C25, '04_LOG_FIELD_ENTRIES'!K:K, "AC_*") -> 0 | K25: =SUMIFS(J$2:J25, C$2:C25, C25) -> 1299.2 | L25: =I25-K25 -> 1037.82 | M25: =I25-G25 -> 2337.02 | N25: =IF(G25>0, I25/G25, 1) -> 1 | O25: =IF(K25>0, I25/K25, 1) -> 1.7988147 | P25: =IF(AND(N25>=0.95, O25>=0.95), "SALUDABLE", IF(N25<0.9, "ALERTA RETRASO", "ALERTA SOBRECOSTO")) -> SALUDABLE
A26: 7 | B26: 2026-08-07 | C26: WBS-100 | D26: Obras Preliminares, Trazo y Movilización | E26: =SUM('01_PRESUPUESTO_CRONOGRAMA_BASE'!G2:G3) -> 16336.4 | F26: =SUMIFS('02_CRONOGRAMA_PV_DIARIO'!E:E, '02_CRONOGRAMA_PV_DIARIO'!A:A, A26, '02_CRONOGRAMA_PV_DIARIO'!C:C, C26) -> 1166.89 | G26: =SUMIFS(F$2:F26, C$2:C26, C26) -> 8168.23 | H26: =SUMIFS('04_LOG_FIELD_ENTRIES'!J:J, '04_LOG_FIELD_ENTRIES'!B:B, B26, '04_LOG_FIELD_ENTRIES'!D:D, C26, '04_LOG_FIELD_ENTRIES'!K:K, "EV_PRODUCCION") -> 0 | I26: =SUMIFS(H$2:H26, C$2:C26, C26) -> 5823.2 | J26: =SUMIFS('04_LOG_FIELD_ENTRIES'!J:J, '04_LOG_FIELD_ENTRIES'!B:B, B26, '04_LOG_FIELD_ENTRIES'!D:D, C26, '04_LOG_FIELD_ENTRIES'!K:K, "AC_*") -> 0 | K26: =SUMIFS(J$2:J26, C$2:C26, C26) -> 6331 | L26: =I26-K26 -> -507.8 | M26: =I26-G26 -> -2345.03 | N26: =IF(G26>0, I26/G26, 1) -> 0.71290843 | O26: =IF(K26>0, I26/K26, 1) -> 0.9197915 | P26: =IF(AND(N26>=0.95, O26>=0.95), "SALUDABLE", IF(N26<0.9, "ALERTA RETRASO", "ALERTA SOBRECOSTO")) -> ALERTA RETRASO
A27: 7 | B27: 2026-08-07 | C27: WBS-200 | D27: Red de Alcantarillado, Zanjas y Buzones | E27: =SUM('01_PRESUPUESTO_CRONOGRAMA_BASE'!G4:G9) -> 372046.56 | F27: =SUMIFS('02_CRONOGRAMA_PV_DIARIO'!E:E, '02_CRONOGRAMA_PV_DIARIO'!A:A, A27, '02_CRONOGRAMA_PV_DIARIO'!C:C, C27) -> 0 | G27: =SUMIFS(F$2:F27, C$2:C27, C27) -> 0 | H27: =SUMIFS('04_LOG_FIELD_ENTRIES'!J:J, '04_LOG_FIELD_ENTRIES'!B:B, B27, '04_LOG_FIELD_ENTRIES'!D:D, C27, '04_LOG_FIELD_ENTRIES'!K:K, "EV_PRODUCCION") -> 0 | I27: =SUMIFS(H$2:H27, C$2:C27, C27) -> 44254.52 | J27: =SUMIFS('04_LOG_FIELD_ENTRIES'!J:J, '04_LOG_FIELD_ENTRIES'!B:B, B27, '04_LOG_FIELD_ENTRIES'!D:D, C27, '04_LOG_FIELD_ENTRIES'!K:K, "AC_*") -> 0 | K27: =SUMIFS(J$2:J27, C$2:C27, C27) -> 34269.2 | L27: =I27-K27 -> 9985.32 | M27: =I27-G27 -> 44254.52 | N27: =IF(G27>0, I27/G27, 1) -> 1 | O27: =IF(K27>0, I27/K27, 1) -> 1.2913788 | P27: =IF(AND(N27>=0.95, O27>=0.95), "SALUDABLE", IF(N27<0.9, "ALERTA RETRASO", "ALERTA SOBRECOSTO")) -> SALUDABLE
A28: 7 | B28: 2026-08-07 | C28: WBS-300 | D28: Red de Agua Potable y Conexiones Domiciliarias | E28: =SUM('01_PRESUPUESTO_CRONOGRAMA_BASE'!G10:G11) -> 57565.2 | F28: =SUMIFS('02_CRONOGRAMA_PV_DIARIO'!E:E, '02_CRONOGRAMA_PV_DIARIO'!A:A, A28, '02_CRONOGRAMA_PV_DIARIO'!C:C, C28) -> 0 | G28: =SUMIFS(F$2:F28, C$2:C28, C28) -> 0 | H28: =SUMIFS('04_LOG_FIELD_ENTRIES'!J:J, '04_LOG_FIELD_ENTRIES'!B:B, B28, '04_LOG_FIELD_ENTRIES'!D:D, C28, '04_LOG_FIELD_ENTRIES'!K:K, "EV_PRODUCCION") -> 0 | I28: =SUMIFS(H$2:H28, C$2:C28, C28) -> 9327.45 | J28: =SUMIFS('04_LOG_FIELD_ENTRIES'!J:J, '04_LOG_FIELD_ENTRIES'!B:B, B28, '04_LOG_FIELD_ENTRIES'!D:D, C28, '04_LOG_FIELD_ENTRIES'!K:K, "AC_*") -> 0 | K28: =SUMIFS(J$2:J28, C$2:C28, C28) -> 7730.8 | L28: =I28-K28 -> 1596.65 | M28: =I28-G28 -> 9327.45 | N28: =IF(G28>0, I28/G28, 1) -> 1 | O28: =IF(K28>0, I28/K28, 1) -> 1.206531 | P28: =IF(AND(N28>=0.95, O28>=0.95), "SALUDABLE", IF(N28<0.9, "ALERTA RETRASO", "ALERTA SOBRECOSTO")) -> SALUDABLE
A29: 7 | B29: 2026-08-07 | C29: WBS-400 | D29: Pruebas Hidráulicas, Desinfección y Entrega | E29: =SUM('01_PRESUPUESTO_CRONOGRAMA_BASE'!G12:G12) -> 9348.06 | F29: =SUMIFS('02_CRONOGRAMA_PV_DIARIO'!E:E, '02_CRONOGRAMA_PV_DIARIO'!A:A, A29, '02_CRONOGRAMA_PV_DIARIO'!C:C, C29) -> 0 | G29: =SUMIFS(F$2:F29, C$2:C29, C29) -> 0 | H29: =SUMIFS('04_LOG_FIELD_ENTRIES'!J:J, '04_LOG_FIELD_ENTRIES'!B:B, B29, '04_LOG_FIELD_ENTRIES'!D:D, C29, '04_LOG_FIELD_ENTRIES'!K:K, "EV_PRODUCCION") -> 0 | I29: =SUMIFS(H$2:H29, C$2:C29, C29) -> 2337.02 | J29: =SUMIFS('04_LOG_FIELD_ENTRIES'!J:J, '04_LOG_FIELD_ENTRIES'!B:B, B29, '04_LOG_FIELD_ENTRIES'!D:D, C29, '04_LOG_FIELD_ENTRIES'!K:K, "AC_*") -> 0 | K29: =SUMIFS(J$2:J29, C$2:C29, C29) -> 1299.2 | L29: =I29-K29 -> 1037.82 | M29: =I29-G29 -> 2337.02 | N29: =IF(G29>0, I29/G29, 1) -> 1 | O29: =IF(K29>0, I29/K29, 1) -> 1.7988147 | P29: =IF(AND(N29>=0.95, O29>=0.95), "SALUDABLE", IF(N29<0.9, "ALERTA RETRASO", "ALERTA SOBRECOSTO")) -> SALUDABLE
A30: 8 | B30: 2026-08-08 | C30: WBS-100 | D30: Obras Preliminares, Trazo y Movilización | E30: =SUM('01_PRESUPUESTO_CRONOGRAMA_BASE'!G2:G3) -> 16336.4 | F30: =SUMIFS('02_CRONOGRAMA_PV_DIARIO'!E:E, '02_CRONOGRAMA_PV_DIARIO'!A:A, A30, '02_CRONOGRAMA_PV_DIARIO'!C:C, C30) -> 1166.89 | G30: =SUMIFS(F$2:F30, C$2:C30, C30) -> 9335.12 | H30: =SUMIFS('04_LOG_FIELD_ENTRIES'!J:J, '04_LOG_FIELD_ENTRIES'!B:B, B30, '04_LOG_FIELD_ENTRIES'!D:D, C30, '04_LOG_FIELD_ENTRIES'!K:K, "EV_PRODUCCION") -> 0 | I30: =SUMIFS(H$2:H30, C$2:C30, C30) -> 5823.2 | J30: =SUMIFS('04_LOG_FIELD_ENTRIES'!J:J, '04_LOG_FIELD_ENTRIES'!B:B, B30, '04_LOG_FIELD_ENTRIES'!D:D, C30, '04_LOG_FIELD_ENTRIES'!K:K, "AC_*") -> 0 | K30: =SUMIFS(J$2:J30, C$2:C30, C30) -> 6331 | L30: =I30-K30 -> -507.8 | M30: =I30-G30 -> -3511.92 | N30: =IF(G30>0, I30/G30, 1) -> 0.62379487 | O30: =IF(K30>0, I30/K30, 1) -> 0.9197915 | P30: =IF(AND(N30>=0.95, O30>=0.95), "SALUDABLE", IF(N30<0.9, "ALERTA RETRASO", "ALERTA SOBRECOSTO")) -> ALERTA RETRASO
A31: 8 | B31: 2026-08-08 | C31: WBS-200 | D31: Red de Alcantarillado, Zanjas y Buzones | E31: =SUM('01_PRESUPUESTO_CRONOGRAMA_BASE'!G4:G9) -> 372046.56 | F31: =SUMIFS('02_CRONOGRAMA_PV_DIARIO'!E:E, '02_CRONOGRAMA_PV_DIARIO'!A:A, A31, '02_CRONOGRAMA_PV_DIARIO'!C:C, C31) -> 0 | G31: =SUMIFS(F$2:F31, C$2:C31, C31) -> 0 | H31: =SUMIFS('04_LOG_FIELD_ENTRIES'!J:J, '04_LOG_FIELD_ENTRIES'!B:B, B31, '04_LOG_FIELD_ENTRIES'!D:D, C31, '04_LOG_FIELD_ENTRIES'!K:K, "EV_PRODUCCION") -> 0 | I31: =SUMIFS(H$2:H31, C$2:C31, C31) -> 44254.52 | J31: =SUMIFS('04_LOG_FIELD_ENTRIES'!J:J, '04_LOG_FIELD_ENTRIES'!B:B, B31, '04_LOG_FIELD_ENTRIES'!D:D, C31, '04_LOG_FIELD_ENTRIES'!K:K, "AC_*") -> 0 | K31: =SUMIFS(J$2:J31, C$2:C31, C31) -> 34269.2 | L31: =I31-K31 -> 9985.32 | M31: =I31-G31 -> 44254.52 | N31: =IF(G31>0, I31/G31, 1) -> 1 | O31: =IF(K31>0, I31/K31, 1) -> 1.2913788 | P31: =IF(AND(N31>=0.95, O31>=0.95), "SALUDABLE", IF(N31<0.9, "ALERTA RETRASO", "ALERTA SOBRECOSTO")) -> SALUDABLE
A32: 8 | B32: 2026-08-08 | C32: WBS-300 | D32: Red de Agua Potable y Conexiones Domiciliarias | E32: =SUM('01_PRESUPUESTO_CRONOGRAMA_BASE'!G10:G11) -> 57565.2 | F32: =SUMIFS('02_CRONOGRAMA_PV_DIARIO'!E:E, '02_CRONOGRAMA_PV_DIARIO'!A:A, A32, '02_CRONOGRAMA_PV_DIARIO'!C:C, C32) -> 0 | G32: =SUMIFS(F$2:F32, C$2:C32, C32) -> 0 | H32: =SUMIFS('04_LOG_FIELD_ENTRIES'!J:J, '04_LOG_FIELD_ENTRIES'!B:B, B32, '04_LOG_FIELD_ENTRIES'!D:D, C32, '04_LOG_FIELD_ENTRIES'!K:K, "EV_PRODUCCION") -> 0 | I32: =SUMIFS(H$2:H32, C$2:C32, C32) -> 9327.45 | J32: =SUMIFS('04_LOG_FIELD_ENTRIES'!J:J, '04_LOG_FIELD_ENTRIES'!B:B, B32, '04_LOG_FIELD_ENTRIES'!D:D, C32, '04_LOG_FIELD_ENTRIES'!K:K, "AC_*") -> 0 | K32: =SUMIFS(J$2:J32, C$2:C32, C32) -> 7730.8 | L32: =I32-K32 -> 1596.65 | M32: =I32-G32 -> 9327.45 | N32: =IF(G32>0, I32/G32, 1) -> 1 | O32: =IF(K32>0, I32/K32, 1) -> 1.206531 | P32: =IF(AND(N32>=0.95, O32>=0.95), "SALUDABLE", IF(N32<0.9, "ALERTA RETRASO", "ALERTA SOBRECOSTO")) -> SALUDABLE
A33: 8 | B33: 2026-08-08 | C33: WBS-400 | D33: Pruebas Hidráulicas, Desinfección y Entrega | E33: =SUM('01_PRESUPUESTO_CRONOGRAMA_BASE'!G12:G12) -> 9348.06 | F33: =SUMIFS('02_CRONOGRAMA_PV_DIARIO'!E:E, '02_CRONOGRAMA_PV_DIARIO'!A:A, A33, '02_CRONOGRAMA_PV_DIARIO'!C:C, C33) -> 0 | G33: =SUMIFS(F$2:F33, C$2:C33, C33) -> 0 | H33: =SUMIFS('04_LOG_FIELD_ENTRIES'!J:J, '04_LOG_FIELD_ENTRIES'!B:B, B33, '04_LOG_FIELD_ENTRIES'!D:D, C33, '04_LOG_FIELD_ENTRIES'!K:K, "EV_PRODUCCION") -> 0 | I33: =SUMIFS(H$2:H33, C$2:C33, C33) -> 2337.02 | J33: =SUMIFS('04_LOG_FIELD_ENTRIES'!J:J, '04_LOG_FIELD_ENTRIES'!B:B, B33, '04_LOG_FIELD_ENTRIES'!D:D, C33, '04_LOG_FIELD_ENTRIES'!K:K, "AC_*") -> 0 | K33: =SUMIFS(J$2:J33, C$2:C33, C33) -> 1299.2 | L33: =I33-K33 -> 1037.82 | M33: =I33-G33 -> 2337.02 | N33: =IF(G33>0, I33/G33, 1) -> 1 | O33: =IF(K33>0, I33/K33, 1) -> 1.7988147 | P33: =IF(AND(N33>=0.95, O33>=0.95), "SALUDABLE", IF(N33<0.9, "ALERTA RETRASO", "ALERTA SOBRECOSTO")) -> SALUDABLE
A34: 9 | B34: 2026-08-09 | C34: WBS-100 | D34: Obras Preliminares, Trazo y Movilización | E34: =SUM('01_PRESUPUESTO_CRONOGRAMA_BASE'!G2:G3) -> 16336.4 | F34: =SUMIFS('02_CRONOGRAMA_PV_DIARIO'!E:E, '02_CRONOGRAMA_PV_DIARIO'!A:A, A34, '02_CRONOGRAMA_PV_DIARIO'!C:C, C34) -> 1166.89 | G34: =SUMIFS(F$2:F34, C$2:C34, C34) -> 10502.01 | H34: =SUMIFS('04_LOG_FIELD_ENTRIES'!J:J, '04_LOG_FIELD_ENTRIES'!B:B, B34, '04_LOG_FIELD_ENTRIES'!D:D, C34, '04_LOG_FIELD_ENTRIES'!K:K, "EV_PRODUCCION") -> 0 | I34: =SUMIFS(H$2:H34, C$2:C34, C34) -> 5823.2 | J34: =SUMIFS('04_LOG_FIELD_ENTRIES'!J:J, '04_LOG_FIELD_ENTRIES'!B:B, B34, '04_LOG_FIELD_ENTRIES'!D:D, C34, '04_LOG_FIELD_ENTRIES'!K:K, "AC_*") -> 0 | K34: =SUMIFS(J$2:J34, C$2:C34, C34) -> 6331 | L34: =I34-K34 -> -507.8 | M34: =I34-G34 -> -4678.81 | N34: =IF(G34>0, I34/G34, 1) -> 0.55448433 | O34: =IF(K34>0, I34/K34, 1) -> 0.9197915 | P34: =IF(AND(N34>=0.95, O34>=0.95), "SALUDABLE", IF(N34<0.9, "ALERTA RETRASO", "ALERTA SOBRECOSTO")) -> ALERTA RETRASO
A35: 9 | B35: 2026-08-09 | C35: WBS-200 | D35: Red de Alcantarillado, Zanjas y Buzones | E35: =SUM('01_PRESUPUESTO_CRONOGRAMA_BASE'!G4:G9) -> 372046.56 | F35: =SUMIFS('02_CRONOGRAMA_PV_DIARIO'!E:E, '02_CRONOGRAMA_PV_DIARIO'!A:A, A35, '02_CRONOGRAMA_PV_DIARIO'!C:C, C35) -> 0 | G35: =SUMIFS(F$2:F35, C$2:C35, C35) -> 0 | H35: =SUMIFS('04_LOG_FIELD_ENTRIES'!J:J, '04_LOG_FIELD_ENTRIES'!B:B, B35, '04_LOG_FIELD_ENTRIES'!D:D, C35, '04_LOG_FIELD_ENTRIES'!K:K, "EV_PRODUCCION") -> 0 | I35: =SUMIFS(H$2:H35, C$2:C35, C35) -> 44254.52 | J35: =SUMIFS('04_LOG_FIELD_ENTRIES'!J:J, '04_LOG_FIELD_ENTRIES'!B:B, B35, '04_LOG_FIELD_ENTRIES'!D:D, C35, '04_LOG_FIELD_ENTRIES'!K:K, "AC_*") -> 0 | K35: =SUMIFS(J$2:J35, C$2:C35, C35) -> 34269.2 | L35: =I35-K35 -> 9985.32 | M35: =I35-G35 -> 44254.52 | N35: =IF(G35>0, I35/G35, 1) -> 1 | O35: =IF(K35>0, I35/K35, 1) -> 1.2913788 | P35: =IF(AND(N35>=0.95, O35>=0.95), "SALUDABLE", IF(N35<0.9, "ALERTA RETRASO", "ALERTA SOBRECOSTO")) -> SALUDABLE
A36: 9 | B36: 2026-08-09 | C36: WBS-300 | D36: Red de Agua Potable y Conexiones Domiciliarias | E36: =SUM('01_PRESUPUESTO_CRONOGRAMA_BASE'!G10:G11) -> 57565.2 | F36: =SUMIFS('02_CRONOGRAMA_PV_DIARIO'!E:E, '02_CRONOGRAMA_PV_DIARIO'!A:A, A36, '02_CRONOGRAMA_PV_DIARIO'!C:C, C36) -> 0 | G36: =SUMIFS(F$2:F36, C$2:C36, C36) -> 0 | H36: =SUMIFS('04_LOG_FIELD_ENTRIES'!J:J, '04_LOG_FIELD_ENTRIES'!B:B, B36, '04_LOG_FIELD_ENTRIES'!D:D, C36, '04_LOG_FIELD_ENTRIES'!K:K, "EV_PRODUCCION") -> 0 | I36: =SUMIFS(H$2:H36, C$2:C36, C36) -> 9327.45 | J36: =SUMIFS('04_LOG_FIELD_ENTRIES'!J:J, '04_LOG_FIELD_ENTRIES'!B:B, B36, '04_LOG_FIELD_ENTRIES'!D:D, C36, '04_LOG_FIELD_ENTRIES'!K:K, "AC_*") -> 0 | K36: =SUMIFS(J$2:J36, C$2:C36, C36) -> 7730.8 | L36: =I36-K36 -> 1596.65 | M36: =I36-G36 -> 9327.45 | N36: =IF(G36>0, I36/G36, 1) -> 1 | O36: =IF(K36>0, I36/K36, 1) -> 1.206531 | P36: =IF(AND(N36>=0.95, O36>=0.95), "SALUDABLE", IF(N36<0.9, "ALERTA RETRASO", "ALERTA SOBRECOSTO")) -> SALUDABLE
A37: 9 | B37: 2026-08-09 | C37: WBS-400 | D37: Pruebas Hidráulicas, Desinfección y Entrega | E37: =SUM('01_PRESUPUESTO_CRONOGRAMA_BASE'!G12:G12) -> 9348.06 | F37: =SUMIFS('02_CRONOGRAMA_PV_DIARIO'!E:E, '02_CRONOGRAMA_PV_DIARIO'!A:A, A37, '02_CRONOGRAMA_PV_DIARIO'!C:C, C37) -> 0 | G37: =SUMIFS(F$2:F37, C$2:C37, C37) -> 0 | H37: =SUMIFS('04_LOG_FIELD_ENTRIES'!J:J, '04_LOG_FIELD_ENTRIES'!B:B, B37, '04_LOG_FIELD_ENTRIES'!D:D, C37, '04_LOG_FIELD_ENTRIES'!K:K, "EV_PRODUCCION") -> 0 | I37: =SUMIFS(H$2:H37, C$2:C37, C37) -> 2337.02 | J37: =SUMIFS('04_LOG_FIELD_ENTRIES'!J:J, '04_LOG_FIELD_ENTRIES'!B:B, B37, '04_LOG_FIELD_ENTRIES'!D:D, C37, '04_LOG_FIELD_ENTRIES'!K:K, "AC_*") -> 0 | K37: =SUMIFS(J$2:J37, C$2:C37, C37) -> 1299.2 | L37: =I37-K37 -> 1037.82 | M37: =I37-G37 -> 2337.02 | N37: =IF(G37>0, I37/G37, 1) -> 1 | O37: =IF(K37>0, I37/K37, 1) -> 1.7988147 | P37: =IF(AND(N37>=0.95, O37>=0.95), "SALUDABLE", IF(N37<0.9, "ALERTA RETRASO", "ALERTA SOBRECOSTO")) -> SALUDABLE
