Workbook

Sheet 01. Presupuesto Base
A1: PRESUPUESTO OFICIAL COMERCIAL (LICITACIÓN / OFERTA CLIENTE)
A2: Proyecto: Redes Sanitarias de Agua Potable y Alcantarillado - Habilitación Urbana Los Cedros
A3: Plazo: 60 días calendario (8 semanas) | Modalidad: Suma Alzada / Precios Unitarios
A5: Item | B5: Descripción de Partida / Especialidad | C5: Unidad | D5: Metrado | E5: P.U. Directo (S/) | F5: Parcial Directo (S/)
A6: 01 | B6: REDES SANITARIAS DE HABILITACIÓN URBANA
A7: 01.01 | B7: OBRAS PRELIMINARES Y TRABAJOS PROVISIONALES
A8: 01.01 | B8: Obras Preliminares y Trabajos Provisionales | C8: GLB | D8: 1 | E8: ='02. Analisis de PU'!H18 -> 8296.4 | F8: =ROUND(D8*E8, 2) -> 8296.4
A9: 01.02 | B9: RED DE ALCANTARILLADO SANITARIO Y BUZONES
A10: 01.02.01 | B10: Trazo, Nivelación y Replanteo de Zanjas | C10: M | D10: 2400 | E10: ='02. Analisis de PU'!H36 -> 3.35 | F10: =ROUND(D10*E10, 2) -> 8040
A11: 01.02.02 | B11: Excavación de Zanja H=1.50m - 2.20m a Máquina (Terreno Normal) | C11: M3 | D11: 3840 | E11: ='02. Analisis de PU'!H50 -> 11.66 | F11: =ROUND(D11*E11, 2) -> 44774.4
A12: 01.02.03 | B12: Preparación y Colocación de Cama de Arena e=0.10m | C12: M | D12: 2400 | E12: ='02. Analisis de PU'!H64 -> 11.12 | F12: =ROUND(D12*E12, 2) -> 26688
A13: 01.02.04 | B13: Suministro e Instalación de Tubería PVC UF DN 200mm Serie S-20 para Alcantarillado | C13: M | D13: 1400 | E13: ='02. Analisis de PU'!H81 -> 55.51 | F13: =ROUND(D13*E13, 2) -> 77714
A14: 01.02.05 | B14: Relleno Compactado de Zanja en Capas de 0.20m con Maquinaria/Plancha | C14: M3 | D14: 3300 | E14: ='02. Analisis de PU'!H100 -> 28.54 | F14: =ROUND(D14*E14, 2) -> 94182
A15: 01.02.06 | B15: Construcción de Buzones Prefabricados de Concreto h=1.50m - 2.50m (Inc. Marco y Tapa) | C15: UND | D15: 32 | E15: ='02. Analisis de PU'!H118 -> 2500.73 | F15: =ROUND(D15*E15, 2) -> 80023.36
A16: 01.02.07 | B16: Conexiones Domiciliarias de Alcantarillado (Caja de Registro + Acometida) | C16: UND | D16: 120 | E16: ='02. Analisis de PU'!H134 -> 405.54 | F16: =ROUND(D16*E16, 2) -> 48664.8
A17: 01.03 | B17: RED DE AGUA POTABLE Y CONEXIONES DOMICILIARIAS
A18: 01.03.01 | B18: Suministro e Instalación de Tubería PVC C-10 DN 110mm para Agua Potable | C18: M | D18: 1000 | E18: ='02. Analisis de PU'!H150 -> 38.76 | F18: =ROUND(D18*E18, 2) -> 38760
A19: 01.03.02 | B19: Conexiones Domiciliarias de Agua Potable (Caja de Agua + Abrazadera + Acometida) | C19: UND | D19: 120 | E19: ='02. Analisis de PU'!H166 -> 156.71 | F19: =ROUND(D19*E19, 2) -> 18805.2
A20: 01.04 | B20: PRUEBAS HIDRÁULICAS Y PUESTA EN SERVICIO
A21: 01.04.01 | B21: Pruebas Hidráulicas de Redes de Agua y Alcantarillado + Desinfección | C21: GLB | D21: 1 | E21: ='02. Analisis de PU'!H185 -> 9348.06 | F21: =ROUND(D21*E21, 2) -> 9348.06
E23: COSTO DIRECTO TOTAL (CD) | F23: =SUM(F8,F10,F11,F12,F13,F14,F15,F16,F18,F19,F21) -> 455296.22
E24: GASTOS GENERALES (10.00%) | F24: =ROUND(F23*0.1, 2) -> 45529.62
E25: UTILIDAD (8.00%) | F25: =ROUND(F23*0.08, 2) -> 36423.7
E26: SUBTOTAL (VALOR DE VENTA SIN IGV) | F26: =F23+F24+F25 -> 537249.54
E27: IMPUESTO GENERAL A LAS VENTAS (I.G.V. 18.00%) | F27: =ROUND(F26*0.18, 2) -> 96704.92
E28: TOTAL PRESUPUESTO COMERCIAL (CON IGV) | F28: =F26+F27 -> 633954.46

Sheet 02. Analisis de PU
A1: ANÁLISIS DE PRECIOS UNITARIOS DIRECTOS - PRESUPUESTO COMERCIAL
A2: Proyecto: Redes Sanitarias de Agua Potable y Alcantarillado - Habilitación Urbana Los Cedros
A4: Item: 01.01 | B4: Obras Preliminares y Trabajos Provisionales | F4: Rendimiento: | G4: 1 | H4: GLB/DIA
A5: Código Rec. | B5: Descripción Recurso | C5: Unidad | D5: Cuadrilla | E5: Jornal | F5: Cantidad / Aporte | G5: Precio (S/) | H5: Parcial (S/)
B6: MANO DE OBRA
A7: MO_CAPATAZ | B7: CAPATAZ | C7: hh | D7: 0.5 | E7: 8 | F7: =ROUND(D7*E7/G$4, 4) -> 4 | G7: 32.5 | H7: =ROUND(F7*G7, 2) -> 130
A8: MO_PEON | B8: PEON | C8: hh | D8: 4 | E8: 8 | F8: =ROUND(D8*E8/G$4, 4) -> 32 | G8: 20.1 | H8: =ROUND(F8*G8, 2) -> 643.2
B9: Subtotal Mano de Obra | H9: =SUM(H7:H8) -> 773.2
B10: MATERIALES
A11: MAT_CARTEL | B11: CARTEL DE OBRA 3.60X2.40M | C11: und | F11: 1 | G11: 1200 | H11: =ROUND(F11*G11, 2) -> 1200
A12: MAT_CASETA | B12: CASETA DE ALMACEN Y OFICINA PROVISIONAL | C12: glb | F12: 1 | G12: 2300 | H12: =ROUND(F12*G12, 2) -> 2300
B13: Subtotal Materiales | H13: =SUM(H11:H12) -> 3500
B14: EQUIPOS Y MAQUINARIA
A15: EQ_HERRAMIENTAS | B15: HERRAMIENTAS MANUALES | C15: %MO | F15: 0.03 | G15: =H9 -> 773.2 | H15: =ROUND(F15*G15, 2) -> 23.2
A16: SUB_MOVILIZACION | B16: SUBCONTRATO DE MOVILIZACION Y DESMOVILIZACION DE MAQUINARIA | C16: glb | F16: 1 | G16: 4000 | H16: =ROUND(F16*G16, 2) -> 4000
B17: Subtotal Equipos & Subcontratos | H17: =SUM(H15:H16) -> 4023.2
B18: PRECIO UNITARIO DIRECTO (S/) | H18: =SUM(H9, H13, H17) -> 8296.4
A20: Item: 01.02.01 | B20: Trazo, Nivelación y Replanteo de Zanjas | F20: Rendimiento: | G20: 250 | H20: M/DIA
A21: Código Rec. | B21: Descripción Recurso | C21: Unidad | D21: Cuadrilla | E21: Jornal | F21: Cantidad / Aporte | G21: Precio (S/) | H21: Parcial (S/)
B22: MANO DE OBRA
A23: MO_CAPATAZ | B23: CAPATAZ | C23: hh | D23: 0.2 | E23: 8 | F23: =ROUND(D23*E23/G$20, 4) -> 0.0064 | G23: 32.5 | H23: =ROUND(F23*G23, 2) -> 0.21
A24: MO_OPERARIO | B24: OPERARIO | C24: hh | D24: 1 | E24: 8 | F24: =ROUND(D24*E24/G$20, 4) -> 0.032 | G24: 26.8 | H24: =ROUND(F24*G24, 2) -> 0.86
A25: MO_PEON | B25: PEON | C25: hh | D25: 2 | E25: 8 | F25: =ROUND(D25*E25/G$20, 4) -> 0.064 | G25: 20.1 | H25: =ROUND(F25*G25, 2) -> 1.29
B26: Subtotal Mano de Obra | H26: =SUM(H23:H25) -> 2.36
B27: MATERIALES
A28: MAT_ESTACA | B28: ESTACAS Y MADERA PARA TRAZO | C28: pza | F28: 0.05 | G28: 4.5 | H28: =ROUND(F28*G28, 2) -> 0.23
A29: MAT_PINTURA | B29: PINTURA SPRAY MARCADOR DE ZANJA | C29: gla | F29: 0.004 | G29: 18 | H29: =ROUND(F29*G29, 2) -> 0.07
A30: MAT_CORDEL | B30: CORDEL / NYLON | C30: m | F30: 0.05 | G30: 0.8 | H30: =ROUND(F30*G30, 2) -> 0.04
B31: Subtotal Materiales | H31: =SUM(H28:H30) -> 0.34
B32: EQUIPOS Y MAQUINARIA
A33: EQ_ESTACION_TOTAL | B33: EQUIPO DE TOPOGRAFIA ESTACION TOTAL | C33: hm | D33: 1 | E33: 8 | F33: =ROUND(D33*E33/G$20, 4) -> 0.032 | G33: 18 | H33: =ROUND(F33*G33, 2) -> 0.58
A34: EQ_HERRAMIENTAS | B34: HERRAMIENTAS MANUALES | C34: %MO | F34: 0.03 | G34: =H26 -> 2.36 | H34: =ROUND(F34*G34, 2) -> 0.07
B35: Subtotal Equipos & Subcontratos | H35: =SUM(H33:H34) -> 0.65
B36: PRECIO UNITARIO DIRECTO (S/) | H36: =SUM(H26, H31, H35) -> 3.35
A38: Item: 01.02.02 | B38: Excavación de Zanja H=1.50m - 2.20m a Máquina (Terreno Normal) | F38: Rendimiento: | G38: 160 | H38: M3/DIA
A39: Código Rec. | B39: Descripción Recurso | C39: Unidad | D39: Cuadrilla | E39: Jornal | F39: Cantidad / Aporte | G39: Precio (S/) | H39: Parcial (S/)
B40: MANO DE OBRA
A41: MO_CAPATAZ | B41: CAPATAZ | C41: hh | D41: 0.2 | E41: 8 | F41: =ROUND(D41*E41/G$38, 4) -> 0.01 | G41: 32.5 | H41: =ROUND(F41*G41, 2) -> 0.33
A42: MO_PEON | B42: PEON | C42: hh | D42: 2 | E42: 8 | F42: =ROUND(D42*E42/G$38, 4) -> 0.1 | G42: 20.1 | H42: =ROUND(F42*G42, 2) -> 2.01
B43: Subtotal Mano de Obra | H43: =SUM(H41:H42) -> 2.34
...

Sheet 03. Listado de Insumos
A1: EXPLOSIÓN DE INSUMOS CONSOLIDADOS Y ANÁLISIS DE INCIDENCIA
A2: Proyecto: Redes Sanitarias de Agua Potable y Alcantarillado - Habilitación Urbana Los Cedros
A4: Código Insumo | B4: Descripción del Recurso | C4: Tipo Recurso | D4: Unidad | E4: Cantidad Consolidada | F4: Precio Unit. (S/) | G4: Parcial Total (S/) | H4: % Incidencia CD
A5: EQ_BOMBA_PRUEBA | B5: BOMBA HIDROSTÁTICA DE PRUEBA DE PRESIÓN | C5: EQP | D5: hm | F5: 30 | G5: =ROUND(E5*F5, 2) -> 0 | H5: =G5/'01. Presupuesto Base'!F$23 -> 0
A6: EQ_CAMION_CISTERNA | B6: CAMION CISTERNA 4X2 (AGUA) 2,000 GLN | C6: EQP | D6: hm | F6: 140 | G6: =ROUND(E6*F6, 2) -> 0 | H6: =G6/'01. Presupuesto Base'!F$23 -> 0
A7: EQ_CAMION_GRUAN | B7: CAMION GRUA 5 TN PARA MONTAJE DE BUZONES | C7: EQP | D7: hm | F7: 160 | G7: =ROUND(E7*F7, 2) -> 0 | H7: =G7/'01. Presupuesto Base'!F$23 -> 0
A8: EQ_ESTACION_TOTAL | B8: EQUIPO DE TOPOGRAFIA ESTACION TOTAL | C8: EQP | D8: hm | F8: 18 | G8: =ROUND(E8*F8, 2) -> 0 | H8: =G8/'01. Presupuesto Base'!F$23 -> 0
A9: EQ_EXCAVADORA | B9: EXCAVADORA SOBRE ORUGAS 140 HP | C9: EQP | D9: hm | F9: 185 | G9: =ROUND(E9*F9, 2) -> 0 | H9: =G9/'01. Presupuesto Base'!F$23 -> 0
A10: EQ_PLANCHA | B10: PLANCHA COMPACTADORA 7 HP | C10: EQP | D10: hm | F10: 25 | G10: =ROUND(E10*F10, 2) -> 0 | H10: =G10/'01. Presupuesto Base'!F$23 -> 0
A11: EQ_RETROEXCAVADORA | B11: RETROEXCAVADORA SOBRE LLANTAS 62 HP | C11: EQP | D11: hm | F11: 130 | G11: =ROUND(E11*F11, 2) -> 0 | H11: =G11/'01. Presupuesto Base'!F$23 -> 0
A12: MAT_ACCESORIOS_AGUA | B12: ACCESORIOS Y CODOS PVC AGUA 110MM (PROMEDIO/M) | C12: MAT | D12: glb | F12: 5 | G12: =ROUND(E12*F12, 2) -> 0 | H12: =G12/'01. Presupuesto Base'!F$23 -> 0
A13: MAT_AGUA | B13: AGUA PARA COMPACTACIÓN Y PRUEBAS | C13: MAT | D13: m3 | F13: 12 | G13: =ROUND(E13*F13, 2) -> 0 | H13: =G13/'01. Presupuesto Base'!F$23 -> 0
A14: MAT_ARENA_CAMAS | B14: ARENA FINA SELECCIONADA PARA CAMA E=0.10M | C14: MAT | D14: m3 | F14: 45 | G14: =ROUND(E14*F14, 2) -> 0 | H14: =G14/'01. Presupuesto Base'!F$23 -> 0
A15: MAT_BUZON_PREF | B15: BUZON PREFABRICADO CONCRETO H=1.5-2.5M CON MARCO Y TAPA | C15: MAT | D15: und | F15: 1050 | G15: =ROUND(E15*F15, 2) -> 0 | H15: =G15/'01. Presupuesto Base'!F$23 -> 0
A16: MAT_CAJA_AGUA | B16: CAJA TERMOFORMADA PARA MEDIDOR + ABRAZADERA + LLAVE DE PASO | C16: MAT | D16: und | F16: 62 | G16: =ROUND(E16*F16, 2) -> 0 | H16: =G16/'01. Presupuesto Base'!F$23 -> 0
... A37: SUB_PRUEBA_LAB | B37: SUBCONTRATO PRUEBAS DE LABORATORIO DE AGUA (BACTERIOLOGICO/FISICOQUIMICO) | C37: SUB | D37: glb | F37: 3800 | G37: =ROUND(E37*F37, 2) -> 0 | H37: =G37/'01. Presupuesto Base'!F$23 -> 0
B38: TOTAL COSTO DIRECTO INSUMOS CONSOLIDADOS | G38: =SUM(G5:G37) -> 0 | H38: =SUM(H5:H37) -> 0
